Workbook

Sheet JAN
C1: LOBBY ENTERPRISES
A2: PROPERTY MANAGERS AND ESTATE AGENTS
A3: JAN 2026
I4: P.O.BOX 11987
A5: ANITA PLOT | I5: TEL : 0722711933/4454322
A6: A/C No '0630179417471
A7: Tel No
H8: Care taker | I8: ANITA
H9: Phone no
A10: HSE NO | B10: NAME | C10: PHONE NO | D10: DEPOSIT PAID | E10: MONTHLY RENT | F10: BAL B/D | G10: RENT DUE | H10: RENT PAID | I10: RCT NO | J10: PERIOD | K10: BALANCE | L10: STATUS | M10: FORMS
A11: 1 | B11: RACHAEL | C11: 0741311326 | E11: 4000 | F11: 0 | G11: =D11+E11+F11 -> 4000 | H11: =4000 -> 4000 | I11: UAICC47UZY | J11: JAN | K11: =G11-H11 -> 0 | M11: SIGNED
A12: 2 | B12: IMELDA | C12: '0707746822 | D12: 0 | E12: 4000 | F12: 0 | G12: =D12+E12+F12 -> 4000 | H12: =4000 -> 4000 | I12: UADQ23F0JD | J12: JAN | K12: =G12-H12 -> 0 | M12: SIGNED
A13: 3 | B13: JOHN MUTEMBEI | C13: 0113100973 | D13: 0 | E13: 4000 | F13: 0 | G13: =D13+E13+F13 -> 4000 | H13: =4000 -> 4000 | I13: DIRECT | J13: JAN | K13: =G13-H13 -> 0 | M13: SIGNED
A14: 4 | B14: GEORGE OUCHA | C14: 0720726146 | E14: 6000 | F14: 0 | G14: =D14+E14+F14 -> 6000 | H14: =6000 -> 6000 | I14: UAJ6U42AQY | J14: JAN | K14: =G14-H14 -> 0
A15: 5 | B15: ELIZABETH K | C15: 0799945987 | E15: 6500 | F15: 0 | G15: =D15+E15+F15 -> 6500 | H15: =6500 -> 6500 | I15: UAA7F3GUHD | J15: JAN | K15: =G15-H15 -> 0
A16: 6 | B16: SUSAN WANJIKU | C16: 0792878247 | D16: 0 | E16: 6500 | F16: 0 | G16: =D16+E16+F16 -> 6500 | H16: =5500+1000 -> 6500 | I16: UA67F34H9W/UAJ7F4BZ8P | J16: JAN | K16: =G16-H16 -> 0 | M16: SIGNED
A17: 7 | B17: VACANT | F17: 0 | G17: =D17+E17+F17 -> 0 | J17: JAN | K17: =G17-H17 -> 0 | M17: SIGNED
A18: 8 | B18: VICTOR KIVUTSI | C18: 0720788630 | D18: 0 | E18: 5000 | F18: 0 | G18: =D18+E18+F18 -> 5000 | H18: =5000 -> 5000 | I18: UAEA53YFSY | J18: JAN | K18: =G18-H18 -> 0 | L18: 10th | M18: SIGNED
A19: 9 | B19: ANNASTACIA | C19: 0725869394 | F19: 0 | G19: =D19+E19+F19 -> 0 | J19: JAN | K19: =G19-H19 -> 0
A20: 10 | B20: CHEBITA OMBOGO /OSCAR | C20: 0711275102 | D20: 0 | E20: 3400 | F20: 0 | G20: =D20+E20+F20 -> 3400 | H20: =3400 -> 3400 | I20: UA62231VSX | J20: JAN | K20: =G20-H20 -> 0 | M20: SIGNED
A21: 11 | B21: BENARD MUTHUI | C21: 0729369553 | D21: 0 | E21: 4500 | F21: 0 | G21: =D21+E21+F21 -> 4500 | H21: =4500 -> 4500 | I21: UA4FX2Y578 | J21: JAN | K21: =G21-H21 -> 0 | M21: SIGNED
A22: 12 | B22: DAVID THIANI | C22: 0715806277 | D22: 0 | E22: 8000 | F22: 3000 | G22: =D22+E22+F22 -> 11000 | H22: =8000 -> 8000 | I22: UAAC63GC1D | J22: JAN | K22: =G22-H22 -> 3000 | L22: OFF | M22: SIGNED
A23: 13 | B23: MARY NYAMBURA(CHURCH) | C23: 0722135696 | D23: 0 | E23: 10000 | F23: 0 | G23: =D23+E23+F23 -> 10000 | H23: =10000 -> 10000 | I23: UAG4G481C0 | J23: JAN | K23: =G23-H23 -> 0 | L23: 15TH | M23: SIGNED
A24: 14 | B24: Vacant | F24: 0 | G24: =D24+E24+F24 -> 0 | J24: JAN | K24: =G24-H24 -> 0 | M24: SIGNED
A25: 15 | B25: ANNE WANJIRU | C25: 0740712315 | D25: 0 | E25: 10000 | F25: 2000 | G25: =D25+E25+F25 -> 12000 | H25: =4000+3000+2500 -> 9500 | I25: UAB233P67U/UAJ234CWXY/UA5235A3KH | J25: JAN | K25: =G25-H25 -> 2500 | L25: OFF | M25: SIGNED
A26: 16 | B26: VACANT | F26: 0 | G26: =D26+E26+F26 -> 0 | J26: JAN | K26: =G26-H26 -> 0
A27: 17 | B27: IRENE MAKENA | C27: 0719665779 | E27: 18000 | F27: 0 | G27: =D27+E27+F27 -> 18000 | H27: =18000 -> 18000 | I27: UACKF3J5FZ | J27: JAN | K27: =G27-H27 -> 0 | L27: 10th | M27: SIGNED
A28: 18 | B28: WILLIAM /GOEFREY | C28: 0727561491 | E28: 9000 | F28: 0 | G28: =D28+E28+F28 -> 9000 | H28: =9000 -> 9000 | I28: UA75D33X6Y | J28: JAN | K28: =G28-H28 -> 0 | M28: SIGNED
A29: 19 | B29: VACANT | G29: =D29+E29+F29 -> 0 | J29: JAN
A30: Totals | E30: =SUM(E11:E29) -> 98900 | F30: =SUM(F11:F29) -> 5000 | G30: =SUM(G11:G29) -> 103900 | H30: =SUM(H11:H29) -> 98400 | K30: =SUM(K11:K29) -> 5500
A31: Deductions
A32: Less Management fees | H32: =10%*H30 -> 9840
A33: DIRECT | H33: =H13 -> 4000
A34: TOTAL DEDUCTIONS | H34: =SUM(H32:H33) -> 13840
A35: BAL B/F | H35: =[1]DEC!$K$37 -> 0
I36: PAID | J36: PAID | K36: Balance
A37: AMOUNT DUE | H37: =H30-H34+H35 -> 84560 | I37: 70000 | J37: 14560 | K37: =H37-I37-J37 -> 0
A38: AUTHORISED BY JOSEPH GITHINJI | K38: 46053
F41: =8350-7600 -> 750
H42: =(H30/G30)*100 -> 94.706449
...

Sheet FEB
C1: LOBBY ENTERPRISES
A2: PROPERTY MANAGERS AND ESTATE AGENTS
A3: FEB 2026
I4: P.O.BOX 11987
A5: ANITA PLOT | I5: TEL : 0722711933/4454322
A6: A/C No '0630179417471
A7: Tel No
H8: Care taker | I8: ANITA
H9: Phone no
A10: HSE NO | B10: NAME | C10: PHONE NO | D10: DEPOSIT PAID | E10: MONTHLY RENT | F10: BAL B/D | G10: RENT DUE | H10: RENT PAID | I10: RCT NO | J10: PERIOD | K10: BALANCE | L10: STATUS | M10: FORMS
A11: 1 | B11: RACHAEL | C11: 0741311326 | E11: 4000 | F11: =JAN!K11 -> 0 | G11: =D11+E11+F11 -> 4000 | H11: 4000 | I11: DIRECT | J11: FEB | K11: =G11-H11 -> 0 | M11: SIGNED
A12: 2 | B12: IMELDA | C12: '0707746822 | D12: 0 | E12: 4000 | F12: =JAN!K12 -> 0 | G12: =D12+E12+F12 -> 4000 | H12: =4000 -> 4000 | I12: UBBQ260N71 | J12: FEB | K12: =G12-H12 -> 0 | M12: SIGNED
A13: 3 | B13: JOHN MUTEMBEI | C13: 0113100973 | D13: 0 | E13: 4000 | F13: =JAN!K13 -> 0 | G13: =D13+E13+F13 -> 4000 | J13: FEB | K13: =G13-H13 -> 4000 | L13: LOCKED | M13: SIGNED
A14: 4 | B14: GEORGE OUCHA | C14: 0720726146 | E14: 6000 | F14: =JAN!K14 -> 0 | G14: =D14+E14+F14 -> 6000 | H14: =6000 -> 6000 | I14: UBC6U6CO0N | J14: FEB | K14: =G14-H14 -> 0
A15: 5 | B15: ELIZABETH KURA | C15: 0799945987 | E15: 6500 | F15: =JAN!K15 -> 0 | G15: =D15+E15+F15 -> 6500 | H15: =6500 -> 6500 | I15: UB9D966QO | J15: FEB | K15: =G15-H15 -> 0
A16: 6 | B16: SUSAN WANJIKU | C16: 0792878247 | D16: 0 | E16: 6500 | F16: =JAN!K16 -> 0 | G16: =D16+E16+F16 -> 6500 | H16: =5900+600 -> 6500 | I16: UB97F691S1/UBK7F7CTE2 | J16: FEB | K16: =G16-H16 -> 0 | M16: SIGNED
A17: 7 | B17: VACANT | F17: =JAN!K17 -> 0 | G17: =D17+E17+F17 -> 0 | J17: FEB | K17: =G17-H17 -> 0 | M17: SIGNED
A18: 8 | B18: VICTOR KIVUTSI | C18: 0720788630 | D18: 0 | E18: 5000 | F18: =JAN!K18 -> 0 | G18: =D18+E18+F18 -> 5000 | H18: =5000 -> 5000 | I18: UBBA56MTAH | J18: FEB | K18: =G18-H18 -> 0 | L18: 10th | M18: SIGNED
A19: 9 | B19: ANNASTACIA | C19: 0725869394 | F19: =JAN!K19 -> 0 | G19: =D19+E19+F19 -> 0 | J19: FEB | K19: =G19-H19 -> 0
A20: 10 | B20: CHEBITA OMBOGO /OSCAR | C20: 0711275102 | D20: 0 | E20: 3400 | F20: =JAN!K20 -> 0 | G20: =D20+E20+F20 -> 3400 | H20: =3400 -> 3400 | I20: UB5225UYB | J20: FEB | K20: =G20-H20 -> 0 | M20: SIGNED
A21: 11 | B21: BENARD MUTHUI | C21: 0729369553 | D21: 0 | E21: 4500 | F21: =JAN!K21 -> 0 | G21: =D21+E21+F21 -> 4500 | H21: =4500 -> 4500 | I21: UB5FX5UJ92 | J21: FEB | K21: =G21-H21 -> 0 | M21: SIGNED
A22: 12 | B22: DAVID THIANI | C22: 0715806277 | D22: 0 | E22: 8000 | F22: =JAN!K22 -> 3000 | G22: =D22+E22+F22 -> 11000 | H22: =8000 -> 8000 | I22: 5793 | J22: FEB | K22: =G22-H22 -> 3000 | M22: SIGNED
A23: 13 | B23: MARY NYAMBURA(CHURCH) | C23: 0722135696 | D23: 0 | E23: 10000 | F23: =JAN!K23 -> 0 | G23: =D23+E23+F23 -> 10000 | H23: =10000 -> 10000 | I23: UBG4G77IND | J23: FEB | K23: =G23-H23 -> 0 | L23: 15TH | M23: SIGNED
A24: 14 | B24: Vacant | F24: =JAN!K24 -> 0 | G24: =D24+E24+F24 -> 0 | J24: FEB | K24: =G24-H24 -> 0 | M24: SIGNED
A25: 15 | B25: ANNE WANJIRU | C25: 0740712315 | D25: 0 | E25: 10000 | F25: =JAN!K25 -> 2500 | G25: =D25+E25+F25 -> 12500 | H25: =1500+5000+3000 -> 9500 | I25: UB2235NXZI/UBH2373ZL7/UBQ2381BBT | J25: FEB | K25: =G25-H25 -> 3000 | M25: SIGNED
A26: 16 | B26: VACANT | F26: =JAN!K26 -> 0 | G26: =D26+E26+F26 -> 0 | J26: FEB | K26: =G26-H26 -> 0
A27: 17 | B27: IRENE MAKENA | C27: 0719665779 | E27: 18000 | F27: =JAN!K27 -> 0 | G27: =D27+E27+F27 -> 18000 | H27: =18000 -> 18000 | I27: UBBKF6CJ5T | J27: FEB | K27: =G27-H27 -> 0 | L27: 10th | M27: SIGNED
A28: 18 | B28: ELIZABETH OMUSE | E28: 9000 | F28: =JAN!K28 -> 0 | G28: =D28+E28+F28 -> 9000 | H28: =9000 -> 9000 | I28: UBA5D69YYP | J28: FEB | K28: =G28-H28 -> 0 | M28: SIGNED
A29: 19 | B29: VACANT | F29: =JAN!K29 -> 0 | G29: =D29+E29+F29 -> 0 | J29: FEB
A30: Totals | E30: =SUM(E11:E29) -> 98900 | F30: =SUM(F11:F29) -> 5500 | G30: =SUM(G11:G29) -> 104400 | H30: =SUM(H11:H29) -> 94400 | K30: =SUM(K11:K29) -> 10000
A31: Deductions
A32: Less Management fees | H32: =10%*H30 -> 9440
A33: DIRECT | H33: =H11 -> 4000
A34: TOTAL DEDUCTIONS | H34: =SUM(H32:H33) -> 13440
A35: BAL B/F | H35: =JAN!K37 -> 0
I36: PAID | J36: PAID | K36: Balance
A37: AMOUNT DUE | H37: =H30-H34+H35 -> 80960 | I37: 70000 | J37: 10960 | K37: =H37-I37-J37 -> 0
A38: AUTHORISED BY JOSEPH GITHINJI | K38: 46081
F41: =8350-7600 -> 750
H42: =(H30/G30)*100 -> 90.421456
...

Sheet MAR
C1: LOBBY ENTERPRISES
A2: PROPERTY MANAGERS AND ESTATE AGENTS
A3: MAR 2026
I4: P.O.BOX 11987
A5: ANITA PLOT | I5: TEL : 0722711933/4454322
A6: A/C No '0630179417471
A7: Tel No
H8: Care taker | I8: ANITA
H9: Phone no
A10: HSE NO | B10: NAME | C10: PHONE NO | D10: DEPOSIT PAID | E10: MONTHLY RENT | F10: BAL B/D | G10: RENT DUE | H10: RENT PAID | I10: RCT NO | J10: PERIOD | K10: BALANCE | L10: STATUS | M10: FORMS
A11: 1 | B11: RACHAEL | C11: 0741311326 | E11: 5000 | F11: =FEB!K11 -> 0 | G11: =D11+E11+F11 -> 5000 | H11: =10000 -> 10000 | I11: UCOCCAG0C7 | J11: MAR | K11: =G11-H11 -> -5000 | M11: SIGNED
A12: 2 | B12: IMELDA | C12: '0707746822 | D12: 0 | E12: 4000 | F12: =FEB!K12 -> 0 | G12: =D12+E12+F12 -> 4000 | H12: =4000 -> 4000 | I12: UC3Q27UVXU | J12: MAR | K12: =G12-H12 -> 0 | M12: SIGNED
A13: 3 | B13: TENANT | D13: 0 | E13: 4000 | G13: =D13+E13+F13 -> 4000 | H13: =4000 -> 4000 | I13: DIRECT | J13: MAR | K13: =G13-H13 -> 0 | M13: SIGNED
A14: 4 | B14: GEORGE OUCHA | C14: 0720726146 | E14: 6000 | F14: =FEB!K14 -> 0 | G14: =D14+E14+F14 -> 6000 | H14: =6000 -> 6000 | I14: UC96U8MK0D | J14: MAR | K14: =G14-H14 -> 0
A15: 5 | B15: ELIZABETH KURA | C15: 0799945987 | E15: 6500 | F15: =FEB!K15 -> 0 | G15: =D15+E15+F15 -> 6500 | H15: =6500 -> 6500 | I15: UC77F8QTPK | J15: MAR | K15: =G15-H15 -> 0
A16: 6 | B16: SUSAN WANJIKU | C16: 0792878247 | D16: 0 | E16: 6500 | F16: =FEB!K16 -> 0 | G16: =D16+E16+F16 -> 6500 | H16: =4600+700+1000 -> 6300 | I16: UCB7F95NK3/UCN7FABE79/UCT7FB292N | J16: MAR | K16: =G16-H16 -> 200 | M16: SIGNED
A17: 7 | B17: NDUNGÚ KINUTHIA | E17: 5000 | F17: =FEB!K17 -> 0 | G17: =D17+E17+F17 -> 5000 | H17: =5000 -> 5000 | I17: UC9658Y74R | J17: MAR | K17: =G17-H17 -> 0 | M17: SIGNED
A18: 8 | B18: VICTOR KIVUTSI | C18: 0720788630 | D18: 0 | E18: 5000 | F18: =FEB!K18 -> 0 | G18: =D18+E18+F18 -> 5000 | H18: =5000 -> 5000 | I18: UCEA59KZD5 | J18: MAR | K18: =G18-H18 -> 0 | L18: 10th | M18: SIGNED
A19: 9 | B19: ANNASTACIA | C19: 0725869394 | F19: =FEB!K19 -> 0 | G19: =D19+E19+F19 -> 0 | J19: MAR | K19: =G19-H19 -> 0
A20: 10 | B20: CHEBITA OMBOGO /OSCAR | C20: 0711275102 | D20: 0 | E20: 3400 | F20: =FEB!K20 -> 0 | G20: =D20+E20+F20 -> 3400 | H20: =3400 -> 3400 | I20: UC6228K0QL | J20: MAR | K20: =G20-H20 -> 0 | M20: SIGNED
A21: 11 | B21: BENARD MUTHUI | C21: 0729369553 | D21: 0 | E21: 4500 | F21: =FEB!K21 -> 0 | G21: =D21+E21+F21 -> 4500 | H21: =4500 -> 4500 | I21: UC5FX8I8F6 | J21: MAR | K21: =G21-H21 -> 0 | M21: SIGNED
A22: 12 | B22: DAVID THIANI | C22: 0715806277 | D22: 0 | E22: 8000 | F22: =FEB!K22 -> 3000 | G22: =D22+E22+F22 -> 11000 | H22: =8000 -> 8000 | I22: UCFC69K6DP | J22: MAR | K22: =G22-H22 -> 3000 | M22: SIGNED
A23: 13 | B23: MARY NYAMBURA(CHURCH) | C23: 0722135696 | D23: 0 | E23: 10000 | F23: =FEB!K23 -> 0 | G23: =D23+E23+F23 -> 10000 | H23: =10000 -> 10000 | I23: UC4G9YFDE | J23: MAR | K23: =G23-H23 -> 0 | L23: 15TH | M23: SIGNED
A24: 14 | B24: Vacant | F24: =FEB!K24 -> 0 | G24: =D24+E24+F24 -> 0 | J24: MAR | K24: =G24-H24 -> 0 | M24: SIGNED
A25: 15 | B25: ANNE WANJIRU | C25: 0740712315 | D25: 0 | E25: 10000 | F25: =FEB!K25 -> 3000 | G25: =D25+E25+F25 -> 13000 | H25: =2000+5000+3000 -> 10000 | I25: UC3238IOZS/UCD239EE6/UD123BFR7F | J25: MAR | K25: =G25-H25 -> 3000 | M25: SIGNED
A26: 16 | B26: VACANT | F26: =FEB!K26 -> 0 | G26: =D26+E26+F26 -> 0 | J26: MAR | K26: =G26-H26 -> 0
A27: 17 | B27: IRENE MAKENA | C27: 0719665779 | E27: 18000 | F27: =FEB!K27 -> 0 | G27: =D27+E27+F27 -> 18000 | H27: =18000 -> 18000 | I27: UCAKF8XTDJ | J27: MAR | K27: =G27-H27 -> 0 | L27: 10th | M27: SIGNED
A28: 18 | B28: ELIZABETH OMUSE | E28: 9000 | F28: =FEB!K28 -> 0 | G28: =D28+E28+F28 -> 9000 | H28: =9000 -> 9000 | I28: UCA5D8WIO5 | J28: MAR | K28: =G28-H28 -> 0 | M28: SIGNED
A29: 19 | B29: VACANT | F29: =FEB!K29 -> 0 | G29: =D29+E29+F29 -> 0 | J29: MAR
A30: Totals | E30: =SUM(E11:E29) -> 104900 | F30: =SUM(F11:F29) -> 6000 | G30: =SUM(G11:G29) -> 110900 | H30: =SUM(H11:H29) -> 109700 | K30: =SUM(K11:K29) -> 1200
A31: Deductions
A32: Less Management fees | H32: =10%*H30 -> 10970
A33: DIRECT | H33: =H13 -> 4000
A34: TOTAL DEDUCTIONS | H34: =SUM(H32:H33) -> 14970
A35: BAL B/F | H35: =FEB!K37 -> 0
I36: PAID | J36: PAID | K36: Balance
A37: AMOUNT DUE | H37: =H30-H34+H35 -> 94730 | I37: 70000 | J37: 24730 | K37: =H37-I37-J37 -> 0
A38: AUTHORISED BY JOSEPH GITHINJI | K38: 46112
F41: =8350-7600 -> 750
H42: =(H30/G30)*100 -> 98.917944
...

Sheet APR
C1: LOBBY ENTERPRISES
A2: PROPERTY MANAGERS AND ESTATE AGENTS
A3: APR 2026
I4: P.O.BOX 11987
A5: ANITA PLOT | I5: TEL : 0722711933/4454322
A6: A/C No '0630179417471
A7: Tel No
H8: Care taker | I8: ANITA
H9: Phone no
A10: HSE NO | B10: NAME | C10: PHONE NO | D10: DEPOSIT PAID | E10: MONTHLY RENT | F10: BAL B/D | G10: RENT DUE | H10: RENT PAID | I10: RCT NO | J10: PERIOD | K10: BALANCE | L10: STATUS | M10: FORMS
A11: 1 | B11: RACHAEL | C11: 0741311326 | E11: 5000 | F11: =MAR!K11 -> -5000 | G11: =D11+E11+F11 -> 0 | J11: APR | K11: =G11-H11 -> 0 | M11: SIGNED
A12: 2 | B12: IMELDA | C12: '0707746822 | D12: 0 | E12: 4000 | F12: =MAR!K12 -> 0 | G12: =D12+E12+F12 -> 4000 | H12: =4000 -> 4000 | I12: UD7Q2BJO2S | J12: APR | K12: =G12-H12 -> 0 | M12: SIGNED | N12: RCTD
A13: 3 | B13: TENANT | D13: 0 | E13: 4000 | F13: =MAR!K13 -> 0 | G13: =D13+E13+F13 -> 4000 | H13: =4000 -> 4000 | I13: DIRECT | J13: APR | K13: =G13-H13 -> 0 | M13: SIGNED
A14: 4 | B14: GEORGE OUCHA | C14: 0720726146 | E14: 6000 | F14: =MAR!K14 -> 0 | G14: =D14+E14+F14 -> 6000 | H14: =6000 -> 6000 | I14: UDA6U06H1T | J14: APR | K14: =G14-H14 -> 0 | N14: RCTD
A15: 5 | B15: ELIZABETH KURA | C15: 0799945987 | E15: 6500 | F15: =MAR!K15 -> 0 | G15: =D15+E15+F15 -> 6500 | H15: =6500 -> 6500 | I15: UD77F07IB5 | J15: APR | K15: =G15-H15 -> 0 | N15: RCTD
A16: 6 | B16: SUSAN WANJIKU | C16: 0792878247 | D16: 0 | E16: 6500 | F16: =MAR!K16 -> 200 | G16: =D16+E16+F16 -> 6700 | H16: =4800+1800 -> 6600 | I16: UDA7FF0GASF/UDC7F0QR6P | J16: APR | K16: =G16-H16 -> 100 | M16: SIGNED | N16: RCTD
A17: 7 | B17: NDUNGÚ KINUTHIA | E17: 5500 | F17: =MAR!K17 -> 0 | G17: =D17+E17+F17 -> 5500 | H17: =5000 -> 5000 | I17: DIRECT | J17: APR | K17: =G17-H17 -> 500 | M17: SIGNED
A18: 8 | B18: VICTOR KIVUTSI | C18: 0720788630 | D18: 0 | E18: 5000 | F18: =MAR!K18 -> 0 | G18: =D18+E18+F18 -> 5000 | H18: =5000 -> 5000 | I18: UDFA5197T4 | J18: APR | K18: =G18-H18 -> 0 | L18: 10th | M18: SIGNED
A19: 9 | B19: ANNASTACIA | C19: 0725869394 | F19: =MAR!K19 -> 0 | G19: =D19+E19+F19 -> 0 | J19: APR | K19: =G19-H19 -> 0
A20: 10 | B20: CHEBITA OMBOGO /OSCAR | C20: 0711275102 | D20: 0 | E20: 3400 | F20: =MAR!K20 -> 0 | G20: =D20+E20+F20 -> 3400 | H20: =3400 -> 3400 | I20: UD72202YZY | J20: APR | K20: =G20-H20 -> 0 | M20: SIGNED | N20: RCTD
A21: 11 | B21: BENARD MUTHUI | C21: 0729369553 | D21: 0 | E21: 4500 | F21: =MAR!K21 -> 0 | G21: =D21+E21+F21 -> 4500 | H21: =4500 -> 4500 | I21: UD5FXBUAQJ | J21: APR | K21: =G21-H21 -> 0 | M21: SIGNED | N21: RCTD
A22: 12 | B22: DAVID THIANI | C22: 0715806277 | D22: 0 | E22: 8000 | F22: =MAR!K22 -> 3000 | G22: =D22+E22+F22 -> 11000 | H22: =8000 -> 8000 | I22: 5432 | J22: APR | K22: =G22-H22 -> 3000 | M22: SIGNED
A23: 13 | B23: MARY NYAMBURA(CHURCH) | C23: 0722135696 | D23: 0 | E23: 10000 | F23: =MAR!K23 -> 0 | G23: =D23+E23+F23 -> 10000 | H23: =10000 -> 10000 | I23: UDG4G1KAZD | J23: APR | K23: =G23-H23 -> 0 | L23: 15TH | M23: SIGNED
A24: 14 | B24: Vacant | F24: =MAR!K24 -> 0 | G24: =D24+E24+F24 -> 0 | J24: APR | K24: =G24-H24 -> 0 | M24: SIGNED
A25: 15 | B25: ANNE WANJIRU | C25: 0740712315 | D25: 0 | E25: 10000 | F25: =MAR!K25 -> 3000 | G25: =D25+E25+F25 -> 13000 | H25: =8000 -> 8000 | I25: UDF2315XGY | J25: APR | K25: =G25-H25 -> 5000 | M25: SIGNED
A26: 16 | B26: VACANT | F26: =MAR!K26 -> 0 | G26: =D26+E26+F26 -> 0 | J26: APR | K26: =G26-H26 -> 0
A27: 17 | B27: IRENE MAKENA | C27: 0719665779 | E27: 18000 | F27: =MAR!K27 -> 0 | G27: =D27+E27+F27 -> 18000 | H27: =18000 -> 18000 | I27: UDBKF0G6CG | J27: APR | K27: =G27-H27 -> 0 | L27: 10th | M27: SIGNED
A28: 18 | B28: ELIZABETH OMUSE | E28: 9000 | F28: =MAR!K28 -> 0 | G28: =D28+E28+F28 -> 9000 | H28: =9000 -> 9000 | I28: UDA5D0AYI5 | J28: APR | K28: =G28-H28 -> 0 | M28: SIGNED | N28: RCTD
A29: 19 | B29: VACANT | F29: =MAR!K29 -> 0 | G29: =D29+E29+F29 -> 0 | J29: APR
A30: Totals | E30: =SUM(E11:E29) -> 105400 | F30: =SUM(F11:F29) -> 1200 | G30: =SUM(G11:G29) -> 106600 | H30: =SUM(H11:H29) -> 98000 | K30: =SUM(K11:K29) -> 8600
A31: Deductions
A32: Less Management fees | H32: =10%*H30 -> 9800
A33: DIRECT | H33: =H13+H17 -> 9000
A34: TOTAL DEDUCTIONS | H34: =SUM(H32:H33) -> 18800
A35: BAL B/F | H35: =MAR!K37 -> 0
I36: PAID | J36: PAID | K36: Balance
A37: AMOUNT DUE | H37: =H30-H34+H35 -> 79200 | I37: 70000 | J37: 9200 | K37: =H37-I37-J37 -> 0
A38: AUTHORISED BY JOSEPH GITHINJI | K38: 46142
F41: =8350-7600 -> 750
H42: =(H30/G30)*100 -> 91.932458
...

Sheet MAY
C1: LOBBY ENTERPRISES
A2: PROPERTY MANAGERS AND ESTATE AGENTS
A3: MAY 2026
I4: P.O.BOX 11987
A5: ANITA PLOT | I5: TEL : 0722711933/4454322
A6: A/C No '0630179417471
A7: Tel No
H8: Care taker | I8: ANITA
H9: Phone no
A10: HSE NO | B10: NAME | C10: PHONE NO | D10: DEPOSIT PAID | E10: MONTHLY RENT | F10: BAL B/D | G10: RENT DUE | H10: RENT PAID | I10: RCT NO | J10: PERIOD | K10: BALANCE | L10: STATUS | M10: FORMS
A11: 1 | B11: RACHAEL | C11: 0741311326 | E11: 5000 | F11: =APR!K11 -> 0 | G11: =D11+E11+F11 -> 5000 | J11: MAY | K11: =G11-H11 -> 5000 | L11: TO EVICT | M11: SIGNED
A12: 2 | B12: IMELDA | C12: '0707746822 | D12: 0 | E12: 4000 | F12: =APR!K12 -> 0 | G12: =D12+E12+F12 -> 4000 | H12: =4000 -> 4000 | I12: UE8Q2348C2 | J12: MAY | K12: =G12-H12 -> 0 | M12: SIGNED | N12: RCTD
A13: 3 | B13: Vacant | D13: 0 | F13: =APR!K13 -> 0 | G13: =D13+E13+F13 -> 0 | J13: MAY | K13: =G13-H13 -> 0 | M13: SIGNED
A14: 4 | B14: GEORGE OUCHA | C14: 0720726146 | E14: 6000 | F14: =APR!K14 -> 0 | G14: =D14+E14+F14 -> 6000 | H14: =6000 -> 6000 | I14: UEB6U3N1Z0 | J14: MAY | K14: =G14-H14 -> 0 | N14: RCTD
A15: 5 | B15: ELIZABETH KURA | C15: 0799945987 | E15: 6500 | F15: =APR!K15 -> 0 | G15: =D15+E15+F15 -> 6500 | H15: =6500 -> 6500 | I15: UEA7F3Z6Q4 | J15: MAY | K15: =G15-H15 -> 0 | N15: RCTD
A16: 6 | B16: SUSAN WANJIKU | C16: 0792878247 | D16: 0 | E16: 6500 | F16: =APR!K16 -> 100 | G16: =D16+E16+F16 -> 6600 | H16: =4500+2000 -> 6500 | I16: UEC7F45G8U/UED7F4BPJB | J16: MAY | K16: =G16-H16 -> 100 | M16: SIGNED | N16: RCTD
A17: 7 | B17: NDUNGÚ KINUTHIA | E17: 5500 | F17: =APR!K17 -> 500 | G17: =D17+E17+F17 -> 6000 | H17: =5500 -> 5500 | I17: UEJ654YU2V | J17: MAY | K17: =G17-H17 -> 500 | M17: SIGNED
A18: 8 | B18: VICTOR KIVUTSI | C18: 0720788630 | D18: 0 | E18: 5000 | F18: =APR!K18 -> 0 | G18: =D18+E18+F18 -> 5000 | H18: =5000 -> 5000 | I18: UEHA551K5F | J18: MAY | K18: =G18-H18 -> 0 | L18: 10th | M18: SIGNED
A19: 9 | B19: ANNASTACIA | C19: 0725869394 | F19: =APR!K19 -> 0 | G19: =D19+E19+F19 -> 0 | J19: MAY | K19: =G19-H19 -> 0
A20: 10 | B20: CHEBITA OMBOGO /OSCAR | C20: 0711275102 | D20: 0 | E20: 3400 | F20: =APR!K20 -> 0 | G20: =D20+E20+F20 -> 3400 | H20: =3400 -> 3400 | I20: UE7223ENT8 | J20: MAY | K20: =G20-H20 -> 0 | M20: SIGNED | N20: RCTD
A21: 11 | B21: BENARD MUTHUI | C21: 0729369553 | D21: 0 | E21: 4500 | F21: =APR!K21 -> 0 | G21: =D21+E21+F21 -> 4500 | H21: =4500 -> 4500 | I21: UEFX3GFZ0 | J21: MAY | K21: =G21-H21 -> 0 | M21: SIGNED | N21: RCTD
A22: 12 | B22: DAVID THIANI | C22: 0715806277 | D22: 0 | E22: 8000 | F22: =APR!K22 -> 3000 | G22: =D22+E22+F22 -> 11000 | H22: =8000 -> 8000 | I22: 7707 | J22: MAY | K22: =G22-H22 -> 3000 | L22: OCT MESSAGE NOT ON STATEMENT | M22: SIGNED
A23: 13 | B23: MARY NYAMBURA(CHURCH) | C23: 0722135696 | D23: 0 | E23: 10000 | F23: =APR!K23 -> 0 | G23: =D23+E23+F23 -> 10000 | H23: =10000 -> 10000 | I23: UEF4G4UV05 | J23: MAY | K23: =G23-H23 -> 0 | L23: 15TH | M23: SIGNED
A24: 14 | B24: Vacant | F24: =APR!K24 -> 0 | G24: =D24+E24+F24 -> 0 | J24: MAY | K24: =G24-H24 -> 0 | M24: SIGNED
A25: 15 | B25: ANNE WANJIRU | C25: 0740712315 | D25: 0 | E25: 10000 | F25: =APR!K25 -> 5000 | G25: =D25+E25+F25 -> 15000 | H25: =4000+2500+2500+4000 -> 13000 | I25: UE6233P9VD/UEL235C3PH/UEP2355H4L/UER2360O32 | J25: MAY | K25: =G25-H25 -> 2000 | L25: REDUCING | M25: SIGNED
A26: 16 | B26: VACANT | F26: =APR!K26 -> 0 | G26: =D26+E26+F26 -> 0 | J26: MAY | K26: =G26-H26 -> 0
A27: 17 | B27: IRENE MAKENA | C27: 0719665779 | E27: 18000 | F27: =APR!K27 -> 0 | G27: =D27+E27+F27 -> 18000 | H27: =18000 -> 18000 | I27: UEDKF43ZFP | J27: MAY | K27: =G27-H27 -> 0 | L27: 10th | M27: SIGNED
A28: 18 | B28: ELIZABETH OMUSE | E28: 9000 | F28: =APR!K28 -> 0 | G28: =D28+E28+F28 -> 9000 | H28: =9000 -> 9000 | I28: UE85D3I5W0 | J28: MAY | K28: =G28-H28 -> 0 | M28: SIGNED | N28: RCTD
A29: 19 | B29: VACANT | F29: =APR!K29 -> 0 | G29: =D29+E29+F29 -> 0 | J29: MAY
A30: Totals | E30: =SUM(E11:E29) -> 101400 | F30: =SUM(F11:F29) -> 8600 | G30: =SUM(G11:G29) -> 110000 | H30: =SUM(H11:H29) -> 99400 | K30: =SUM(K11:K29) -> 10600
A31: Deductions
A32: Less Management fees | H32: =10%*H30 -> 9940
A33: DIRECT
A34: TOTAL DEDUCTIONS | H34: =SUM(H32:H33) -> 9940
A35: BAL B/F | H35: =MAR!K37 -> 0
I36: PAID | J36: PAID | K36: Balance
A37: AMOUNT DUE | H37: =H30-H34+H35 -> 89460 | I37: 70000 | J37: 13960 | K37: =H37-I37-J37 -> 5500
A38: AUTHORISED BY JOSEPH GITHINJI | K38: 46173

Sheet JUNE
C1: LOBBY ENTERPRISES
A2: PROPERTY MANAGERS AND ESTATE AGENTS
A3: JUNE 2026
I4: P.O.BOX 11987
A5: ANITA PLOT | I5: TEL : 0722711933/4454322
A6: A/C No '0630179417471
A7: Tel No
H8: Care taker | I8: ANITA
H9: Phone no
A10: HSE NO | B10: NAME | C10: PHONE NO | D10: DEPOSIT PAID | E10: MONTHLY RENT | F10: BAL B/D | G10: RENT DUE | H10: RENT PAID | I10: RCT NO | J10: PERIOD | K10: BALANCE | L10: STATUS | M10: FORMS
A11: 1 | B11: TENANT | G11: =D11+E11+F11 -> 0 | J11: JUNE | K11: =G11-H11 -> 0 | M11: SIGNED
A12: 2 | B12: IMELDA | C12: '0707746822 | D12: 0 | E12: 4000 | F12: =MAY!K12 -> 0 | G12: =D12+E12+F12 -> 4000 | H12: =4000 -> 4000 | I12: UFBQ26W56S | J12: JUNE | K12: =G12-H12 -> 0 | M12: SIGNED | N12: RCTD
A13: 3 | B13: TENANT | D13: 0 | F13: =MAY!K13 -> 0 | G13: =D13+E13+F13 -> 0 | J13: JUNE | K13: =G13-H13 -> 0 | M13: SIGNED
A14: 4 | B14: GEORGE OUCHA | C14: 0720726146 | E14: 6000 | F14: =MAY!K14 -> 0 | G14: =D14+E14+F14 -> 6000 | H14: =6000 -> 6000 | I14: UF86U6TW2Q | J14: JUNE | K14: =G14-H14 -> 0 | N14: RCTD
A15: 5 | B15: ELIZABETH KURA | C15: 0799945987 | E15: 6500 | F15: =MAY!K15 -> 0 | G15: =D15+E15+F15 -> 6500 | H15: =6500 -> 6500 | I15: UF87F788QM | J15: JUNE | K15: =G15-H15 -> 0 | N15: RCTD
A16: 6 | B16: SUSAN WANJIKU | C16: 0792878247 | D16: 0 | E16: 6500 | F16: =MAY!K16 -> 100 | G16: =D16+E16+F16 -> 6600 | H16: =6000+500 -> 6500 | I16: UF97F7EZKA/UFG7F86BVX | J16: JUNE | K16: =G16-H16 -> 100 | M16: SIGNED | N16: RCTD
A17: 7 | B17: NDUNGÚ KINUTHIA | E17: 5500 | F17: =MAY!K17 -> 500 | G17: =D17+E17+F17 -> 6000 | H17: =5500 -> 5500 | I17: UFN6590PTJ | J17: JUNE | K17: =G17-H17 -> 500 | M17: SIGNED
A18: 8 | B18: VICTOR KIVUTSI | C18: 0720788630 | D18: 0 | E18: 5000 | F18: =MAY!K18 -> 0 | G18: =D18+E18+F18 -> 5000 | H18: =5000 -> 5000 | I18: UFHA58LZHG | J18: JUNE | K18: =G18-H18 -> 0 | L18: 10th | M18: SIGNED
A19: 9 | B19: ANNASTACIA | C19: 0725869394 | F19: =MAY!K19 -> 0 | G19: =D19+E19+F19 -> 0 | J19: JUNE | K19: =G19-H19 -> 0
A20: 10 | B20: CHEBITA OMBOGO /OSCAR | C20: 0711275102 | D20: 0 | E20: 3400 | F20: =MAY!K20 -> 0 | G20: =D20+E20+F20 -> 3400 | H20: =3400 -> 3400 | I20: UF7226ZON5 | J20: JUNE | K20: =G20-H20 -> 0 | M20: SIGNED | N20: RCTD
A21: 11 | B21: BENARD MUTHUI | C21: 0729369553 | D21: 0 | E21: 4500 | F21: =MAY!K21 -> 0 | G21: =D21+E21+F21 -> 4500 | H21: =4500 -> 4500 | I21: UF6FX749LX | J21: JUNE | K21: =G21-H21 -> 0 | M21: SIGNED | N21: RCTD
A22: 12 | B22: DAVID THIANI | C22: 0715806277 | D22: 0 | E22: 8000 | F22: =MAY!K22 -> 3000 | G22: =D22+E22+F22 -> 11000 | H22: =8000 -> 8000 | I22: 3915 | J22: JUNE | K22: =G22-H22 -> 3000 | M22: SIGNED
A23: 13 | B23: MARY NYAMBURA(CHURCH) | C23: 0722135696 | D23: 0 | E23: 10000 | F23: =MAY!K23 -> 0 | G23: =D23+E23+F23 -> 10000 | H23: =10000 -> 10000 | I23: UFG4G8N7UU | J23: JUNE | K23: =G23-H23 -> 0 | L23: 15TH | M23: SIGNED
A24: 14 | B24: Vacant | F24: =MAY!K24 -> 0 | G24: =D24+E24+F24 -> 0 | J24: JUNE | K24: =G24-H24 -> 0 | M24: SIGNED
A25: 15 | B25: ANNE WANJIRU | C25: 0740712315 | D25: 0 | E25: 10000 | F25: =MAY!K25 -> 2000 | G25: =D25+E25+F25 -> 12000 | H25: =7000+2000 -> 9000 | I25: UF238JWEU/UFQ239KGLM | J25: JUNE | K25: =G25-H25 -> 3000 | M25: SIGNED
A26: 16 | B26: VACANT | F26: =MAY!K26 -> 0 | G26: =D26+E26+F26 -> 0 | J26: JUNE | K26: =G26-H26 -> 0
A27: 17 | B27: IRENE MAKENA | C27: 0719665779 | E27: 18000 | F27: =MAY!K27 -> 0 | G27: =D27+E27+F27 -> 18000 | H27: =18000 -> 18000 | I27: UFBKF72T0 | J27: JUNE | K27: =G27-H27 -> 0 | L27: 10th | M27: SIGNED
A28: 18 | B28: ELIZABETH OMUSE | E28: 9000 | F28: =MAY!K28 -> 0 | G28: =D28+E28+F28 -> 9000 | H28: =9000 -> 9000 | I28: UFA5D794YF | J28: JUNE | K28: =G28-H28 -> 0 | M28: SIGNED | N28: RCTD
A29: 19 | B29: VACANT | F29: =MAY!K29 -> 0 | G29: =D29+E29+F29 -> 0 | J29: JUNE
A30: Totals | E30: =SUM(E11:E29) -> 96400 | F30: =SUM(F11:F29) -> 5600 | G30: =SUM(G11:G29) -> 102000 | H30: =SUM(H11:H29) -> 95400 | K30: =SUM(K11:K29) -> 6600
A31: Deductions
A32: Less Management fees | H32: =10%*H30 -> 9540
A33: DIRECT
A34: TOTAL DEDUCTIONS | H34: =SUM(H32:H33) -> 9540
A35: BAL B/F | H35: =MAY!K37 -> 5500
I36: PAID | J36: PAID | K36: Balance
A37: AMOUNT DUE | H37: =H30-H34+H35 -> 91360 | I37: 70000 | K37: =H37-I37-J37 -> 21360
A38: AUTHORISED BY JOSEPH GITHINJI | K38: 46203
H41: =H30/G30*100 -> 93.529412

Sheet JULY
C1: LOBBY ENTERPRISES
A2: PROPERTY MANAGERS AND ESTATE AGENTS
A3: JULY 2026
I4: P.O.BOX 11987
A5: ANITA PLOT | I5: TEL : 0722711933/4454322
A6: A/C No '0630179417471
A7: Tel No
H8: Care taker | I8: ANITA
H9: Phone no
A10: HSE NO | B10: NAME | C10: PHONE NO | D10: DEPOSIT PAID | E10: MONTHLY RENT | F10: BAL B/D | G10: RENT DUE | H10: RENT PAID | I10: RCT NO | J10: PERIOD | K10: BALANCE | L10: STATUS | M10: FORMS
A11: 1 | B11: EUGINE SIMIYU | E11: 5000 | F11: =JUNE!K11 -> 0 | G11: =D11+E11+F11 -> 5000 | H11: =5000 -> 5000 | I11: UG6K2AAEZX | J11: JULY | K11: =G11-H11 -> 0 | M11: SIGNED
A12: 2 | B12: IMELDA | C12: '0707746822 | D12: 0 | E12: 4000 | F12: =JUNE!K12 -> 0 | G12: =D12+E12+F12 -> 4000 | J12: JULY | K12: =G12-H12 -> 4000 | M12: SIGNED | N12: RCTD
A13: 3 | B13: TENANT | D13: 0 | E13: 4000 | F13: =JUNE!K13 -> 0 | G13: =D13+E13+F13 -> 4000 | J13: JULY | K13: =G13-H13 -> 4000 | M13: SIGNED
A14: 4 | B14: GEORGE OUCHA | C14: 0720726146 | E14: 6000 | F14: =JUNE!K14 -> 0 | G14: =D14+E14+F14 -> 6000 | J14: JULY | K14: =G14-H14 -> 6000 | N14: RCTD
A15: 5 | B15: ELIZABETH KURA | C15: 0799945987 | E15: 6500 | F15: =JUNE!K15 -> 0 | G15: =D15+E15+F15 -> 6500 | H15: =6000 -> 6000 | I15: UG67FAHDCH | J15: JULY | K15: =G15-H15 -> 500 | N15: RCTD
A16: 6 | B16: SUSAN WANJIKU | C16: 0792878247 | D16: 0 | E16: 6500 | F16: =JUNE!K16 -> 100 | G16: =D16+E16+F16 -> 6600 | H16: =6500 -> 6500 | I16: UGBCAWJLK | J16: JULY | K16: =G16-H16 -> 100 | M16: SIGNED | N16: RCTD
A17: 7 | B17: NDUNGÚ KINUTHIA | E17: 5500 | F17: =JUNE!K17 -> 500 | G17: =D17+E17+F17 -> 6000 | J17: JULY | K17: =G17-H17 -> 6000 | M17: SIGNED
A18: 8 | B18: VICTOR KIVUTSI | C18: 0720788630 | D18: 0 | E18: 5000 | F18: =JUNE!K18 -> 0 | G18: =D18+E18+F18 -> 5000 | J18: JULY | K18: =G18-H18 -> 5000 | L18: 10th | M18: SIGNED
A19: 9 | B19: ANNASTACIA | C19: 0725869394 | E19: 5000 | F19: =JUNE!K19 -> 0 | G19: =D19+E19+F19 -> 5000 | J19: JULY | K19: =G19-H19 -> 5000
A20: 10 | B20: CHEBITA OMBOGO /OSCAR | C20: 0711275102 | D20: 0 | E20: 3400 | F20: =JUNE!K20 -> 0 | G20: =D20+E20+F20 -> 3400 | H20: =3400 -> 3400 | I20: UG522A7J00 | J20: JULY | K20: =G20-H20 -> 0 | M20: SIGNED | N20: RCTD
A21: 11 | B21: BENARD MUTHUI | C21: 0729369553 | D21: 0 | E21: 4500 | F21: =JUNE!K21 -> 0 | G21: =D21+E21+F21 -> 4500 | H21: =4500 -> 4500 | I21: UG5FXAH8AA | J21: JULY | K21: =G21-H21 -> 0 | M21: SIGNED | N21: RCTD
A22: 12 | B22: DAVID THIANI | C22: 0715806277 | D22: 0 | E22: 8000 | F22: =JUNE!K22 -> 3000 | G22: =D22+E22+F22 -> 11000 | H22: =8000 -> 8000 | I22: UG6C6AKXF6 | J22: JULY | K22: =G22-H22 -> 3000 | M22: SIGNED
A23: 13 | B23: MARY NYAMBURA(CHURCH) | C23: 0722135696 | D23: 0 | E23: 10000 | F23: =JUNE!K23 -> 0 | G23: =D23+E23+F23 -> 10000 | J23: JULY | K23: =G23-H23 -> 10000 | L23: 15TH | M23: SIGNED
A24: 14 | B24: TENANT | E24: 4500 | F24: =JUNE!K24 -> 0 | G24: =D24+E24+F24 -> 4500 | J24: JULY | K24: =G24-H24 -> 4500 | M24: SIGNED
A25: 15 | B25: ANNE WANJIRU | C25: 0740712315 | D25: 0 | E25: 10000 | F25: =JUNE!K25 -> 3000 | G25: =D25+E25+F25 -> 13000 | H25: =1500 -> 1500 | I25: UG323AEOIU | J25: JULY | K25: =G25-H25 -> 11500 | M25: SIGNED
A26: 16 | B26: TENANT | E26: 8000 | F26: =JUNE!K26 -> 0 | G26: =D26+E26+F26 -> 8000 | J26: JULY | K26: =G26-H26 -> 8000
A27: 17 | B27: IRENE MAKENA | C27: 0719665779 | E27: 18000 | F27: =JUNE!K27 -> 0 | G27: =D27+E27+F27 -> 18000 | H27: =18000 -> 18000 | I27: UGAIAVHFO | J27: JULY | K27: =G27-H27 -> 0 | L27: 10th | M27: SIGNED
A28: 18 | B28: ELIZABETH OMUSE | E28: 9000 | F28: =JUNE!K28 -> 0 | G28: =D28+E28+F28 -> 9000 | H28: =9000 -> 9000 | I28: UG95DAL7VE | J28: JULY | K28: =G28-H28 -> 0 | M28: SIGNED | N28: RCTD
A29: 19 | B29: TENANT | E29: 10000 | F29: =JUNE!K29 -> 0 | G29: =D29+E29+F29 -> 10000 | J29: JULY | K29: =G29-H29 -> 10000
A30: Totals | E30: =SUM(E11:E29) -> 132900 | F30: =SUM(F11:F29) -> 6600 | G30: =SUM(G11:G29) -> 139500 | H30: =SUM(H11:H29) -> 61900 | K30: =SUM(K11:K29) -> 77600
A31: Deductions
A32: Less Management fees | H32: =10%*H30 -> 6190
A33: DIRECT
A34: TOTAL DEDUCTIONS | H34: =SUM(H32:H33) -> 6190
A35: BAL B/F | H35: =JUNE!K37 -> 21360
I36: PAID | J36: PAID | K36: Balance
A37: AMOUNT DUE | H37: =H30-H34+H35 -> 77070 | K37: =H37-I37-J37 -> 77070
A38: AUTHORISED BY JOSEPH GITHINJI | K38: 46234
H41: =H30/G30*100 -> 44.37276
