Workbook

Sheet JAN
B1: LOBBY ENTERPRISES
A2: PROPERTY MANAGERS AND ESTATE AGENTS
A3: JAN 2026
K4: P.O.BOX 11987
A5: APPHIA APARTMENTS | K5: TEL :
A6: STATEMENT OF ACCOUNT
A7: NCBA PAYBILL '6432500027 | C7: 880100 | J7: Caretaker | K7: KELVIN
J8: Phone no | K8: 0714418782
A9: NAME | C9: CONTACT | D9: DEPOSIT PAID | E9: MONTHLY RENT | F9: BAL B/D | G9: GARBAGE | H9: WATER BILLS | I9: RENT DUE | J9: RENT PAID | K9: RCT NO | L9: PERIOD | M9: BALANCE | N9: STATUS | O9: FORMS
A10: A1 | B10: MAULINE MALESI | C10: 0743508108 | D10: 0 | E10: 7500 | F10: -7600 | G10: 100 | H10: 500 | I10: =D10+E10+F10+G10+H10 -> 500 | L10: JAN | M10: =I10-J10 -> 500 | O10: SIGNED | Q10: THAMANDA | R10: 150000
A11: A2 | B11: PETER | C11: 0719820676 | E11: 7500 | F11: 700 | G11: 100 | H11: 250 | I11: =D11+E11+F11+G11+H11 -> 8550 | J11: =8000 -> 8000 | K11: 1018(13TH DEC) | L11: JAN | M11: =I11-J11 -> 550 | O11: SIGNED | Q11: KINOO | R11: 50000
A12: A3 | B12: Chrispine ooko | C12: 0712271588 | D12: 0 | E12: 7500 | F12: 600 | G12: 100 | H12: 500 | I12: =D12+E12+F12+G12+H12 -> 8700 | J12: =8000 -> 8000 | K12: UAH0E3YW9O | L12: JAN | M12: =I12-J12 -> 700 | N12: 10TH | O12: SIGNED | Q12: KAGWE | R12: 140208
A13: A4 | B13: YASEER | C13: 0783047456 | D13: 0 | E13: 7500 | F13: -300 | G13: 100 | H13: 0 | I13: =D13+E13+F13+G13+H13 -> 7300 | J13: =7500 -> 7500 | K13: UAMJX4DV8Z | L13: JAN | M13: =I13-J13 -> -200 | O13: SIGNED | Q13: KIBALI | R13: 32850
A14: A5 | B14: VACANT | H14: 0 | I14: =D14+E14+F14+G14+H14 -> 0 | L14: JAN | M14: =I14-J14 -> 0 | O14: SIGNED | Q14: NJENGA | R14: 32160
A15: A6 | B15: Vincent Mambili | C15: 0710558651 | D15: 0 | E15: 7500 | F15: 950 | G15: 100 | H15: 250 | I15: =D15+E15+F15+G15+H15 -> 8800 | J15: =8800 -> 8800 | K15: UAADW3F5WR | L15: JAN | M15: =I15-J15 -> 0 | O15: SIGNED | Q15: KANGETHE | R15: 38250
A16: B1 | B16: AMOS/STANLEY | C16: 0729892835 | E16: 7500 | F16: 8300 | G16: 100 | H16: 250 | I16: =D16+E16+F16+G16+H16 -> 16150 | J16: =2000+1000+1500+4000 -> 8500 | K16: UAAOC3DUHE/UAGOC400QS/UALOC4E7WL/UAUEZ5DCKM | L16: JAN | M16: =I16-J16 -> 7650 | N16: LOCKED | O16: SIGNED | Q16: R.EAST | R16: 50000
A17: B2 | B17: PETER KARIUKI | C17: 0723743290 | D17: 0 | E17: 7500 | F17: -350 | G17: 100 | H17: 0 | I17: =D17+E17+F17+G17+H17 -> 7250 | J17: =7500+500 -> 8000 | K17: 9889/1845 | L17: JAN | M17: =I17-J17 -> -750 | O17: SIGNED | Q17: JAGIET | R17: 60000
A18: B3 | B18: CYTHIA | C18: 0772369562 | E18: 7500 | F18: -4150 | G18: 100 | H18: 500 | I18: =D18+E18+F18+G18+H18 -> 3950 | L18: JAN | M18: =I18-J18 -> 3950 | O18: SIGNED | Q18: GHETTO | R18: 150000
A19: B4 | B19: Bernice Yvonne | C19: 0705481466 | D19: 0 | E19: 7500 | F19: 2400 | G19: 100 | H19: 250 | I19: =D19+E19+F19+G19+H19 -> 10250 | J19: =8100 -> 8100 | K19: UA9MM3DUJY | L19: JAN | M19: =I19-J19 -> 2150 | N19: 10TH | O19: SIGNED | Q19: NYALI | R19: 190000
A20: B5 | B20: George Kirigo | C20: 0710152025 | D20: 0 | E20: 7500 | F20: =[1]DEC!$M$20 -> 0 | G20: 100 | H20: 0 | I20: =D20+E20+F20+G20+H20 -> 7600 | J20: =7600 -> 7600 | K20: UA5DA2TWRR | L20: JAN | M20: =I20-J20 -> 0 | O20: SIGNED | Q20: APPHIA | R20: 100000
A21: B6 | B21: Dina Mdombi | C21: 0704588355 | D21: 0 | E21: 7500 | F21: 400 | G21: 100 | H21: 250 | I21: =D21+E21+F21+G21+H21 -> 8250 | J21: =7750 -> 7750 | K21: UA9CS36V5B | L21: JAN | M21: =I21-J21 -> 500 | N21: 10TH | O21: SIGNED | Q21: SPICES | R21: 30000
A22: C1 | B22: GEOFFREY OMUSE | C22: 0748039842 | D22: 0 | E22: 7000 | F22: 1250 | G22: 100 | H22: 250 | I22: =D22+E22+F22+G22+H22 -> 8600 | J22: =7000 -> 7000 | K22: UA3QM2URZQ | L22: JAN | M22: =I22-J22 -> 1600 | O22: SIGNED | Q22: FRANCIS | R22: 11500
A23: C2 | B23: Esther John | C23: 0723307353 | D23: 0 | E23: 7000 | F23: 250 | G23: 100 | H23: 0 | I23: =D23+E23+F23+G23+H23 -> 7350 | J23: =7350 -> 7350 | K23: UA5P02TYNA | L23: JAN | M23: =I23-J23 -> 0 | O23: SIGNED | Q23: JAMES | R23: 15500
A24: C3 | B24: DICKSON ZAWADI | C24: 0757132539* | E24: 7000 | F24: 500 | G24: 100 | H24: 0 | I24: =D24+E24+F24+G24+H24 -> 7600 | J24: =7100+500 -> 7600 | K24: UA87C368DX/UAO7C4LXMD | L24: JAN | M24: =I24-J24 -> 0 | O24: SIGNED | Q24: ADRIAN | R24: 43800
A25: C4 | B25: JAMES BETHUEL | C25: 0724771903 | D25: 0 | E25: 7000 | F25: =[1]DEC!$M$25 -> 250 | G25: 100 | H25: 500 | I25: =D25+E25+F25+G25+H25 -> 7850 | J25: =7600 -> 7600 | K25: UA57O2UEAZ | L25: JAN | M25: =I25-J25 -> 250 | O25: SIGNED | R25: =SUM(R10:R24) -> 1094268
A26: C5 | B26: ISAAC ARABU | C26: 0745762814 | D26: 0 | E26: 7000 | F26: -100 | G26: 100 | H26: 0 | I26: =D26+E26+F26+G26+H26 -> 7000 | J26: =7300 -> 7300 | K26: UA7O733CZ7 | L26: JAN | M26: =I26-J26 -> -300 | N26: 10TH | O26: SIGNED
A27: C6 | B27: CARETAKER | C27: 0714418782 | F27: 0 | H27: 0 | I27: =D27+E27+F27+G27+H27 -> 0 | L27: JAN | M27: =I27-J27 -> 0 | O27: SIGNED
A28: Totals | D28: =SUM(D10:D27) -> 0 | E28: =SUM(E10:E27) -> 117500 | F28: =SUM(F10:F27) -> 3100 | G28: =SUM(G10:G27) -> 1600 | H28: =SUM(H10:H27) -> 3500 | I28: =SUM(I10:I27) -> 125700 | J28: =SUM(J10:J27) -> 109100 | M28: =SUM(M10:M27) -> 16600
A30: Less Management fees | J30: =8%*(J28-H28-G28-D28) -> 8320
A31: TOKENS | J31: =500+1000+1000 -> 2500
A32: GARBAGE | J32: 1700
A33: WATER METER CLEANING | J33: 1000
A34: SILK/FILLER/WAGE/UNDERCOAT HSE A5 | J34: 5000
A35: Waterbill | J35: 8370
A36: TOTAL DEDUCTIONS | J36: =SUM(J30:J35) -> 26890
K37: 0
A38: BAL B/F | J38: =[1]DEC!$M$39 -> -800
K39: Paid | L39: Paid | M39: Balance
A40: Amount Due | J40: =J28-J36+J38 -> 81410 | K40: 100000 | M40: =J40-K40-L40 -> -18590
A42: AUTHORISED BY JOSEPH GITHINJI | M42: 46053
...

Sheet FEB
B1: LOBBY ENTERPRISES
A2: PROPERTY MANAGERS AND ESTATE AGENTS
A3: FEB 2026
K4: P.O.BOX 11987
A5: APPHIA APARTMENTS | K5: TEL :
A6: STATEMENT OF ACCOUNT
A7: NCBA PAYBILL '6432500027 | C7: 880100 | J7: Caretaker | K7: KELVIN
J8: Phone no | K8: 0714418782
A9: NAME | C9: CONTACT | D9: DEPOSIT PAID | E9: MONTHLY RENT | F9: BAL B/D | G9: GARBAGE | H9: WATER BILLS | I9: RENT DUE | J9: RENT PAID | K9: RCT NO | L9: PERIOD | M9: BALANCE | N9: STATUS | O9: FORMS
A10: A1 | B10: MAULINE MALESI | C10: 0743508108 | D10: 0 | E10: 7500 | F10: =JAN!M10 -> 500 | G10: 100 | H10: 750 | I10: =D10+E10+F10+G10+H10 -> 8850 | J10: 8600 | K10: 3738 | L10: FEB | M10: =I10-J10 -> 250 | O10: SIGNED | Q10: THAMANDA | R10: 150000
A11: A2 | B11: PETER | C11: 0719820676 | E11: 7500 | F11: =JAN!M11 -> 550 | G11: 100 | H11: 500 | I11: =D11+E11+F11+G11+H11 -> 8650 | J11: =7750 -> 7750 | K11: UB9U978F2Q | L11: FEB | M11: =I11-J11 -> 900 | O11: SIGNED | Q11: KINOO | R11: 50000
A12: A3 | B12: Chrispine ooko | C12: 0712271588 | D12: 0 | E12: 7500 | F12: =JAN!M12 -> 700 | G12: 100 | H12: 750 | I12: =D12+E12+F12+G12+H12 -> 9050 | J12: =8250 -> 8250 | K12: UBD0E6JSXO | L12: FEB | M12: =I12-J12 -> 800 | N12: 10TH | O12: SIGNED | Q12: KAGWE | R12: 140208
A13: A4 | B13: YASEER | C13: 0783047456 | D13: 0 | E13: 7500 | F13: =JAN!M13 -> -200 | G13: 100 | H13: 0 | I13: =D13+E13+F13+G13+H13 -> 7400 | J13: =3000+4500 -> 7500 | K13: UBCJX6EVCQ/UBLJX79S3H | L13: FEB | M13: =I13-J13 -> -100 | O13: SIGNED | Q13: KIBALI | R13: 32850
A14: A5 | B14: ABDUL RAHMAN | C14: 0725903270/0751934076 | D14: 7500 | E14: 7500 | F14: =JAN!M14 -> 0 | G14: 100 | H14: 0 | I14: =D14+E14+F14+G14+H14 -> 15100 | J14: =6000+3000 -> 9000 | K14: UB9S02QUM6/UBO717EX9D | L14: FEB | M14: =I14-J14 -> 6100 | N14: MARCH BOOKING | O14: SIGNED | Q14: NJENGA | R14: 32160
A15: A6 | B15: Vincent Mambili | C15: 0710558651 | E15: 7500 | F15: =JAN!M15 -> 0 | G15: 100 | H15: 500 | I15: =D15+E15+F15+G15+H15 -> 8100 | J15: =8000 -> 8000 | K15: UB5DW5VGGL | L15: FEB | M15: =I15-J15 -> 100 | O15: SIGNED | Q15: KANGETHE | R15: 38250
A16: B1 | B16: AMOS/STANLEY | C16: 0729892835 | E16: 7500 | F16: =JAN!M16 -> 7650 | G16: 100 | H16: 250 | I16: =D16+E16+F16+G16+H16 -> 15500 | J16: =4000+1000+2000+3500 -> 10500 | K16: UB9EZ6CCBG/UBAEZ6GYY4/UBLEZ7G8TW/UBSEZ845VL | L16: FEB | M16: =I16-J16 -> 5000 | O16: SIGNED | Q16: R.EAST | R16: 50000
A17: B2 | B17: PETER KARIUKI | C17: 0723743290 | D17: 0 | E17: 7500 | F17: =JAN!M17 -> -750 | G17: 100 | H17: 250 | I17: =D17+E17+F17+G17+H17 -> 7100 | J17: =500+7500 -> 8000 | K17: 2071/1234 | L17: FEB | M17: =I17-J17 -> -900 | O17: SIGNED | Q17: JAGIET | R17: 60000
A18: B3 | B18: CYTHIA | C18: 0772369562 | E18: 7500 | F18: =JAN!M18 -> 3950 | G18: 100 | H18: 750 | I18: =D18+E18+F18+G18+H18 -> 12300 | J18: =9000 -> 9000 | K18: UB4SB76D2E | L18: FEB | M18: =I18-J18 -> 3300 | O18: SIGNED | Q18: GHETTO | R18: 150000
A19: B4 | B19: Bernice Yvonne | C19: 0705481466 | D19: 0 | E19: 7500 | F19: =JAN!M19 -> 2150 | G19: 100 | H19: 500 | I19: =D19+E19+F19+G19+H19 -> 10250 | J19: =8100 -> 8100 | K19: UB9MM6BKW0 | L19: FEB | M19: =I19-J19 -> 2150 | N19: 10TH | O19: SIGNED | Q19: NYALI | R19: 190000
A20: B5 | B20: George Kirigo | C20: 0710152025 | D20: 0 | E20: 7500 | F20: =JAN!M20 -> 0 | G20: 100 | I20: =D20+E20+F20+G20+H20 -> 7600 | J20: =7750 -> 7750 | K20: UB4DA5KJGR | L20: FEB | M20: =I20-J20 -> -150 | O20: SIGNED | Q20: APPHIA | R20: 100000
A21: B6 | B21: Dina Mdombi | C21: 0704588355 | D21: 0 | E21: 7500 | F21: =JAN!M21 -> 500 | G21: 100 | H21: 500 | I21: =D21+E21+F21+G21+H21 -> 8600 | J21: =8100 -> 8100 | K21: UB5CS5M4RG | L21: FEB | M21: =I21-J21 -> 500 | N21: 10TH | O21: SIGNED | Q21: SPICES | R21: 30000
A22: C1 | B22: GEOFFREY OMUSE | C22: 0748039842 | D22: 0 | E22: 7000 | F22: =JAN!M22 -> 1600 | G22: 100 | H22: 500 | I22: =D22+E22+F22+G22+H22 -> 9200 | J22: =7500 -> 7500 | K22: UB6QM613N8 | L22: FEB | M22: =I22-J22 -> 1700 | O22: SIGNED | Q22: FRANCIS | R22: 11500
A23: C2 | B23: Esther John | C23: 0723307353 | D23: 0 | E23: 7000 | F23: =JAN!M23 -> 0 | G23: 100 | H23: 500 | I23: =D23+E23+F23+G23+H23 -> 7600 | J23: =7600 -> 7600 | K23: UB5P05OXV9 | L23: FEB | M23: =I23-J23 -> 0 | O23: SIGNED | Q23: JAMES | R23: 15500
A24: C3 | B24: DICKSON ZAWADI | C24: 0757132539* | E24: 7000 | F24: =JAN!M24 -> 0 | G24: 100 | H24: 250 | I24: =D24+E24+F24+G24+H24 -> 7350 | J24: =6000+1350 -> 7350 | K24: UBF7C6OJFF/UBJ7C72KW3 | L24: FEB | M24: =I24-J24 -> 0 | O24: SIGNED | Q24: ADRIAN | R24: 43800
A25: C4 | B25: JAMES BETHUEL | C25: 0724771903 | D25: 0 | E25: 7000 | F25: =JAN!M25 -> 250 | G25: 100 | H25: 750 | I25: =D25+E25+F25+G25+H25 -> 8100 | J25: =7600 -> 7600 | K25: UB57O5Q0TQ | L25: FEB | M25: =I25-J25 -> 500 | O25: SIGNED | R25: =SUM(R10:R24) -> 1094268
A26: C5 | B26: ISAAC ARABU | C26: 0745762814 | D26: 0 | E26: 7000 | F26: =JAN!M26 -> -300 | G26: 100 | H26: 0 | I26: =D26+E26+F26+G26+H26 -> 6800 | J26: =7100 -> 7100 | K26: UB8O763KBV | L26: FEB | M26: =I26-J26 -> -300 | N26: 10TH | O26: SIGNED
A27: C6 | B27: CARETAKER | C27: 0714418782 | F27: =JAN!M27 -> 0 | H27: 0 | I27: =D27+E27+F27+G27+H27 -> 0 | L27: FEB | M27: =I27-J27 -> 0 | O27: SIGNED
A28: Totals | D28: =SUM(D10:D27) -> 7500 | E28: =SUM(E10:E27) -> 125000 | F28: =SUM(F10:F27) -> 16600 | G28: =SUM(G10:G27) -> 1700 | H28: =SUM(H10:H27) -> 6750 | I28: =SUM(I10:I27) -> 157550 | J28: =SUM(J10:J27) -> 137700 | M28: =SUM(M10:M27) -> 19850
A30: Less Management fees | J30: =8%*(J28-H28-G28-D28) -> 9740
A31: TOKENS | J31: =1000+1000 -> 2000
A32: KURIA GARBAGE | J32: =1700 -> 1700
A33: KPLC METER REPAIR | J33: =1000 -> 1000
A34: WATER METER CLEANING | J34: =1000 -> 1000
A35: CISTERN REPAIR/WAGE HSE A2 | J35: =1000 -> 1000
A36: Waterbill | J36: =8300 -> 8300
A37: TOTAL DEDUCTIONS | J37: =SUM(J30:J36) -> 24740
K38: 0
A39: BAL B/F | J39: =JAN!M40 -> -18590
K40: Paid | L40: Paid | M40: Balance
A41: Amount Due | J41: =J28-J37+J39 -> 94370 | K41: 80000 | L41: 14570 | M41: =J41-K41-L41 -> -200
...

Sheet MAR
B1: LOBBY ENTERPRISES
A2: PROPERTY MANAGERS AND ESTATE AGENTS
A3: MAR 2026
K4: P.O.BOX 11987
A5: APPHIA APARTMENTS | K5: TEL :
A6: STATEMENT OF ACCOUNT
A7: NCBA PAYBILL '6432500027 | C7: 880100 | J7: Caretaker | K7: KELVIN
J8: Phone no | K8: 0714418782
A9: NAME | C9: CONTACT | D9: DEPOSIT PAID | E9: MONTHLY RENT | F9: BAL B/D | G9: GARBAGE | H9: WATER BILLS | I9: RENT DUE | J9: RENT PAID | K9: RCT NO | L9: PERIOD | M9: BALANCE | N9: STATUS | O9: FORMS
A10: A1 | B10: MAULINE MALESI | C10: 0743508108 | D10: 0 | E10: 7500 | F10: =FEB!M10 -> 250 | G10: 100 | H10: 500 | I10: =D10+E10+F10+G10+H10 -> 8350 | J10: =8350 -> 8350 | K10: UC9JC8WLKK | L10: MAR | M10: =I10-J10 -> 0 | O10: SIGNED | Q10: THAMANDA | R10: 150000
A11: A2 | B11: PETER | C11: 0719820676 | E11: 7500 | F11: =FEB!M11 -> 900 | G11: 100 | H11: 500 | I11: =D11+E11+F11+G11+H11 -> 9000 | J11: =7850 -> 7850 | K11: UC9U98EHCI | L11: MAR | M11: =I11-J11 -> 1150 | O11: SIGNED | Q11: KINOO | R11: 50000
A12: A3 | B12: Chrispine ooko | C12: 0712271588 | D12: 0 | E12: 7500 | F12: =FEB!M12 -> 800 | G12: 100 | H12: 450 | I12: =D12+E12+F12+G12+H12 -> 8850 | J12: =7950 -> 7950 | K12: UCG0E9F9L4 | L12: MAR | M12: =I12-J12 -> 900 | N12: 10TH | O12: SIGNED | Q12: KAGWE | R12: 140208
A13: A4 | B13: YASEER | C13: 0783047456 | D13: 0 | E13: 7500 | F13: =FEB!M13 -> -100 | G13: 100 | H13: 150 | I13: =D13+E13+F13+G13+H13 -> 7650 | L13: MAR | M13: =I13-J13 -> 7650 | N13: LOCKED | O13: SIGNED | Q13: KIBALI | R13: 32850
A14: A5 | B14: ABDUL RAHMAN | C14: 0725903270/0751934076 | F14: =FEB!M14 -> 6100 | G14: 100 | I14: =D14+E14+F14+G14+H14 -> 6200 | J14: =6200 -> 6200 | K14: UCB718UDOB | L14: MAR | M14: =I14-J14 -> 0 | O14: SIGNED | Q14: NJENGA | R14: 32160
A15: A6 | B15: Vincent Mambili | C15: 0710558651 | E15: 7500 | F15: =FEB!M15 -> 100 | G15: 100 | H15: 250 | I15: =D15+E15+F15+G15+H15 -> 7950 | J15: =7500 -> 7500 | K15: UC6DW8JI5G | L15: MAR | M15: =I15-J15 -> 450 | O15: SIGNED | Q15: KANGETHE | R15: 38250
A16: B1 | B16: AMOS/STANLEY | C16: 0729892835 | E16: 7500 | F16: =FEB!M16 -> 5000 | G16: 100 | H16: 0 | I16: =D16+E16+F16+G16+H16 -> 12600 | J16: =2500+4000+2000+3800 -> 12300 | K16: UC2EZ8C47K/UCA5C8Z7IR/UCD5C9AAE4/UCRMEAMTKJ | L16: MAR | M16: =I16-J16 -> 300 | O16: SIGNED | Q16: R.EAST | R16: 50000
A17: B2 | B17: PETER KARIUKI | C17: 0723743290 | D17: 0 | E17: 7500 | F17: =FEB!M17 -> -900 | G17: 100 | H17: 250 | I17: =D17+E17+F17+G17+H17 -> 6950 | J17: =7500+500 -> 8000 | K17: 2ND MAR | L17: MAR | M17: =I17-J17 -> -1050 | O17: SIGNED | Q17: JAGIET | R17: 60000
A18: B3 | B18: CYTHIA | C18: 0772369562 | E18: 7500 | F18: =FEB!M18 -> 3300 | G18: 100 | H18: 0 | I18: =D18+E18+F18+G18+H18 -> 10900 | J18: =500+8000 -> 8500 | K18: ELECTRICAL (IAN)/UCA2H98O2Y | L18: MAR | M18: =I18-J18 -> 2400 | O18: SIGNED | Q18: GHETTO | R18: 150000
A19: B4 | B19: Bernice Yvonne | C19: 0705481466 | D19: 0 | E19: 7500 | F19: =FEB!M19 -> 2150 | G19: 100 | H19: 425 | I19: =D19+E19+F19+G19+H19 -> 10175 | J19: =8100 -> 8100 | K19: UC9MM8ZAZC | L19: MAR | M19: =I19-J19 -> 2075 | N19: 10TH | O19: SIGNED | Q19: NYALI | R19: 190000
A20: B5 | B20: George Kirigo | C20: 0710152025 | D20: 0 | E20: 7500 | F20: =FEB!M20 -> -150 | G20: 100 | H20: 300 | I20: =D20+E20+F20+G20+H20 -> 7750 | J20: =7600 -> 7600 | K20: UC5DA8A4LQ | L20: MAR | M20: =I20-J20 -> 150 | O20: SIGNED | Q20: APPHIA | R20: 100000
A21: B6 | B21: Dina Mdombi | C21: 0704588355 | D21: 0 | E21: 7500 | F21: =FEB!M21 -> 500 | G21: 100 | H21: 250 | I21: =D21+E21+F21+G21+H21 -> 8350 | J21: =7850 -> 7850 | K21: UCACS8OZDV | L21: MAR | M21: =I21-J21 -> 500 | N21: 10TH | O21: SIGNED | Q21: SPICES | R21: 30000
A22: C1 | B22: GEOFFREY OMUSE | C22: 0748039842 | D22: 0 | E22: 7000 | F22: =FEB!M22 -> 1700 | G22: 100 | H22: 350 | I22: =D22+E22+F22+G22+H22 -> 9150 | J22: =7000 -> 7000 | K22: UCAQM9270R | L22: MAR | M22: =I22-J22 -> 2150 | O22: SIGNED | Q22: FRANCIS | R22: 11500
A23: C2 | B23: Esther John | C23: 0723307353 | D23: 0 | E23: 7000 | F23: =FEB!M23 -> 0 | G23: 100 | H23: 250 | I23: =D23+E23+F23+G23+H23 -> 7350 | J23: =7350 -> 7350 | K23: UC5P08BRLO | L23: MAR | M23: =I23-J23 -> 0 | O23: SIGNED | Q23: JAMES | R23: 15500
A24: C3 | B24: DICKSON ZAWADI | C24: 0757132539* | E24: 7000 | F24: =FEB!M24 -> 0 | G24: 100 | H24: 250 | I24: =D24+E24+F24+G24+H24 -> 7350 | J24: =7100 -> 7100 | K24: UC57C8FHP3 | L24: MAR | M24: =I24-J24 -> 250 | O24: SIGNED | Q24: ADRIAN | R24: 43800
A25: C4 | B25: JAMES BETHUEL | C25: 0724771903 | D25: 0 | E25: 7000 | F25: =FEB!M25 -> 500 | G25: 100 | H25: 500 | I25: =D25+E25+F25+G25+H25 -> 8100 | J25: =7600 -> 7600 | K25: UC57O8CRX2 | L25: MAR | M25: =I25-J25 -> 500 | O25: SIGNED | R25: =SUM(R10:R24) -> 1094268
A26: C5 | B26: ISAAC ARABU | C26: 0745762814 | D26: 0 | E26: 7000 | F26: =FEB!M26 -> -300 | G26: 100 | H26: 0 | I26: =D26+E26+F26+G26+H26 -> 6800 | J26: =7300 -> 7300 | K26: UCAO78V57O | L26: MAR | M26: =I26-J26 -> -500 | N26: 10TH | O26: SIGNED
A27: C6 | B27: CARETAKER | C27: 0714418782 | F27: =FEB!M27 -> 0 | H27: 0 | I27: =D27+E27+F27+G27+H27 -> 0 | L27: MAR | M27: =I27-J27 -> 0 | O27: SIGNED
A28: Totals | D28: =SUM(D10:D27) -> 0 | E28: =SUM(E10:E27) -> 117500 | F28: =SUM(F10:F27) -> 19850 | G28: =SUM(G10:G27) -> 1700 | H28: =SUM(H10:H27) -> 4425 | I28: =SUM(I10:I27) -> 143475 | J28: =SUM(J10:J27) -> 126550 | M28: =SUM(M10:M27) -> 16925
A30: Less Management fees | J30: =8%*(J28-H28-G28-D28) -> 9634
A31: TOKENS | J31: =1000+1000+1000 -> 3000
A32: ELECTRICAL REPAIRS HSE B3 | J32: 500
A33: KURIA GARBAGE | J33: =1700 -> 1700
A34: Waterbill | J34: =8300 -> 8300
A35: WATER METER CLEANING | J35: =1000 -> 1000
A36: MAGIC CONNECTOR/WAGE | J36: =750 -> 750
A37: GATE WELDING REPAIR/TAMPER CODE REQUEST/METER REPAIR | J37: =3000 -> 3000
A39: TOTAL DEDUCTIONS | J39: =SUM(J30:J38) -> 27884
K40: 0
A41: BAL B/F | J41: =FEB!M41 -> -200
K42: Paid | L42: Paid | M42: Balance
...

Sheet APR
B1: LOBBY ENTERPRISES
A2: PROPERTY MANAGERS AND ESTATE AGENTS
A3: APR 2026
K4: P.O.BOX 11987
A5: APPHIA APARTMENTS | K5: TEL :
A6: STATEMENT OF ACCOUNT
A7: NCBA PAYBILL '6432500027 | C7: 880100 | J7: Caretaker | K7: KELVIN
J8: Phone no | K8: 0714418782
A9: NAME | C9: CONTACT | D9: DEPOSIT PAID | E9: MONTHLY RENT | F9: BAL B/D | G9: GARBAGE | H9: WATER BILLS | I9: RENT DUE | J9: RENT PAID | K9: RCT NO | L9: PERIOD | M9: BALANCE | N9: STATUS | O9: FORMS
A10: A1 | B10: MAULINE MALESI | C10: 0743508108 | D10: 0 | E10: 7500 | F10: =MAR!M10 -> 0 | G10: 100 | H10: 750 | I10: =D10+E10+F10+G10+H10 -> 8350 | J10: =8350 -> 8350 | K10: UD7JC04NGE | L10: APR | M10: =I10-J10 -> 0 | O10: SIGNED | Q10: THAMANDA | R10: 150000 | S10: RCTD
A11: A2 | B11: PETER | C11: 0719820676 | E11: 7500 | F11: =MAR!M11 -> 1150 | G11: 100 | H11: 500 | I11: =D11+E11+F11+G11+H11 -> 9250 | J11: =8100 -> 8100 | K11: UD8U99N8XP | L11: APR | M11: =I11-J11 -> 1150 | O11: SIGNED | Q11: KINOO | R11: 50000
A12: A3 | B12: Chrispine ooko | C12: 0712271588 | D12: 0 | E12: 7500 | F12: =MAR!M12 -> 900 | G12: 100 | H12: 250 | I12: =D12+E12+F12+G12+H12 -> 8750 | J12: =7750 -> 7750 | K12: UDH0E13M0X | L12: APR | M12: =I12-J12 -> 1000 | N12: 10TH | O12: SIGNED | Q12: KAGWE | R12: 140208
A13: A4 | B13: YASEER | C13: 0783047456 | D13: 0 | E13: 7500 | F13: =MAR!M13 -> 7650 | G13: 100 | H13: 250 | I13: =D13+E13+F13+G13+H13 -> 15500 | J13: =7500+7500 -> 15000 | K13: UDAJX0BU4O/UDMJX1KT77 | L13: APR | M13: =I13-J13 -> 500 | N13: LOCKED | O13: SIGNED | Q13: KIBALI | R13: 32850 | S13: RCTD
A14: A5 | B14: ABDUL RAHMAN | C14: 0725903270/0751934076 | E14: 7500 | F14: =MAR!M14 -> 0 | G14: 100 | H14: 250 | I14: =D14+E14+F14+G14+H14 -> 7850 | J14: =2500+2600+2750 -> 7850 | K14: UD671BLAE4/UDC710FRQZ/UDH710XBTJ | L14: APR | M14: =I14-J14 -> 0 | N14: 10TH | O14: SIGNED | Q14: NJENGA | R14: 32160 | S14: RCTD
A15: A6 | B15: Vincent Mambili | C15: 0710558651 | E15: 7500 | F15: =MAR!M15 -> 450 | G15: 100 | H15: 500 | I15: =D15+E15+F15+G15+H15 -> 8550 | J15: =7200 -> 7200 | K15: UD7DW04LAB | L15: APR | M15: =I15-J15 -> 1350 | O15: SIGNED | Q15: KANGETHE | R15: 38250 | S15: RCTD
A16: B1 | B16: AMOS/STANLEY | C16: 0729892835 | E16: 7500 | F16: =MAR!M16 -> 300 | G16: 100 | H16: 500 | I16: =D16+E16+F16+G16+H16 -> 8400 | J16: =3200+1500 -> 4700 | K16: UDA5C0EXG9/UDK5C1JBQQ | L16: APR | M16: =I16-J16 -> 3700 | O16: SIGNED | Q16: R.EAST | R16: 50000 | S16: RCTD
A17: B2 | B17: PETER KARIUKI | C17: 0723743290 | D17: 0 | E17: 7500 | F17: =MAR!M17 -> -1050 | G17: 100 | H17: 750 | I17: =D17+E17+F17+G17+H17 -> 7300 | J17: =7500+500 -> 8000 | K17: 2701/'0812 | L17: APR | M17: =I17-J17 -> -700 | O17: SIGNED | Q17: JAGIET | R17: 60000
A18: B3 | B18: VACANT | I18: =D18+E18+F18+G18+H18 -> 0 | L18: APR | M18: =I18-J18 -> 0 | O18: SIGNED | Q18: GHETTO | R18: 150000
A19: B4 | B19: CYTHIA MADESHE | C19: 0772369562 | E19: 7500 | F19: 2400 | G19: 100 | H19: 750 | I19: =D19+E19+F19+G19+H19 -> 10750 | J19: 7500 | K19: UD32HBT1PK/UD82H0IKY1 | L19: APR | M19: =I19-J19 -> 3250 | O19: SIGNED | Q19: GHETTO | R19: 150000 | S19: RCTD
A20: B5 | B20: George Kirigo | C20: 0710152025 | D20: 0 | E20: 7500 | F20: =MAR!M20 -> 150 | G20: 100 | I20: =D20+E20+F20+G20+H20 -> 7750 | J20: =7750 -> 7750 | K20: UD3DABB9DL | L20: APR | M20: =I20-J20 -> 0 | O20: SIGNED | Q20: APPHIA | R20: 100000 | S20: RCTD
A21: B6 | B21: Dina Mdombi | C21: 0704588355 | D21: 0 | E21: 7500 | F21: =MAR!M21 -> 500 | G21: 100 | H21: 500 | I21: =D21+E21+F21+G21+H21 -> 8600 | J21: =7600 -> 7600 | K21: UD6CSBJMO9 | L21: APR | M21: =I21-J21 -> 1000 | N21: 10TH | O21: SIGNED | Q21: SPICES | R21: 30000 | S21: RCTD
A22: C1 | B22: GEOFFREY OMUSE | C22: 0748039842 | D22: 0 | E22: 7000 | F22: =MAR!M22 -> 2150 | G22: 100 | H22: 500 | I22: =D22+E22+F22+G22+H22 -> 9750 | J22: =7000 -> 7000 | K22: UD8QM07VHW | L22: APR | M22: =I22-J22 -> 2750 | O22: SIGNED | Q22: FRANCIS | R22: 11500 | S22: RCTD
A23: C2 | B23: Esther John | C23: 0723307353 | D23: 0 | E23: 7000 | F23: =MAR!M23 -> 0 | G23: 100 | H23: 500 | I23: =D23+E23+F23+G23+H23 -> 7600 | J23: =7350 -> 7350 | K23: UD4P0BH2IF | L23: APR | M23: =I23-J23 -> 250 | O23: SIGNED | Q23: JAMES | R23: 15500 | S23: RCTD
A24: C3 | B24: DICKSON ZAWADI | C24: 0757132539* | E24: 7000 | F24: =MAR!M24 -> 250 | G24: 100 | H24: 500 | I24: =D24+E24+F24+G24+H24 -> 7850 | J24: =7300 -> 7300 | K24: UD27CBALZO | L24: APR | M24: =I24-J24 -> 550 | O24: SIGNED | Q24: ADRIAN | R24: 43800 | S24: RCTD
A25: C4 | B25: JAMES BETHUEL | C25: 0724771903 | D25: 0 | E25: 7000 | F25: =MAR!M25 -> 500 | G25: 100 | H25: 750 | I25: =D25+E25+F25+G25+H25 -> 8350 | J25: =7600 -> 7600 | K25: UD57OBM6LG | L25: APR | M25: =I25-J25 -> 750 | O25: SIGNED | R25: =SUM(R10:R24) -> 1054268 | S25: RCTD
A26: C5 | B26: ISAAC ARABU | C26: 0745762814 | D26: 0 | E26: 7000 | F26: =MAR!M26 -> -500 | G26: 100 | H26: 500 | I26: =D26+E26+F26+G26+H26 -> 7100 | J26: =6000 -> 6000 | K26: UD8O702NBD | L26: APR | M26: =I26-J26 -> 1100 | N26: 10TH | O26: SIGNED | S26: RCTD
A27: C6 | B27: CARETAKER | C27: 0714418782 | F27: =MAR!M27 -> 0 | I27: =D27+E27+F27+G27+H27 -> 0 | L27: APR | M27: =I27-J27 -> 0 | O27: SIGNED
A28: Totals | D28: =SUM(D10:D27) -> 0 | E28: =SUM(E10:E27) -> 117500 | F28: =SUM(F10:F27) -> 14850 | G28: =SUM(G10:G27) -> 1600 | H28: =SUM(H10:H27) -> 7750 | I28: =SUM(I10:I27) -> 141700 | J28: =SUM(J10:J27) -> 125050 | M28: =SUM(M10:M27) -> 16650
A30: Less Management fees | J30: =8%*(J28-H28-G28-D28) -> 9256
A31: TOKENS | J31: =1000+1000+1000 -> 3000
A32: DEPOSIT REFUND HSE A5 | J32: 2500
A33: KURIA GARBAGE | J33: =1700 -> 1700
A34: Waterbill | J34: =11300 -> 11300
A35: WATER METER CLEANING | J35: 1000
A36: SQUIZER/SOFT BROOM | J36: =600 -> 600
A38: TOTAL DEDUCTIONS | J38: =SUM(J30:J37) -> 29356
K39: 0
A40: BAL B/F | J40: =MAR!M43 -> -200
K41: Paid | L41: Paid | M41: Balance
A42: Amount Due | J42: =J28-J38+J40 -> 95494 | K42: 80000 | L42: 15634 | M42: =J42-K42-L42 -> -140
...

Sheet MAY
B1: LOBBY ENTERPRISES
A2: PROPERTY MANAGERS AND ESTATE AGENTS
A3: MAY 2026
K4: P.O.BOX 11987
A5: APPHIA APARTMENTS | K5: TEL :
A6: STATEMENT OF ACCOUNT
A7: NCBA PAYBILL '6432500027 | C7: 880100 | J7: Caretaker | K7: KELVIN
J8: Phone no | K8: 0714418782
A9: NAME | C9: CONTACT | D9: DEPOSIT PAID | E9: MONTHLY RENT | F9: BAL B/D | G9: GARBAGE | H9: WATER BILLS | I9: RENT DUE | J9: RENT PAID | K9: RCT NO | L9: PERIOD | M9: BALANCE | N9: STATUS | O9: FORMS
A10: A1 | B10: MAULINE MALESI | C10: 0743508108 | D10: 0 | E10: 7500 | F10: =APR!M10 -> 0 | G10: 100 | H10: 500 | I10: =D10+E10+F10+G10+H10 -> 8100 | J10: =8100 -> 8100 | K10: UE7JC3LXVA | L10: MAY | M10: =I10-J10 -> 0 | O10: SIGNED | Q10: THAMANDA | R10: 150000 | S10: RCTD
A11: A2 | B11: PETER | C11: 0719820676 | E11: 7500 | F11: =APR!M11 -> 1150 | G11: 100 | H11: 250 | I11: =D11+E11+F11+G11+H11 -> 9000 | J11: =7850 -> 7850 | K11: UE8U9AWZ5V | L11: MAY | M11: =I11-J11 -> 1150 | O11: SIGNED | Q11: KINOO | R11: 50000
A12: A3 | B12: Chrispine ooko | C12: 0712271588 | D12: 0 | E12: 7500 | F12: =APR!M12 -> 1000 | G12: 100 | H12: 250 | I12: =D12+E12+F12+G12+H12 -> 8850 | J12: =7950 -> 7950 | K12: UE70E39STQ | L12: MAY | M12: =I12-J12 -> 900 | N12: 10TH | O12: SIGNED | Q12: KAGWE | R12: 140208
A13: A4 | B13: YASEER | C13: 0783047456 | D13: 0 | E13: 7500 | F13: =APR!M13 -> 500 | G13: 100 | H13: 250 | I13: =D13+E13+F13+G13+H13 -> 8350 | J13: =6500 -> 6500 | K13: UERS03O0ZA | L13: MAY | M13: =I13-J13 -> 1850 | O13: SIGNED | Q13: KIBALI | R13: 32850 | S13: RCTD
A14: A5 | B14: ABDUL RAHMAN | C14: 0725903270/0751934076 | E14: 7500 | F14: =APR!M14 -> 0 | G14: 100 | H14: 250 | I14: =D14+E14+F14+G14+H14 -> 7850 | J14: =7500 -> 7500 | K14: UEL714QH58 | L14: MAY | M14: =I14-J14 -> 350 | N14: 10TH | O14: SIGNED | Q14: NJENGA | R14: 32160 | S14: RCTD
A15: A6 | B15: Vincent Mambili | C15: 0710558651 | E15: 7500 | F15: =APR!M15 -> 1350 | G15: 100 | H15: 500 | I15: =D15+E15+F15+G15+H15 -> 9450 | J15: =8100 -> 8100 | K15: UE6DW3FYEW | L15: MAY | M15: =I15-J15 -> 1350 | O15: SIGNED | Q15: KANGETHE | R15: 38250 | S15: RCTD
A16: B1 | B16: AMOS/STANLEY | C16: 0729892835 | E16: 7500 | F16: =APR!M16 -> 3700 | G16: 100 | H16: 750 | I16: =D16+E16+F16+G16+H16 -> 12050 | J16: =2500+2000 -> 4500 | K16: UED5C49NO3/UEI5C4RSTJ | L16: MAY | M16: =I16-J16 -> 7550 | N16: LOCKED TO EVICT | O16: SIGNED | Q16: R.EAST | R16: 50000 | S16: RCTD
A17: B2 | B17: PETER KARIUKI | C17: 0723743290 | D17: 0 | E17: 7500 | F17: =APR!M17 -> -700 | G17: 100 | H17: 500 | I17: =D17+E17+F17+G17+H17 -> 7400 | J17: =7500+500 -> 8000 | K17: 8841/7464 | L17: MAY | M17: =I17-J17 -> -600 | O17: SIGNED | Q17: JAGIET | R17: 60000
A18: B3 | B18: VACANT | F18: =APR!M18 -> 0 | H18: 250 | I18: =D18+E18+F18+G18+H18 -> 250 | L18: MAY | M18: =I18-J18 -> 250 | O18: SIGNED | Q18: GHETTO | R18: 150000
A19: B4 | B19: CYTHIA MADESHE | C19: 0772369562 | E19: 7500 | F19: =APR!M19 -> 3250 | G19: 100 | H19: 250 | I19: =D19+E19+F19+G19+H19 -> 11100 | J19: =4000+3000 -> 7000 | K19: UE52H3M9F3/UEB2HH4AOVW | L19: MAY | M19: =I19-J19 -> 4100 | O19: SIGNED | Q19: GHETTO | R19: 150000 | S19: RCTD
A20: B5 | B20: George Kirigo | C20: 0710152025 | D20: 0 | E20: 7500 | F20: =APR!M20 -> 0 | G20: 100 | I20: =D20+E20+F20+G20+H20 -> 7600 | J20: =7600 -> 7600 | K20: UE5DA31OLT | L20: MAY | M20: =I20-J20 -> 0 | O20: SIGNED | Q20: APPHIA | R20: 100000 | S20: RCTD
A21: B6 | B21: Dina Mdombi | C21: 0704588355 | D21: 0 | E21: 7500 | F21: =APR!M21 -> 1000 | G21: 100 | H21: 0 | I21: =D21+E21+F21+G21+H21 -> 8600 | J21: =7600 -> 7600 | K21: UEFCS3ZVWP | L21: MAY | M21: =I21-J21 -> 1000 | N21: 10TH | O21: SIGNED | Q21: SPICES | R21: 30000 | S21: RCTD
A22: C1 | B22: GEOFFREY OMUSE | C22: 0748039842 | D22: 0 | E22: 7000 | F22: =APR!M22 -> 2750 | G22: 100 | H22: 250 | I22: =D22+E22+F22+G22+H22 -> 10100 | J22: =7000 -> 7000 | K22: UE7QM3IRWS | L22: MAY | M22: =I22-J22 -> 3100 | O22: SIGNED | Q22: FRANCIS | R22: 11500 | S22: RCTD
A23: C2 | B23: Esther John | C23: 0723307353 | D23: 0 | E23: 7000 | F23: =APR!M23 -> 250 | G23: 100 | I23: =D23+E23+F23+G23+H23 -> 7350 | J23: =21600 -> 21600 | K23: UE6P037FKM | L23: MAY | M23: =I23-J23 -> -14250 | O23: SIGNED | Q23: JAMES | R23: 15500 | S23: RCTD
A24: C3 | B24: DICKSON ZAWADI | C24: 0757132539* | E24: 7000 | F24: =APR!M24 -> 550 | G24: 100 | H24: 500 | I24: =D24+E24+F24+G24+H24 -> 8150 | J24: =7650 -> 7650 | K24: UE67C39Q5Q | L24: MAY | M24: =I24-J24 -> 500 | O24: SIGNED | Q24: ADRIAN | R24: 43800 | S24: RCTD
A25: C4 | B25: JAMES BETHUEL | C25: 0724771903 | D25: 0 | E25: 7000 | F25: =APR!M25 -> 750 | G25: 100 | H25: 500 | I25: =D25+E25+F25+G25+H25 -> 8350 | J25: =7350 -> 7350 | K25: UE57O334R8 | L25: MAY | M25: =I25-J25 -> 1000 | O25: SIGNED | R25: =SUM(R10:R24) -> 1054268 | S25: RCTD
A26: C5 | B26: ISAAC ARABU | C26: 0745762814 | D26: 0 | E26: 7000 | F26: =APR!M26 -> 1100 | G26: 100 | H26: 500 | I26: =D26+E26+F26+G26+H26 -> 8700 | J26: =7300 -> 7300 | K26: UE4O732N82 | L26: MAY | M26: =I26-J26 -> 1400 | N26: 10TH | O26: SIGNED | S26: RCTD
A27: C6 | B27: CARETAKER | C27: 0714418782 | F27: =APR!M27 -> 0 | I27: =D27+E27+F27+G27+H27 -> 0 | L27: MAY | M27: =I27-J27 -> 0 | O27: SIGNED
A28: Totals | D28: =SUM(D10:D27) -> 0 | E28: =SUM(E10:E27) -> 117500 | F28: =SUM(F10:F27) -> 16650 | G28: =SUM(G10:G27) -> 1600 | H28: =SUM(H10:H27) -> 5500 | I28: =SUM(I10:I27) -> 141250 | J28: =SUM(J10:J27) -> 131600 | M28: =SUM(M10:M27) -> 9650
A30: Less Management fees | J30: =8%*(J28-H28-G28-D28) -> 9960
A31: TOKENS | J31: =1000+1000+1000 -> 3000
A32: KURIA GARBAGE | J32: =1700 -> 1700
A33: Waterbill | J33: =8300 -> 8300
A34: WATER METER CLEANING | J34: 1000
A35: PUMP SERVICE/FITTINGS/WAGE | J35: =6450 -> 6450
A36: TOTAL DEDUCTIONS | J36: =SUM(J30:J35) -> 30410
K37: 0
A38: BAL B/F | J38: =APR!M42 -> -140
K39: Paid | L39: Paid | M39: Balance
A40: Amount Due | J40: =J28-J36+J38 -> 101050 | K40: 80000 | L40: 21750 | M40: =J40-K40-L40 -> -700
A42: AUTHORISED BY JOSEPH GITHINJI | M42: 46173
...

Sheet JUNE
B1: LOBBY ENTERPRISES
A2: PROPERTY MANAGERS AND ESTATE AGENTS
A3: JUNE 2026
K4: P.O.BOX 11987
A5: APPHIA APARTMENTS | K5: TEL :
A6: STATEMENT OF ACCOUNT
A7: NCBA PAYBILL '6432500027 | C7: 880100 | J7: Caretaker | K7: KELVIN
J8: Phone no | K8: 0714418782
A9: NAME | C9: CONTACT | D9: DEPOSIT PAID | E9: MONTHLY RENT | F9: BAL B/D | G9: GARBAGE | H9: WATER BILLS | I9: RENT DUE | J9: RENT PAID | K9: RCT NO | L9: PERIOD | M9: BALANCE | N9: STATUS | O9: FORMS
A10: A1 | B10: MAULINE MALESI | C10: 0743508108 | D10: 0 | E10: 7500 | F10: =MAY!M10 -> 0 | G10: 100 | H10: 500 | I10: =D10+E10+F10+G10+H10 -> 8100 | J10: =8100 -> 8100 | K10: UF5JC6WSF9 | L10: JUNE | M10: =I10-J10 -> 0 | O10: SIGNED | Q10: THAMANDA | R10: 150000 | S10: RCTD
A11: A2 | B11: PETER | C11: 0719820676 | E11: 7500 | F11: =MAY!M11 -> 1150 | G11: 100 | H11: 1000 | I11: =D11+E11+F11+G11+H11 -> 9750 | J11: =8100 -> 8100 | K11: UF8U90DKO7 | L11: JUNE | M11: =I11-J11 -> 1650 | O11: SIGNED | Q11: KINOO | R11: 50000
A12: A3 | B12: Chrispine ooko | C12: 0712271588 | D12: 0 | E12: 7500 | F12: =MAY!M12 -> 900 | G12: 100 | H12: 750 | I12: =D12+E12+F12+G12+H12 -> 9250 | J12: =7750 -> 7750 | K12: UF40E6I351 | L12: JUNE | M12: =I12-J12 -> 1500 | O12: SIGNED | Q12: KAGWE | R12: 140208
A13: A4 | B13: YASEER | C13: 0783047456 | D13: 0 | E13: 7500 | F13: =MAY!M13 -> 1850 | G13: 100 | H13: 750 | I13: =D13+E13+F13+G13+H13 -> 10200 | L13: JUNE | M13: =I13-J13 -> 10200 | N13: LOCKED | O13: SIGNED | Q13: KIBALI | R13: 32850 | S13: RCTD
A14: A5 | B14: ABDUL RAHMAN | C14: 0725903270/0751934076 | E14: 7500 | F14: =MAY!M14 -> 350 | G14: 100 | H14: 250 | I14: =D14+E14+F14+G14+H14 -> 8200 | J14: =7500 -> 7500 | K14: UF8716SXZ5 | L14: JUNE | M14: =I14-J14 -> 700 | O14: SIGNED | Q14: NJENGA | R14: 32160 | S14: RCTD
A15: A6 | B15: Vincent Mambili | C15: 0710558651 | E15: 7500 | F15: =MAY!M15 -> 1350 | G15: 100 | H15: 250 | I15: =D15+E15+F15+G15+H15 -> 9200 | J15: =1350+6000 -> 7350 | K15: UF6ME6VEFQ/UF7ME711K3 | L15: JUNE | M15: =I15-J15 -> 1850 | O15: SIGNED | Q15: KANGETHE | R15: 38250 | S15: RCTD
A16: B1 | B16: AMOS/STANLEY | C16: 0729892835 | E16: 7500 | F16: =MAY!M16 -> 7550 | G16: 100 | H16: 750 | I16: =D16+E16+F16+G16+H16 -> 15900 | J16: =2800+2500 -> 5300 | K16: UFB5C7HBIL/UFPOC959X2 | L16: JUNE | M16: =I16-J16 -> 10600 | N16: LOCKED | O16: SIGNED | Q16: R.EAST | R16: 50000 | S16: RCTD
A17: B2 | B17: PETER KARIUKI | C17: 0723743290 | D17: 0 | E17: 7500 | F17: =MAY!M17 -> -600 | G17: 100 | H17: 1000 | I17: =D17+E17+F17+G17+H17 -> 8000 | J17: =7500+500 -> 8000 | K17: 0214 | L17: JUNE | M17: =I17-J17 -> 0 | O17: SIGNED | Q17: JAGIET | R17: 60000
A18: B3 | B18: VACANT | I18: =D18+E18+F18+G18+H18 -> 0 | L18: JUNE | M18: =I18-J18 -> 0 | O18: SIGNED | Q18: GHETTO | R18: 150000
A19: B4 | B19: CYTHIA MADESHE | C19: 0772369562 | E19: 7500 | F19: =MAY!M19 -> 4100 | G19: 100 | H19: 1000 | I19: =D19+E19+F19+G19+H19 -> 12700 | J19: =8500 -> 8500 | K19: UF52HH78U7Z | L19: JUNE | M19: =I19-J19 -> 4200 | O19: SIGNED | Q19: GHETTO | R19: 150000 | S19: RCTD
A20: B5 | B20: George Kirigo | C20: 0710152025 | D20: 0 | E20: 7500 | F20: =MAY!M20 -> 0 | G20: 100 | H20: 0 | I20: =D20+E20+F20+G20+H20 -> 7600 | J20: =7600 -> 7600 | K20: UF5DA6IHY8 | L20: JUNE | M20: =I20-J20 -> 0 | O20: SIGNED | Q20: APPHIA | R20: 100000 | S20: RCTD
A21: B6 | B21: Dina Mdombi | C21: 0704588355 | D21: 0 | E21: 7500 | F21: =MAY!M21 -> 1000 | G21: 100 | H21: 1000 | I21: =D21+E21+F21+G21+H21 -> 9600 | J21: =7850 -> 7850 | K21: UFGCS7MH0F | L21: JUNE | M21: =I21-J21 -> 1750 | O21: SIGNED | Q21: SPICES | R21: 30000 | S21: RCTD
A22: C1 | B22: GEOFFREY OMUSE | C22: 0748039842 | D22: 0 | E22: 7000 | F22: =MAY!M22 -> 3100 | G22: 100 | H22: 1000 | I22: =D22+E22+F22+G22+H22 -> 11200 | J22: =7500 -> 7500 | K22: UF5QM6UWYT | L22: JUNE | M22: =I22-J22 -> 3700 | O22: SIGNED | Q22: FRANCIS | R22: 11500 | S22: RCTD
A23: C2 | B23: Esther John | C23: 0723307353 | D23: 0 | E23: 7000 | F23: =MAY!M23 -> -14250 | G23: 100 | I23: =D23+E23+F23+G23+H23 -> -7150 | L23: JUNE | M23: =I23-J23 -> -7150 | O23: SIGNED | Q23: JAMES | R23: 15500 | S23: RCTD
A24: C3 | B24: DICKSON ZAWADI | C24: 0757132539* | E24: 7000 | F24: =MAY!M24 -> 500 | G24: 100 | H24: 500 | I24: =D24+E24+F24+G24+H24 -> 8100 | J24: =7100 -> 7100 | K24: UFA7C7A769 | L24: JUNE | M24: =I24-J24 -> 1000 | O24: SIGNED | Q24: ADRIAN | R24: 43800 | S24: RCTD
A25: C4 | B25: JAMES BETHUEL | C25: 0724771903 | D25: 0 | E25: 7000 | F25: =MAY!M25 -> 1000 | G25: 100 | H25: 750 | I25: =D25+E25+F25+G25+H25 -> 8850 | J25: =7600 -> 7600 | K25: UF57O6N91H | L25: JUNE | M25: =I25-J25 -> 1250 | O25: SIGNED | R25: =SUM(R10:R24) -> 1054268 | S25: RCTD
A26: C5 | B26: ISAAC ARABU | C26: 0745762814 | D26: 0 | E26: 7000 | F26: =MAY!M26 -> 1400 | G26: 100 | H26: 1000 | I26: =D26+E26+F26+G26+H26 -> 9500 | J26: =7000 -> 7000 | K26: UF9O77AYEM | L26: JUNE | M26: =I26-J26 -> 2500 | O26: SIGNED | S26: RCTD
A27: C6 | B27: CARETAKER | C27: 0714418782 | F27: =MAY!M27 -> 0 | I27: =D27+E27+F27+G27+H27 -> 0 | L27: JUNE | M27: =I27-J27 -> 0 | O27: SIGNED
A28: Totals | D28: =SUM(D10:D27) -> 0 | E28: =SUM(E10:E27) -> 117500 | F28: =SUM(F10:F27) -> 9400 | G28: =SUM(G10:G27) -> 1600 | H28: =SUM(H10:H27) -> 10500 | I28: =SUM(I10:I27) -> 139000 | J28: =SUM(J10:J27) -> 105250 | M28: =SUM(M10:M27) -> 33750
A30: Less Management fees | J30: =8%*(J28-H28-G28-D28) -> 7452
A31: TOKENS | J31: =1000+1000+1000 -> 3000
A32: KURIA GARBAGE | J32: =1700 -> 1700
A33: Waterbill
A34: WATER METER CLEANING | J34: 1000
A35: TOTAL DEDUCTIONS | J35: =SUM(J30:J34) -> 13152
K36: 0
A37: BAL B/F | J37: =MAY!M40 -> -700
K38: Paid | L38: Paid | M38: Balance
A39: Amount Due | J39: =J28-J35+J37 -> 91398 | K39: 80000 | L39: 13578 | M39: =J39-K39-L39 -> -2180
A41: AUTHORISED BY JOSEPH GITHINJI | M41: 46203
M46: =24740-12300-1700 -> 10740
...

Sheet JULY
B1: LOBBY ENTERPRISES
A2: PROPERTY MANAGERS AND ESTATE AGENTS
A3: JULY 2026
K4: P.O.BOX 11987
A5: APPHIA APARTMENTS | K5: TEL :
A6: STATEMENT OF ACCOUNT
A7: NCBA PAYBILL '6432500027 | C7: 880100 | J7: Caretaker | K7: KELVIN
J8: Phone no | K8: 0714418782
A9: NAME | C9: CONTACT | D9: DEPOSIT PAID | E9: MONTHLY RENT | F9: BAL B/D | G9: GARBAGE | H9: WATER BILLS | I9: RENT DUE | J9: RENT PAID | K9: RCT NO | L9: PERIOD | M9: BALANCE | N9: STATUS | O9: FORMS
A10: A1 | B10: MAULINE MALESI | C10: 0743508108 | D10: 0 | E10: 7500 | F10: =JUNE!M10 -> 0 | G10: 100 | H10: 750 | I10: =D10+E10+F10+G10+H10 -> 8350 | J10: =8350 -> 8350 | K10: UG8JCARFLV | L10: JULY | M10: =I10-J10 -> 0 | O10: SIGNED | Q10: THAMANDA | R10: 150000 | S10: RCTD
A11: A2 | B11: PETER | C11: 0719820676 | E11: 7500 | F11: =JUNE!M11 -> 1650 | G11: 100 | H11: 500 | I11: =D11+E11+F11+G11+H11 -> 9750 | J11: =8100 -> 8100 | K11: UG8U91Q1RP | L11: JULY | M11: =I11-J11 -> 1650 | O11: SIGNED | Q11: KINOO | R11: 50000
A12: A3 | B12: Chrispine ooko | C12: 0712271588 | D12: 0 | E12: 7500 | F12: =JUNE!M12 -> 1500 | G12: 100 | H12: 0 | I12: =D12+E12+F12+G12+H12 -> 9100 | J12: =9100 -> 9100 | K12: UG65NAAG5S | L12: JULY | M12: =I12-J12 -> 0 | O12: SIGNED | Q12: KAGWE | R12: 140208
A13: A4 | B13: YASEER | C13: 0783047456 | D13: 0 | E13: 7500 | F13: =JUNE!M13 -> 10200 | G13: 100 | H13: 0 | I13: =D13+E13+F13+G13+H13 -> 17800 | J13: =10000 -> 10000 | K13: UGBCIAZ23T | L13: JULY | M13: =I13-J13 -> 7800 | O13: SIGNED | Q13: KIBALI | R13: 32850 | S13: RCTD
A14: A5 | B14: ABDUL RAHMAN | C14: 0725903270/0751934076 | E14: 7500 | F14: =JUNE!M14 -> 700 | G14: 100 | H14: 250 | I14: =D14+E14+F14+G14+H14 -> 8550 | J14: =7750 -> 7750 | K14: UGF71B188C | L14: JULY | M14: =I14-J14 -> 800 | O14: SIGNED | Q14: NJENGA | R14: 32160 | S14: RCTD
A15: A6 | B15: Vincent Mambili | C15: 0710558651 | E15: 7500 | F15: =JUNE!M15 -> 1850 | G15: 100 | H15: 500 | I15: =D15+E15+F15+G15+H15 -> 9950 | J15: =7000 -> 7000 | K15: UG8MEAMQ99 | L15: JULY | M15: =I15-J15 -> 2950 | O15: SIGNED | Q15: KANGETHE | R15: 38250 | S15: RCTD
A16: B1 | B16: AMOS/STANLEY | C16: 0729892835 | E16: 7500 | F16: =JUNE!M16 -> 10600 | G16: 100 | H16: 750 | I16: =D16+E16+F16+G16+H16 -> 18950 | J16: =5500+3700 -> 9200 | K16: UG6OCAC1IO/UGFOCBDGET | L16: JULY | M16: =I16-J16 -> 9750 | O16: SIGNED | Q16: R.EAST | R16: 50000 | S16: RCTD
A17: B2 | B17: PETER KARIUKI | C17: 0723743290 | D17: 0 | E17: 7500 | F17: =JUNE!M17 -> 0 | G17: 100 | H17: 250 | I17: =D17+E17+F17+G17+H17 -> 7850 | J17: =7500+500 -> 8000 | K17: 7456/8918 | L17: JULY | M17: =I17-J17 -> -150 | O17: SIGNED | Q17: JAGIET | R17: 60000
A18: B3 | B18: VACANT | F18: =JUNE!M18 -> 0 | H18: 0 | I18: =D18+E18+F18+G18+H18 -> 0 | L18: JULY | M18: =I18-J18 -> 0 | O18: SIGNED | Q18: GHETTO | R18: 150000
A19: B4 | B19: CYTHIA MADESHE | C19: 0772369562 | E19: 7500 | F19: =JUNE!M19 -> 4200 | G19: 100 | H19: 1750 | I19: =D19+E19+F19+G19+H19 -> 13550 | J19: =7600 -> 7600 | K19: UG62HAVDNQ | L19: JULY | M19: =I19-J19 -> 5950 | O19: SIGNED | Q19: GHETTO | R19: 150000 | S19: RCTD
A20: B5 | B20: George Kirigo | C20: 0710152025 | D20: 0 | E20: 7500 | F20: =JUNE!M20 -> 0 | G20: 100 | H20: 250 | I20: =D20+E20+F20+G20+H20 -> 7850 | J20: =7850 -> 7850 | K20: UG5DA9ZGX5 | L20: JULY | M20: =I20-J20 -> 0 | O20: SIGNED | Q20: APPHIA | R20: 100000 | S20: RCTD
A21: B6 | B21: Dina Mdombi | C21: 0704588355 | D21: 0 | E21: 7500 | F21: =JUNE!M21 -> 1750 | G21: 100 | H21: 250 | I21: =D21+E21+F21+G21+H21 -> 9600 | J21: =7850 -> 7850 | K21: UG7CSA21D3 | L21: JULY | M21: =I21-J21 -> 1750 | O21: SIGNED | Q21: SPICES | R21: 30000 | S21: RCTD
A22: C1 | B22: GEOFFREY OMUSE | C22: 0748039842 | D22: 0 | E22: 7000 | F22: =JUNE!M22 -> 3700 | G22: 100 | H22: 250 | I22: =D22+E22+F22+G22+H22 -> 11050 | J22: =7100 -> 7100 | K22: UG6QMAGTML | L22: JULY | M22: =I22-J22 -> 3950 | O22: SIGNED | Q22: FRANCIS | R22: 11500 | S22: RCTD
A23: C2 | B23: Esther John | C23: 0723307353 | D23: 0 | E23: 7000 | F23: =JUNE!M23 -> -7150 | G23: 100 | I23: =D23+E23+F23+G23+H23 -> -50 | L23: JULY | M23: =I23-J23 -> -50 | O23: SIGNED | Q23: JAMES | R23: 15500 | S23: RCTD
A24: C3 | B24: DICKSON ZAWADI | C24: 0757132539* | E24: 7000 | F24: =JUNE!M24 -> 1000 | G24: 100 | H24: 250 | I24: =D24+E24+F24+G24+H24 -> 8350 | J24: =7500 -> 7500 | K24: UG97CANJFE | L24: JULY | M24: =I24-J24 -> 850 | O24: SIGNED | Q24: ADRIAN | R24: 43800 | S24: RCTD
A25: C4 | B25: JAMES BETHUEL | C25: 0724771903 | D25: 0 | E25: 7000 | F25: =JUNE!M25 -> 1250 | G25: 100 | H25: 1000 | I25: =D25+E25+F25+G25+H25 -> 9350 | J25: =8250 -> 8250 | K25: UG57OA3NJ6 | L25: JULY | M25: =I25-J25 -> 1100 | O25: SIGNED | R25: =SUM(R10:R24) -> 1054268 | S25: RCTD
A26: C5 | B26: ISAAC ARABU | C26: 0745762814 | D26: 0 | E26: 7000 | F26: =JUNE!M26 -> 2500 | G26: 100 | H26: 0 | I26: =D26+E26+F26+G26+H26 -> 9600 | J26: =7500 -> 7500 | K26: UG7O7AJKGB | L26: JULY | M26: =I26-J26 -> 2100 | O26: SIGNED | S26: RCTD
A27: C6 | B27: CARETAKER | C27: 0714418782 | F27: =JUNE!M27 -> 0 | I27: =D27+E27+F27+G27+H27 -> 0 | L27: JULY | M27: =I27-J27 -> 0 | O27: SIGNED
A28: Totals | D28: =SUM(D10:D27) -> 0 | E28: =SUM(E10:E27) -> 117500 | F28: =SUM(F10:F27) -> 33750 | G28: =SUM(G10:G27) -> 1600 | H28: =SUM(H10:H27) -> 6750 | I28: =SUM(I10:I27) -> 159600 | J28: =SUM(J10:J27) -> 121150 | M28: =SUM(M10:M27) -> 38450
A30: Less Management fees | J30: =8%*(J28-H28-G28-D28) -> 9024
A31: TOKENS | J31: =1000+1000 -> 2000
A32: BOREHOLE WATER RECONNECTION & WAGE | J32: 1500
A33: KURIA GARBAGE | J33: =1700 -> 1700
A34: Waterbill | J34: 5402
A35: WATER METER CLEANING
A36: TOTAL DEDUCTIONS | J36: =SUM(J30:J35) -> 19626
K37: 0
A38: BAL B/F | J38: =JUNE!M39 -> -2180
K39: Paid | L39: Paid | M39: Balance
A40: Amount Due | J40: =J28-J36+J38 -> 99344 | K40: 80000 | L40: 16000 | M40: =J40-K40-L40 -> 3344
A42: AUTHORISED BY JOSEPH GITHINJI | M42: 46234
...

Sheet AUG
B1: LOBBY ENTERPRISES
A2: PROPERTY MANAGERS AND ESTATE AGENTS
A3: AUG 2026
K4: P.O.BOX 11987
A5: APPHIA APARTMENTS | K5: TEL :
A6: STATEMENT OF ACCOUNT
A7: NCBA PAYBILL '6432500027 | C7: 880100 | J7: Caretaker | K7: KELVIN
J8: Phone no | K8: 0714418782
A9: NAME | C9: CONTACT | D9: DEPOSIT PAID | E9: MONTHLY RENT | F9: BAL B/D | G9: GARBAGE | H9: WATER BILLS | I9: RENT DUE | J9: RENT PAID | K9: RCT NO | L9: PERIOD | M9: BALANCE | N9: STATUS | O9: FORMS
A10: A1 | B10: MAULINE MALESI | C10: 0743508108 | D10: 0 | E10: 7500 | F10: =JULY!M10 -> 0 | G10: 100 | H10: 250 | I10: =D10+E10+F10+G10+H10 -> 7850 | J10: =7850 -> 7850 | K10: 9526(COOP BANK) | L10: AUG | M10: =I10-J10 -> 0 | O10: SIGNED | Q10: THAMANDA | R10: 150000 | S10: RCTD
A11: A2 | B11: PETER | C11: 0719820676 | E11: 7500 | F11: =JULY!M11 -> 1650 | G11: 100 | H11: 500 | I11: =D11+E11+F11+G11+H11 -> 9750 | J11: =8100 -> 8100 | K11: UH7U936VZN | L11: AUG | M11: =I11-J11 -> 1650 | O11: SIGNED | Q11: KINOO | R11: 50000
A12: A3 | B12: Chrispine ooko | C12: 0712271588 | D12: 0 | E12: 7500 | F12: =JULY!M12 -> 0 | G12: 100 | H12: 0 | I12: =D12+E12+F12+G12+H12 -> 7600 | J12: =7600 -> 7600 | K12: UHA0E288BJ | L12: AUG | M12: =I12-J12 -> 0 | O12: SIGNED | Q12: KAGWE | R12: 140208
A13: A4 | B13: YASEER | C13: 0783047456 | D13: 0 | E13: 7500 | F13: =JULY!M13 -> 7800 | G13: 100 | H13: 0 | I13: =D13+E13+F13+G13+H13 -> 15400 | J13: =9000 -> 9000 | K13: UHHCI3AEZ0 | L13: AUG | M13: =I13-J13 -> 6400 | O13: SIGNED | Q13: KIBALI | R13: 32850 | S13: RCTD
A14: A5 | B14: ABDUL RAHMAN | C14: 0725903270/0751934076 | E14: 7500 | F14: =JULY!M14 -> 800 | G14: 100 | H14: 250 | I14: =D14+E14+F14+G14+H14 -> 8650 | J14: =8650 -> 8650 | K14: UHK71359N2 | L14: AUG | M14: =I14-J14 -> 0 | O14: SIGNED | Q14: NJENGA | R14: 32160 | S14: RCTD
A15: A6 | B15: Vincent Mambili | C15: 0710558651 | E15: 7500 | F15: =JULY!M15 -> 2950 | G15: 100 | H15: 500 | I15: =D15+E15+F15+G15+H15 -> 11050 | J15: =8000 -> 8000 | K15: UH8ME272XA | L15: AUG | M15: =I15-J15 -> 3050 | O15: SIGNED | Q15: KANGETHE | R15: 38250 | S15: RCTD
A16: B1 | B16: AMOS/STANLEY | C16: 0729892835 | E16: 7500 | F16: =JULY!M16 -> 9750 | G16: 100 | H16: 0 | I16: =D16+E16+F16+G16+H16 -> 17350 | J16: =5000+7000 -> 12000 | K16: UH8OC25LCL/UGVOC189CA | L16: AUG | M16: =I16-J16 -> 5350 | O16: SIGNED | Q16: R.EAST | R16: 50000 | S16: RCTD
A17: B2 | B17: PETER KARIUKI | C17: 0723743290 | D17: 0 | E17: 7500 | F17: =JULY!M17 -> -150 | G17: 100 | H17: 0 | I17: =D17+E17+F17+G17+H17 -> 7450 | J17: =7500+500 -> 8000 | K17: 1729/3044 | L17: AUG | M17: =I17-J17 -> -550 | O17: SIGNED | Q17: JAGIET | R17: 60000
A18: B3 | B18: STEPHEN NGANGA | D18: 10000 | E18: 5000 | F18: =JULY!M18 -> 0 | G18: 100 | H18: 0 | I18: =D18+E18+F18+G18+H18 -> 15100 | L18: AUG | M18: =I18-J18 -> 15100 | O18: SIGNED | Q18: GHETTO | R18: 150000
A19: B4 | B19: CYTHIA MADESHE | C19: 0772369562 | E19: 7500 | F19: =JULY!M19 -> 5950 | G19: 100 | H19: 1250 | I19: =D19+E19+F19+G19+H19 -> 14800 | J19: =9000 -> 9000 | K19: UH22H2267L | L19: AUG | M19: =I19-J19 -> 5800 | O19: SIGNED | Q19: GHETTO | R19: 150000 | S19: RCTD
A20: B5 | B20: George Kirigo | C20: 0710152025 | D20: 0 | E20: 7500 | F20: =JULY!M20 -> 0 | G20: 100 | H20: 0 | I20: =D20+E20+F20+G20+H20 -> 7600 | J20: =7750 -> 7750 | K20: UH3DA1CPF2 | L20: AUG | M20: =I20-J20 -> -150 | O20: SIGNED | Q20: APPHIA | R20: 100000 | S20: RCTD
A21: B6 | B21: VACANT | I21: =D21+E21+F21+G21+H21 -> 0 | L21: AUG | M21: =I21-J21 -> 0 | O21: SIGNED | Q21: SPICES | R21: 30000 | S21: RCTD
A22: C1 | B22: VACANT | H22: 0 | I22: =D22+E22+F22+G22+H22 -> 0 | L22: AUG | M22: =I22-J22 -> 0 | O22: SIGNED | Q22: FRANCIS | R22: 11500 | S22: RCTD
A23: C2 | B23: Esther John | C23: 0723307353 | D23: 0 | E23: 7000 | F23: =JULY!M23 -> -50 | G23: 100 | H23: 250 | I23: =D23+E23+F23+G23+H23 -> 7300 | J23: =7350 -> 7350 | K23: UH5P01P4PR | L23: AUG | M23: =I23-J23 -> -50 | O23: SIGNED | Q23: JAMES | R23: 15500 | S23: RCTD
A24: C3 | B24: DICKSON ZAWADI | C24: 0757132539* | E24: 7000 | F24: =JULY!M24 -> 850 | G24: 100 | H24: 250 | I24: =D24+E24+F24+G24+H24 -> 8200 | J24: =6000 -> 6000 | K24: UHB7C2EZEY | L24: AUG | M24: =I24-J24 -> 2200 | O24: SIGNED | Q24: ADRIAN | R24: 43800 | S24: RCTD
A25: C4 | B25: JAMES BETHUEL | C25: 0724771903 | D25: 0 | E25: 7000 | F25: =JULY!M25 -> 1100 | G25: 100 | H25: 500 | I25: =D25+E25+F25+G25+H25 -> 8700 | J25: =5500 -> 5500 | K25: UH57O1NYNE | L25: AUG | M25: =I25-J25 -> 3200 | O25: SIGNED | R25: =SUM(R10:R24) -> 1054268 | S25: RCTD
A26: C5 | B26: VACANT | H26: 0 | I26: =D26+E26+F26+G26+H26 -> 0 | L26: AUG | M26: =I26-J26 -> 0 | O26: SIGNED | S26: RCTD
A27: C6 | B27: CARETAKER | C27: 0714418782 | F27: =JULY!M27 -> 0 | I27: =D27+E27+F27+G27+H27 -> 0 | L27: AUG | M27: =I27-J27 -> 0 | O27: SIGNED
A28: Totals | D28: =SUM(D10:D27) -> 10000 | E28: =SUM(E10:E27) -> 101000 | F28: =SUM(F10:F27) -> 30650 | G28: =SUM(G10:G27) -> 1400 | H28: =SUM(H10:H27) -> 3750 | I28: =SUM(I10:I27) -> 146800 | J28: =SUM(J10:J27) -> 104800 | M28: =SUM(M10:M27) -> 42000
A30: Less Management fees | J30: =8%*(J28-H28-G28-D28) -> 7172
A31: TOKENS | J31: =1000+1000+1000 -> 3000
A32: KURIA GARBAGE | J32: 1300
A33: PAINT REVAMP HSE C5 AND HSE B3 | J33: 10000
A34: MATERIALS USED ON TANKSBALLCOCK/GI ELBOW/GI SOCKET/THREAD TAPE/GI BACKNUT | J34: 5680
A35: PLUMBING WAGE FOR TANKS | J35: 1500
A36: SOCKET/SILLICONE HSE B5 REPAIR | J36: 700
A37: Waterbill | J37: =6902 -> 6902 | M37: =8%*M32 -> 0
A38: WATER METER CLEANING | J38: 1000
A39: TOTAL DEDUCTIONS | J39: =SUM(J30:J38) -> 37254
K40: 0
A41: BAL B/F | J41: =JULY!M40 -> 3344
...

Sheet SEP
B1: LOBBY ENTERPRISES
A2: PROPERTY MANAGERS AND ESTATE AGENTS
A3: SEP 2026
K4: P.O.BOX 11987
A5: APPHIA APARTMENTS | K5: TEL :
A6: STATEMENT OF ACCOUNT
A7: NCBA PAYBILL '6432500027 | C7: 880100 | J7: Caretaker | K7: KELVIN
J8: Phone no | K8: 0714418782
A9: NAME | C9: CONTACT | D9: DEPOSIT PAID | E9: MONTHLY RENT | F9: BAL B/D | G9: GARBAGE | H9: WATER BILLS | I9: RENT DUE | J9: RENT PAID | K9: RCT NO | L9: PERIOD | M9: BALANCE | N9: STATUS | O9: FORMS
A10: A1 | B10: MAULINE MALESI | C10: 0743508108 | D10: 0 | E10: 7500 | F10: =AUG!M10 -> 0 | G10: 100 | H10: 750 | I10: =D10+E10+F10+G10+H10 -> 8350 | J10: 8350 | K10: 2626 | L10: SEP | M10: =I10-J10 -> 0 | O10: SIGNED | Q10: THAMANDA | R10: 150000 | S10: RCTD
A11: A2 | B11: PETER | C11: 0719820676 | E11: 7500 | F11: =AUG!M11 -> 1650 | G11: 100 | H11: 250 | I11: =D11+E11+F11+G11+H11 -> 9500 | J11: =7850 -> 7850 | K11: UI7U94RRGA | L11: SEP | M11: =I11-J11 -> 1650 | O11: SIGNED | Q11: KINOO | R11: 50000
A12: A3 | B12: Chrispine ooko | C12: 0712271588 | D12: 0 | E12: 7500 | F12: =AUG!M12 -> 0 | G12: 100 | H12: 0 | I12: =D12+E12+F12+G12+H12 -> 7600 | J12: =7500 -> 7500 | K12: UI5QL5JXEM | L12: SEP | M12: =I12-J12 -> 100 | O12: SIGNED | Q12: KAGWE | R12: 140208
A13: A4 | B13: YASEER | C13: 0783047456 | D13: 0 | E13: 7500 | F13: =AUG!M13 -> 6400 | G13: 100 | H13: 0 | I13: =D13+E13+F13+G13+H13 -> 14000 | J13: =5000+8000 -> 13000 | K13: UIQCI833KA/UIHCI6WI01 | L13: SEP | M13: =I13-J13 -> 1000 | O13: SIGNED | Q13: KIBALI | R13: 32850 | S13: RCTD
A14: A5 | B14: ABDUL RAHMAN | C14: 0725903270/0751934076 | E14: 7500 | F14: =AUG!M14 -> 0 | G14: 100 | H14: 500 | I14: =D14+E14+F14+G14+H14 -> 8100 | J14: =3500+4500 -> 8000 | K14: UI8715GO16/UIP717HI9E | L14: SEP | M14: =I14-J14 -> 100 | O14: SIGNED | Q14: NJENGA | R14: 32160 | S14: RCTD
A15: A6 | B15: Vincent Mambili | C15: 0710558651 | E15: 7500 | F15: =AUG!M15 -> 3050 | G15: 100 | H15: 500 | I15: =D15+E15+F15+G15+H15 -> 11150 | J15: =8100 -> 8100 | K15: UI7ME5SBT5 | L15: SEP | M15: =I15-J15 -> 3050 | O15: SIGNED | Q15: KANGETHE | R15: 38250 | S15: RCTD
A16: B1 | B16: AMOS/STANLEY | C16: 0729892835 | E16: 7500 | F16: =AUG!M16 -> 5350 | G16: 100 | H16: 1000 | I16: =D16+E16+F16+G16+H16 -> 13950 | J16: =3500+3000 -> 6500 | K16: UI8ME5VSZZ/ UISOC86KOH | L16: SEP | M16: =I16-J16 -> 7450 | N16: TO EVICT | O16: SIGNED | Q16: R.EAST | R16: 50000 | S16: RCTD
A17: B2 | B17: PETER KARIUKI | C17: 0723743290 | D17: 0 | E17: 7500 | F17: =AUG!M17 -> -550 | G17: 100 | H17: 0 | I17: =D17+E17+F17+G17+H17 -> 7050 | J17: =500+7500 -> 8000 | K17: UI2FC5GSO9/UI2FC5GXLP | L17: SEP | M17: =I17-J17 -> -950 | O17: SIGNED | Q17: JAGIET | R17: 60000
A18: B3 | B18: STEPHEN NGANGA | C18: 0704543562 | E18: 10000 | F18: =AUG!M18 -> 15100 | G18: 100 | H18: 0 | I18: =D18+E18+F18+G18+H18 -> 25200 | J18: =8000+14000 -> 22000 | K18: UI9IY664O8/UG9IYAXVPA | L18: SEP | M18: =I18-J18 -> 3200 | O18: SIGNED | Q18: GHETTO | R18: 150000
A19: B4 | B19: CYTHIA MADESHE | C19: 0772369562 | E19: 7500 | F19: =AUG!M19 -> 5800 | G19: 100 | H19: 1500 | I19: =D19+E19+F19+G19+H19 -> 14900 | J19: =8000+9500 -> 17500 | K19: UI72H68VAE/UIT2H8U1VF | L19: SEP | M19: =I19-J19 -> -2600 | O19: SIGNED | Q19: GHETTO | R19: 150000 | S19: RCTD
A20: B5 | B20: George Kirigo | C20: 0710152025 | D20: 0 | E20: 7500 | F20: =AUG!M20 -> -150 | G20: 100 | H20: 250 | I20: =D20+E20+F20+G20+H20 -> 7700 | J20: =7750 -> 7750 | K20: UI5DA56NMM | L20: SEP | M20: =I20-J20 -> -50 | O20: SIGNED | Q20: APPHIA | R20: 100000 | S20: RCTD
A21: B6 | B21: KELVIN OSEMBO | C21: 0713098540 | D21: 10000 | E21: 10000 | F21: =AUG!M21 -> 0 | I21: =D21+E21+F21+G21+H21 -> 20000 | J21: =10200+3000+1500+300 -> 15000 | K21: UHS5N4E63B/UI4AX5HSCE/U9046/5060 | L21: SEP | M21: =I21-J21 -> 5000 | O21: SIGNED | Q21: SPICES | R21: 30000 | S21: RCTD
A22: C1 | B22: VACANT | F22: =AUG!M22 -> 0 | H22: 0 | I22: =D22+E22+F22+G22+H22 -> 0 | L22: SEP | M22: =I22-J22 -> 0 | O22: SIGNED | Q22: FRANCIS | R22: 11500 | S22: RCTD
A23: C2 | B23: Esther John | C23: 0723307353 | D23: 0 | E23: 7000 | F23: =AUG!M23 -> -50 | G23: 100 | H23: 500 | I23: =D23+E23+F23+G23+H23 -> 7550 | J23: =7600 -> 7600 | K23: UI4P056Z2Z | L23: SEP | M23: =I23-J23 -> -50 | O23: SIGNED | Q23: JAMES | R23: 15500 | S23: RCTD
A24: C3 | B24: DICKSON ZAWADI | C24: 0757132539 | E24: 7000 | F24: =AUG!M24 -> 2200 | G24: 100 | H24: 250 | I24: =D24+E24+F24+G24+H24 -> 9550 | J24: =7000+2050 -> 9050 | K24: UI47C56WZM/UIH7C6N46S | L24: SEP | M24: =I24-J24 -> 500 | O24: SIGNED | Q24: ADRIAN | R24: 43800 | S24: RCTD
A25: C4 | B25: JAMES BETHUEL | C25: 0724771903 | D25: 0 | E25: 7000 | F25: =AUG!M25 -> 3200 | G25: 100 | H25: 1000 | I25: =D25+E25+F25+G25+H25 -> 11300 | J25: =10200 -> 10200 | K25: UI57O58W0O | L25: SEP | M25: =I25-J25 -> 1100 | O25: SIGNED | R25: =SUM(R10:R24) -> 1054268 | S25: RCTD
A26: C5 | B26: HARRISON KAGO | C26: 0742093844 | D26: 10000 | E26: 10000 | F26: =AUG!M26 -> 0 | H26: 0 | I26: =D26+E26+F26+G26+H26 -> 20000 | J26: =15000 -> 15000 | K26: UHUCT558D5 | L26: SEP | M26: =I26-J26 -> 5000 | O26: SIGNED | S26: RCTD
A27: C6 | B27: CARETAKER | C27: 0714418782 | F27: =AUG!M27 -> 0 | H27: 0 | I27: =D27+E27+F27+G27+H27 -> 0 | L27: SEP | M27: =I27-J27 -> 0 | O27: SIGNED
A28: Totals | D28: =SUM(D10:D27) -> 20000 | E28: =SUM(E10:E27) -> 126000 | F28: =SUM(F10:F27) -> 42000 | G28: =SUM(G10:G27) -> 1400 | H28: =SUM(H10:H27) -> 6500 | I28: =SUM(I10:I27) -> 195900 | J28: =SUM(J10:J27) -> 171400 | M28: =SUM(M10:M27) -> 24500
A30: Less Management fees | J30: =8%*(J28-H28-G28-D28) -> 11480
A31: TOKENS | J31: =1000+1000 -> 2000
A32: KURIA GARBAGE | J32: 1600
A33: Waterbill | J33: 30743 | M33: =8%*M32 -> 0
A34: PAINT REVAMP HSE C1/BULB HOLDERS/MAGIC CONNECTOR/SCREWS/MAGIC CONNECTOR(C5/B3) | J34: =7000+1250 -> 8250
A35: WATER METER CLEANING
A36: TOTAL DEDUCTIONS | J36: =SUM(J30:J35) -> 54073
K37: 0
A38: BAL B/F | J38: =AUG!M43 -> -9110
K39: Paid | L39: Paid | M39: Balance
A40: Amount Due | J40: =J28-J36+J38 -> 108217 | K40: 80000 | M40: =J40-K40-L40 -> 28217
A42: AUTHORISED BY JOSEPH GITHINJI | M42: 46295
...

Sheet OCT
B1: LOBBY ENTERPRISES
A2: PROPERTY MANAGERS AND ESTATE AGENTS
A3: OCT 2026
K4: P.O.BOX 11987
A5: APPHIA APARTMENTS | K5: TEL :
A6: STATEMENT OF ACCOUNT
A7: NCBA PAYBILL '6432500027 | C7: 880100 | J7: Caretaker | K7: KELVIN
J8: Phone no | K8: 0714418782
A9: NAME | C9: PHONE NO | D9: DEPOSIT PAID | E9: MONTHLY RENT | F9: BAL B/D | G9: GARBAGE | H9: WATER BILLS | I9: RENT DUE | J9: RENT PAID | K9: RCT NO | L9: PERIOD | M9: BALANCE | N9: STATUS | O9: FORMS
A10: A1 | B10: MAULINE MALESI | C10: 0743508108 | D10: 0 | E10: 7500 | F10: =SEP!M10 -> 0 | G10: 100 | I10: =D10+E10+F10+G10+H10 -> 7600 | L10: OCT | M10: =I10-J10 -> 7600 | O10: SIGNED | Q10: THAMANDA | R10: 150000 | S10: RCTD
A11: A2 | B11: PETER | C11: 0719820676 | E11: 7500 | F11: =SEP!M11 -> 1650 | G11: 100 | I11: =D11+E11+F11+G11+H11 -> 9250 | L11: OCT | M11: =I11-J11 -> 9250 | O11: SIGNED | Q11: KINOO | R11: 50000
A12: A3 | B12: Chrispine ooko | C12: 0712271588 | D12: 0 | E12: 7500 | F12: =SEP!M12 -> 100 | G12: 100 | I12: =D12+E12+F12+G12+H12 -> 7700 | L12: OCT | M12: =I12-J12 -> 7700 | O12: SIGNED | Q12: KAGWE | R12: 140208
A13: A4 | B13: YASEER | C13: 0783047456 | D13: 0 | E13: 7500 | F13: =SEP!M13 -> 1000 | G13: 100 | I13: =D13+E13+F13+G13+H13 -> 8600 | L13: OCT | M13: =I13-J13 -> 8600 | O13: SIGNED | Q13: KIBALI | R13: 32850 | S13: RCTD
A14: A5 | B14: ABDUL RAHMAN | C14: 0725903270/0751934076 | E14: 7500 | F14: =SEP!M14 -> 100 | G14: 100 | I14: =D14+E14+F14+G14+H14 -> 7700 | L14: OCT | M14: =I14-J14 -> 7700 | O14: SIGNED | Q14: NJENGA | R14: 32160 | S14: RCTD
A15: A6 | B15: Vincent Mambili | C15: 0710558651 | E15: 7500 | F15: =SEP!M15 -> 3050 | G15: 100 | I15: =D15+E15+F15+G15+H15 -> 10650 | L15: OCT | M15: =I15-J15 -> 10650 | O15: SIGNED | Q15: KANGETHE | R15: 38250 | S15: RCTD
A16: B1 | B16: AMOS/STANLEY | C16: 0729892835 | E16: 7500 | F16: =SEP!M16 -> 7450 | G16: 100 | I16: =D16+E16+F16+G16+H16 -> 15050 | L16: OCT | M16: =I16-J16 -> 15050 | N16: TO EVICT | O16: SIGNED | Q16: R.EAST | R16: 50000 | S16: RCTD
A17: B2 | B17: PETER KARIUKI | C17: 0723743290 | D17: 0 | E17: 7500 | F17: =SEP!M17 -> -950 | G17: 100 | I17: =D17+E17+F17+G17+H17 -> 6650 | J17: =500+7500 -> 8000 | K17: UJ2FC933EP/UJ2FC9390G | L17: OCT | M17: =I17-J17 -> -1350 | O17: SIGNED | Q17: JAGIET | R17: 60000
A18: B3 | B18: STEPHEN NGANGA | C18: 0704543562 | E18: 10000 | F18: =SEP!M18 -> 3200 | G18: 100 | I18: =D18+E18+F18+G18+H18 -> 13300 | L18: OCT | M18: =I18-J18 -> 13300 | O18: SIGNED | Q18: GHETTO | R18: 150000
A19: B4 | B19: CYTHIA MADESHE | C19: 0772369562 | E19: 7500 | F19: =SEP!M19 -> -2600 | G19: 100 | I19: =D19+E19+F19+G19+H19 -> 5000 | L19: OCT | M19: =I19-J19 -> 5000 | O19: SIGNED | Q19: GHETTO | R19: 150000 | S19: RCTD
A20: B5 | B20: George Kirigo | C20: 0710152025 | D20: 0 | E20: 7500 | F20: =SEP!M20 -> -50 | G20: 100 | I20: =D20+E20+F20+G20+H20 -> 7550 | L20: OCT | M20: =I20-J20 -> 7550 | O20: SIGNED | Q20: APPHIA | R20: 100000 | S20: RCTD
A21: B6 | B21: KELVIN OSEMBO | C21: 0713098540 | E21: 10000 | F21: =SEP!M21 -> 5000 | I21: =D21+E21+F21+G21+H21 -> 15000 | L21: OCT | M21: =I21-J21 -> 15000 | O21: SIGNED | Q21: SPICES | R21: 30000 | S21: RCTD
A22: C1 | B22: VACANT | F22: =SEP!M22 -> 0 | I22: =D22+E22+F22+G22+H22 -> 0 | L22: OCT | M22: =I22-J22 -> 0 | O22: SIGNED | Q22: FRANCIS | R22: 11500 | S22: RCTD
A23: C2 | B23: Esther John | C23: 0723307353 | E23: 7000 | F23: =SEP!M23 -> -50 | G23: 100 | I23: =D23+E23+F23+G23+H23 -> 7050 | L23: OCT | M23: =I23-J23 -> 7050 | O23: SIGNED | Q23: JAMES | R23: 15500 | S23: RCTD
A24: C3 | B24: DICKSON ZAWADI | C24: 0757132539 | E24: 7000 | F24: =SEP!M24 -> 500 | G24: 100 | I24: =D24+E24+F24+G24+H24 -> 7600 | L24: OCT | M24: =I24-J24 -> 7600 | O24: SIGNED | Q24: ADRIAN | R24: 43800 | S24: RCTD
A25: C4 | B25: JAMES BETHUEL | C25: 0724771903 | E25: 7000 | F25: =SEP!M25 -> 1100 | G25: 100 | I25: =D25+E25+F25+G25+H25 -> 8200 | L25: OCT | M25: =I25-J25 -> 8200 | O25: SIGNED | R25: =SUM(R10:R24) -> 1054268 | S25: RCTD
A26: C5 | B26: HARRISON KAGO | C26: 0742093844 | E26: 10000 | F26: =SEP!M26 -> 5000 | I26: =D26+E26+F26+G26+H26 -> 15000 | L26: OCT | M26: =I26-J26 -> 15000 | O26: SIGNED | S26: RCTD
A27: C6 | B27: CARETAKER | C27: 0714418782 | F27: =SEP!M27 -> 0 | I27: =D27+E27+F27+G27+H27 -> 0 | L27: OCT | M27: =I27-J27 -> 0 | O27: SIGNED
A28: Totals | D28: =SUM(D10:D27) -> 0 | E28: =SUM(E10:E27) -> 126000 | F28: =SUM(F10:F27) -> 24500 | G28: =SUM(G10:G27) -> 1400 | H28: =SUM(H10:H27) -> 0 | I28: =SUM(I10:I27) -> 151900 | J28: =SUM(J10:J27) -> 8000 | M28: =SUM(M10:M27) -> 143900
A30: Less Management fees | J30: =8%*(J28-H28-G28-D28) -> 528
A31: TOKENS
A32: KURIA GARBAGE
A33: Waterbill | M33: =8%*M32 -> 0
A34: WATER METER CLEANING
A35: TOTAL DEDUCTIONS | J35: =SUM(J30:J34) -> 528
K36: 0
A37: BAL B/F | J37: =SEP!M40 -> 28217
K38: Paid | L38: Paid | M38: Balance
A39: Amount Due | J39: =J28-J35+J37 -> 35689 | M39: =J39-K39-L39 -> 35689
A41: AUTHORISED BY JOSEPH GITHINJI | M41: 46326
M46: =24740-12300-1700 -> 10740
...
