Workbook

Sheet JAN
C1: LOBBY ENTERPRISES
A2: PROPERTY MANAGERS AND ESTATE AGENTS
A3: 46053
I4: P.O.BOX 11987
I5: TEL : 0722711933/4454322
A6: KABAIKU | H6: Care taker
H7: Phone no
A9: HSE NO | B9: NAME | C9: PHONE NO | D9: DEPOSIT PAID | E9: MONTHLY RENT | F9: BAL B/D | G9: RENT DUE | H9: RENT PAID | I9: RCT NO | J9: PERIOD | K9: BALANCE | L9: STATUS | M9: FORMS
B10: LLD | F10: 0 | G10: =D10+E10+F10 -> 0 | J10: JAN | K10: =G10-H10 -> 0
B11: LLD | F11: 0 | G11: =D11+E11+F11 -> 0 | J11: JAN | K11: =G11-H11 -> 0
A12: 1 | B12: ELIJAH | D12: 1000 | E12: 2500 | F12: 0 | G12: =D12+E12+F12 -> 3500 | H12: =2600 -> 2600 | I12: DIRECT | J12: JAN | K12: =G12-H12 -> 900
A13: 2 | B13: JOSEPH KITHUKU | C13: 01113299379 | E13: 2500 | F13: 2500 | G13: =D13+E13+F13 -> 5000 | H13: =5000 -> 5000 | I13: DIRECT | J13: JAN | K13: =G13-H13 -> 0
A14: 3 | B14: NELSON KHAVUSHIRWA | C14: 0111590680 | E14: 2500 | F14: 0 | G14: =D14+E14+F14 -> 2500 | H14: =2000+500 -> 2500 | I14: UAOP73JQVS/UAGP73Z77H | J14: JAN | K14: =G14-H14 -> 0
A15: 4 | B15: VACANT | G15: =D15+E15+F15 -> 0 | J15: JAN | K15: =G15-H15 -> 0
A16: 5 | B16: PETER( KINYANJUI POLLY) | E16: 2500 | F16: 2500 | G16: =D16+E16+F16 -> 5000 | H16: =G16 -> 5000 | I16: DIRECT | K16: =G16-H16 -> 0
A17: 6 | B17: NEW TENANT | E17: 2500 | F17: 0 | G17: =D17+E17+F17 -> 2500 | H17: =2500 -> 2500 | I17: UAKI44AIXD | J17: JAN | K17: =G17-H17 -> 0
A18: 7 | B18: JOSEPH NJENGA | C18: 0755390895 | E18: 2500 | F18: 200 | G18: =D18+E18+F18 -> 2700 | H18: =2000+500 -> 2500 | I18: UAFC441MGS/UAKC44FW8R | J18: JAN | K18: =G18-H18 -> 200 | O18: PETER KINYANJUI
A19: 8 | B19: MICHAEL | E19: 2500 | F19: 0 | G19: =D19+E19+F19 -> 2500 | H19: =2500 -> 2500 | I19: DIRECT | J19: JAN | K19: =G19-H19 -> 0
A20: 9 | B20: TENANT | E20: 2500 | F20: 0 | G20: =D20+E20+F20 -> 2500 | H20: =2500 -> 2500 | I20: DIRECT | J20: JAN | K20: =G20-H20 -> 0
A21: 10 | B21: TENANT | F21: 0 | G21: =D21+E21+F21 -> 0 | J21: JAN | K21: =G21-H21 -> 0
A22: 11 | B22: ISAYA ONDUNGA | C22: 0721854507 | E22: 2200 | F22: 0 | G22: =D22+E22+F22 -> 2200 | H22: =2200 -> 2200 | I22: UAE6A3Q5J1 | J22: JAN | K22: =G22-H22 -> 0
A23: 12 | B23: martin/BRADINA | C23: 0702306957 | E23: 2500 | F23: 0 | G23: =D23+E23+F23 -> 2500 | H23: =2500 -> 2500 | I23: UA56A2XD9G | J23: JAN | K23: =G23-H23 -> 0
A24: 13 | B24: ELECTINA AKHURA | C24: 0711949488 | E24: 2500 | F24: 2500 | G24: =D24+E24+F24 -> 5000 | H24: =2500 -> 2500 | I24: UAKP147QJ8 | J24: JAN | K24: =G24-H24 -> 2500
A25: 14 | B25: VACANT | G25: =D25+E25+F25 -> 0 | J25: JAN | K25: =G25-H25 -> 0
A26: 15 | B26: ERIC MUNYWOKI | C26: 0702306957 | E26: 2500 | F26: 700 | G26: =D26+E26+F26 -> 3200 | H26: =2400 -> 2400 | I26: UACE53M4LT | J26: JAN | K26: =G26-H26 -> 800
A27: 16/5 | B27: PHILIS MUTHONI | C27: 0707135975 | E27: 3000 | F27: 0 | G27: =D27+E27+F27 -> 3000 | H27: 3000 | I27: UAAEB3F0I6 | J27: JAN | K27: =G27-H27 -> 0 | M27: SIGNED
A28: 17 | B28: LLD | F28: 0 | G28: =D28+E28+F28 -> 0 | J28: JAN | K28: =G28-H28 -> 0
A29: 19 | B29: CHRIS MUTETHIA | C29: 0101270483 | E29: 2500 | F29: 0 | G29: =D29+E29+F29 -> 2500 | H29: =1500+500+500 -> 2500 | I29: UAIOM44OV7/UAOOM4Q47N/UAVOM5CYJL | J29: JAN | K29: =G29-H29 -> 0
A30: 20 | B30: VACANT | G30: =D30+E30+F30 -> 0 | J30: JAN | K30: =G30-H30 -> 0
A31: 21 | B31: MOSES NDWIGA | C31: 0708870237 | E31: 2500 | F31: 0 | G31: =D31+E31+F31 -> 2500 | H31: =2500 -> 2500 | I31: UACR53GSUY | J31: JAN | K31: =G31-H31 -> 0
D32: =SUM(D13:D29) -> 0 | E32: =SUM(E10:E31) -> 37700 | F32: =SUM(F10:F31) -> 8400 | G32: =SUM(G10:G31) -> 47100 | H32: =SUM(H10:H31) -> 42700 | J32: =SUM(J13:J29) -> 0 | K32: =SUM(K10:K31) -> 4400
A33: Totals
A34: Deductions
A35: Less Management fees | H35: =H32*10% -> 4270
A36: CHIEF EVICTION FEE HSE 14 | H36: 1000
A37: DIRECT | H37: =H19+H12+H13+H16+H20 -> 17600
A38: TOTAL DEDUCTIONS | H38: =SUM(H35:H37) -> 22870
A39: BAL B/F | H39: =[1]DEC!$K$38 -> -5230 | I39: Cash deposited | J39: Paid | K39: Balance
A40: AMOUNT DUE | H40: =H32-H38+H39 -> 14600 | I40: 15000 | K40: =H40-I40-J40 -> -400
A41: AUTHORISED BY JOSEPH GITHINJI | K41: 46053
...

Sheet FEB
C1: LOBBY ENTERPRISES
A2: PROPERTY MANAGERS AND ESTATE AGENTS
A3: 46081
I4: P.O.BOX 11987
I5: TEL : 0722711933/4454322
A6: KABAIKU | H6: Care taker
H7: Phone no
A9: HSE NO | B9: NAME | C9: PHONE NO | D9: DEPOSIT PAID | E9: MONTHLY RENT | F9: BAL B/D | G9: RENT DUE | H9: RENT PAID | I9: RCT NO | J9: PERIOD | K9: BALANCE | L9: STATUS | M9: FORMS
B10: LLD | F10: =JAN!K10 -> 0 | G10: =D10+E10+F10 -> 0 | J10: FEB | K10: =G10-H10 -> 0
B11: LLD | F11: =JAN!K11 -> 0 | G11: =D11+E11+F11 -> 0 | J11: FEB | K11: =G11-H11 -> 0
A12: 1 | B12: ELIJAH | E12: 2500 | F12: =JAN!K12 -> 900 | G12: =D12+E12+F12 -> 3400 | H12: =2500 -> 2500 | I12: UB88565E10 | J12: FEB | K12: =G12-H12 -> 900
A13: 2 | B13: JOSEPH KITHUKU | C13: 01113299379 | E13: 2500 | F13: =JAN!K13 -> 0 | G13: =D13+E13+F13 -> 2500 | H13: =2500 -> 2500 | I13: DIRECT | J13: FEB | K13: =G13-H13 -> 0
A14: 3 | B14: NELSON KHAVUSHIRWA | C14: 0111590680 | E14: 2500 | F14: =JAN!K14 -> 0 | G14: =D14+E14+F14 -> 2500 | H14: =1700 -> 1700 | I14: UBFP76RQV2 | J14: FEB | K14: =G14-H14 -> 800
A15: 4 | B15: TENANT | E15: 2500 | F15: =JAN!K15 -> 0 | G15: =D15+E15+F15 -> 2500 | H15: 2500 | I15: DIRECT | J15: FEB | K15: =G15-H15 -> 0
A16: 5 | B16: PETER( KINYANJUI POLLY) | E16: 2500 | F16: =JAN!K16 -> 0 | G16: =D16+E16+F16 -> 2500 | J16: FEB | K16: =G16-H16 -> 2500 | L16: LOCKED
A17: 6 | B17: NEW TENANT | E17: 2500 | F17: =JAN!K17 -> 0 | G17: =D17+E17+F17 -> 2500 | H17: =2500 -> 2500 | I17: 28TH JAN | J17: FEB | K17: =G17-H17 -> 0
A18: 7 | B18: JOSEPH NJENGA | C18: 0755390895 | E18: 2500 | F18: =JAN!K18 -> 200 | G18: =D18+E18+F18 -> 2700 | H18: =1000 -> 1000 | I18: UBRC4817FF | J18: FEB | K18: =G18-H18 -> 1700 | O18: PETER KINYANJUI
A19: 8 | B19: MICHAEL | E19: 2500 | F19: =JAN!K19 -> 0 | G19: =D19+E19+F19 -> 2500 | H19: =1500+1000 -> 2500 | I19: UB9IH67ISI/UBGIH6VKJT | J19: FEB | K19: =G19-H19 -> 0
A20: 9 | B20: TENANT | E20: 2500 | F20: =JAN!K20 -> 0 | G20: =D20+E20+F20 -> 2500 | H20: =2500 -> 2500 | I20: UB9I4665NC | J20: FEB | K20: =G20-H20 -> 0
A21: 10 | B21: JAMES OTIENO | E21: 2500 | F21: =JAN!K21 -> 0 | G21: =D21+E21+F21 -> 2500 | H21: =2000 -> 2000 | I21: UBH896XHSO | J21: FEB | K21: =G21-H21 -> 500
A22: 11 | B22: ISAYA ONDUNGA | C22: 0721854507 | E22: 2200 | F22: =JAN!K22 -> 0 | G22: =D22+E22+F22 -> 2200 | H22: =2200 -> 2200 | I22: UBC6A6HE86 | J22: FEB | K22: =G22-H22 -> 0
A23: 12 | B23: martin/BRADINA | C23: 0702306957 | E23: 2500 | F23: =JAN!K23 -> 0 | G23: =D23+E23+F23 -> 2500 | J23: FEB | K23: =G23-H23 -> 2500 | L23: LOCKED
A24: 13 | B24: ELECTINA AKHURA | C24: 0711949488 | E24: 2500 | F24: =JAN!K24 -> 2500 | G24: =D24+E24+F24 -> 5000 | H24: 5000 | I24: DIRECT | J24: FEB | K24: =G24-H24 -> 0 | L24: 18TH
A25: 14 | B25: TENANT | E25: 2500 | F25: =JAN!K25 -> 0 | G25: =D25+E25+F25 -> 2500 | H25: 2500 | I25: DIRECT | J25: FEB | K25: =G25-H25 -> 0
A26: 15 | B26: ERIC MUNYWOKI | C26: 0702306957 | E26: 2500 | F26: =JAN!K26 -> 800 | G26: =D26+E26+F26 -> 3300 | H26: =2500 -> 2500 | I26: UBEE56P5QV | J26: FEB | K26: =G26-H26 -> 800
A27: 16/5 | B27: PHILIS MUTHONI | C27: 0707135975 | E27: 3000 | F27: =JAN!K27 -> 0 | G27: =D27+E27+F27 -> 3000 | H27: =3000 -> 3000 | I27: UB9EB69MN | J27: FEB | K27: =G27-H27 -> 0 | M27: SIGNED
A28: 17 | B28: LLD | F28: =JAN!K28 -> 0 | G28: =D28+E28+F28 -> 0 | J28: FEB | K28: =G28-H28 -> 0
A29: 19 | B29: CHRIS MUTETHIA | C29: 0101270483 | E29: 2500 | F29: =JAN!K29 -> 0 | G29: =D29+E29+F29 -> 2500 | H29: =2500 -> 2500 | I29: UBFOM6QNBS | J29: FEB | K29: =G29-H29 -> 0
A30: 20 | B30: TENANT | E30: 2500 | F30: =JAN!K30 -> 0 | G30: =D30+E30+F30 -> 2500 | H30: 2500 | I30: DIRECT | J30: FEB | K30: =G30-H30 -> 0
A31: 21 | B31: MOSES NDWIGA | C31: 0708870237 | E31: 2500 | F31: =JAN!K31 -> 0 | G31: =D31+E31+F31 -> 2500 | J31: FEB | K31: =G31-H31 -> 2500
D32: =SUM(D13:D29) -> 0 | E32: =SUM(E10:E31) -> 47700 | F32: =SUM(F10:F31) -> 4400 | G32: =SUM(G10:G31) -> 52100 | H32: =SUM(H10:H31) -> 39900 | J32: =SUM(J13:J29) -> 0 | K32: =SUM(K10:K31) -> 12200
A33: Totals
A34: Deductions
A35: Less Management fees | H35: =H32*10% -> 3990
A36: DIRECT | H36: =H30+H25+H24+H15+H13 -> 15000
A37: TOTAL DEDUCTIONS | H37: =SUM(H35:H36) -> 18990
A38: BAL B/F | H38: =JAN!K40 -> -400 | I38: Cash deposited | J38: Paid | K38: Balance
A39: AMOUNT DUE | H39: =H32-H37+H38 -> 20510 | I39: 15000 | J39: 0 | K39: =H39-I39-J39 -> 5510
A40: AUTHORISED BY JOSEPH GITHINJI | K40: 46081
H44: =H32/G32*100 -> 76.583493
...

Sheet MAR
C1: LOBBY ENTERPRISES
A2: PROPERTY MANAGERS AND ESTATE AGENTS
A3: 46112
I4: P.O.BOX 11987
I5: TEL : 0722711933/4454322
A6: KABAIKU | H6: Care taker
H7: Phone no
A9: HSE NO | B9: NAME | C9: PHONE NO | D9: DEPOSIT PAID | E9: MONTHLY RENT | F9: BAL B/D | G9: RENT DUE | H9: RENT PAID | I9: RCT NO | J9: PERIOD | K9: BALANCE | L9: STATUS | M9: FORMS
B10: LLD | F10: =FEB!K10 -> 0 | G10: =D10+E10+F10 -> 0 | J10: MAR | K10: =G10-H10 -> 0
B11: LLD | F11: =FEB!K11 -> 0 | G11: =D11+E11+F11 -> 0 | J11: MAR | K11: =G11-H11 -> 0
A12: 1 | B12: ELIJAH ONDENGO | E12: 2500 | F12: =FEB!K12 -> 900 | G12: =D12+E12+F12 -> 3400 | H12: =2500 -> 2500 | I12: UCC85946UR | J12: MAR | K12: =G12-H12 -> 900
A13: 2 | B13: JOSEPH KITHUKU | C13: 01113299379 | E13: 2500 | F13: =FEB!K13 -> 0 | G13: =D13+E13+F13 -> 2500 | H13: =1800 -> 1800 | I13: UCGEX9QVDB | J13: MAR | K13: =G13-H13 -> 700
A14: 3 | B14: NELSON KHAVUSHIRWA | C14: 0111590680 | E14: 2500 | F14: =FEB!K14 -> 800 | G14: =D14+E14+F14 -> 3300 | H14: =600 -> 600 | I14: UCKP79WSRU | J14: MAR | K14: =G14-H14 -> 2700 | L14: EVICT
A15: 4 | B15: JOSPHAT OTIENO | E15: 2500 | F15: =FEB!K15 -> 0 | G15: =D15+E15+F15 -> 2500 | J15: MAR | K15: =G15-H15 -> 2500 | L15: EVICT
A16: 5 | B16: PETER( KINYANJUI POLLY) | E16: 2500 | F16: =FEB!K16 -> 2500 | G16: =D16+E16+F16 -> 5000 | H16: =5000 -> 5000 | I16: UCI59RO8J | J16: MAR | K16: =G16-H16 -> 0
A17: 6 | B17: JOSPAT KINZI | E17: 2500 | F17: =FEB!K17 -> 0 | G17: =D17+E17+F17 -> 2500 | H17: =2500 -> 2500 | I17: UC5DN8BXQ2 | J17: MAR | K17: =G17-H17 -> 0
A18: 7 | B18: JOSEPH NJENGA | C18: 0755390895 | E18: 2500 | F18: =FEB!K18 -> 1700 | G18: =D18+E18+F18 -> 4200 | H18: =1500+1000 -> 2500 | I18: ZUCS/UCC49SVL6 | J18: MAR | K18: =G18-H18 -> 1700 | O18: PETER KINYANJUI
A19: 8 | B19: MICHAEL | E19: 2500 | F19: =FEB!K19 -> 0 | G19: =D19+E19+F19 -> 2500 | H19: =2500 -> 2500 | I19: UCIIH9Q4W9 | J19: MAR | K19: =G19-H19 -> 0
A20: 9 | B20: TENANT | E20: 2500 | F20: =FEB!K20 -> 0 | G20: =D20+E20+F20 -> 2500 | H20: =2000 -> 2000 | I20: UCMI4A4ZUB | J20: MAR | K20: =G20-H20 -> 500
A21: 10 | B21: JAMES OTIENO | E21: 2500 | F21: =FEB!K21 -> 500 | G21: =D21+E21+F21 -> 3000 | H21: =1000 -> 1000 | I21: UCJ899SBB3 | J21: MAR | K21: =G21-H21 -> 2000
A22: 11 | B22: ISAYA ONDUNGA | C22: 0721854507 | E22: 2200 | F22: =FEB!K22 -> 0 | G22: =D22+E22+F22 -> 2200 | H22: =2200 -> 2200 | I22: UCE6A9A710 | J22: MAR | K22: =G22-H22 -> 0
A23: 12 | B23: TENANT | E23: 2500 | G23: =D23+E23+F23 -> 2500 | H23: =2500 -> 2500 | I23: DIRECT | J23: MAR | K23: =G23-H23 -> 0
A24: 13 | B24: ELECTINA AKHURA | C24: 0711949488 | E24: 2500 | F24: =FEB!K24 -> 0 | G24: =D24+E24+F24 -> 2500 | H24: =2500 -> 2500 | I24: DIRECT | J24: MAR | K24: =G24-H24 -> 0 | L24: 18TH
A25: 14 | B25: TENANT | E25: 2500 | F25: =FEB!K25 -> 0 | G25: =D25+E25+F25 -> 2500 | H25: =2500 -> 2500 | I25: UC70B8KJ0O | J25: MAR | K25: =G25-H25 -> 0
A26: 15 | B26: ERIC MUNYWOKI | C26: 0702306957 | E26: 2500 | F26: =FEB!K26 -> 800 | G26: =D26+E26+F26 -> 3300 | H26: =2700 -> 2700 | I26: UCAE58X8CF | J26: MAR | K26: =G26-H26 -> 600
A27: 16/5 | B27: PHILIS MUTHONI | C27: 0707135975 | E27: 3000 | F27: =FEB!K27 -> 0 | G27: =D27+E27+F27 -> 3000 | H27: =3000 -> 3000 | I27: UCAEB8YNV0 | J27: MAR | K27: =G27-H27 -> 0 | M27: SIGNED
A28: 17 | B28: LLD | F28: =FEB!K28 -> 0 | G28: =D28+E28+F28 -> 0 | J28: MAR | K28: =G28-H28 -> 0
A29: 19 | B29: CHRIS MUTETHIA | C29: 0101270483 | E29: 2500 | F29: =FEB!K29 -> 0 | G29: =D29+E29+F29 -> 2500 | H29: =2500 -> 2500 | I29: DIRECT | J29: MAR | K29: =G29-H29 -> 0 | L29: 15TH
A30: 21 | B30: MOSES NDWIGA | C30: 0708870237 | E30: 2500 | F30: =FEB!K31 -> 2500 | G30: =D30+E30+F30 -> 5000 | H30: =2500+2500 -> 5000 | I30: UC6R58F1CC/UCOR5A79LD | J30: MAR | K30: =G30-H30 -> 0
D31: =SUM(D13:D29) -> 0 | E31: =SUM(E10:E30) -> 45200 | F31: =SUM(F10:F30) -> 9700 | G31: =SUM(G10:G30) -> 54900 | H31: =SUM(H10:H30) -> 43300 | J31: =SUM(J13:J29) -> 0 | K31: =SUM(K10:K30) -> 11600
A32: Totals
A33: Deductions
A34: Less Management fees | H34: =H31*10% -> 4330
A35: DIRECT | H35: =H29+H24+H23 -> 7500
A36: CHIEF EVICTION HSE 12 | H36: =1000 -> 1000
A37: Rental Tax | H37: 3980
A38: TOTAL DEDUCTIONS | H38: =SUM(H34:H37) -> 16810
A39: BAL B/F | H39: =FEB!K39 -> 5510 | I39: Cash deposited | J39: Paid | K39: Balance
A40: AMOUNT DUE | H40: =H31-H38+H39 -> 32000 | I40: 20000 | J40: 12000 | K40: =H40-I40-J40 -> 0
A41: AUTHORISED BY JOSEPH GITHINJI | K41: 46112
...

Sheet APR
C1: LOBBY ENTERPRISES
A2: PROPERTY MANAGERS AND ESTATE AGENTS
A3: 46142
I4: P.O.BOX 11987
I5: TEL : 0722711933/4454322
A6: KABAIKU | H6: Care taker
H7: Phone no
A9: HSE NO | B9: NAME | C9: PHONE NO | D9: DEPOSIT PAID | E9: MONTHLY RENT | F9: BAL B/D | G9: RENT DUE | H9: RENT PAID | I9: RCT NO | J9: PERIOD | K9: BALANCE | L9: STATUS | M9: FORMS
B10: LLD | F10: =MAR!K10 -> 0 | G10: =D10+E10+F10 -> 0 | J10: APR | K10: =G10-H10 -> 0
B11: LLD | F11: =MAR!K11 -> 0 | G11: =D11+E11+F11 -> 0 | J11: APR | K11: =G11-H11 -> 0
A12: 1 | B12: ELIJAH ONDENGO | E12: 2500 | F12: =MAR!K12 -> 900 | G12: =D12+E12+F12 -> 3400 | H12: =2500 -> 2500 | I12: UDA850HG3S | J12: APR | K12: =G12-H12 -> 900 | M12: RCTD
A13: 2 | B13: JOSEPH KITHUKU | C13: 01113299379 | E13: 2500 | F13: =MAR!K13 -> 700 | G13: =D13+E13+F13 -> 3200 | J13: APR | K13: =G13-H13 -> 3200 | L13: LOCJED
A14: 3 | B14: NELSON KHAVUSHIRWA | C14: 0111590680 | E14: 2500 | F14: =MAR!K14 -> 2700 | G14: =D14+E14+F14 -> 5200 | H14: =1800 -> 1800 | I14: UD2P7BC6QL | J14: APR | K14: =G14-H14 -> 3400 | M14: RCTD
A15: 4 | B15: FREDRICK OTIENO | C15: 0704917113 | E15: 2500 | G15: =D15+E15+F15 -> 2500 | H15: =1500 -> 1500 | I15: UDM7M1W2S4 | J15: APR | K15: =G15-H15 -> 1000
A16: 5 | B16: PETER( KINYANJUI POLLY) | E16: 2500 | F16: =MAR!K16 -> 0 | G16: =D16+E16+F16 -> 2500 | H16: =2500 -> 2500 | I16: UD9I80BSAW | J16: APR | K16: =G16-H16 -> 0 | M16: RCTD
A17: 6 | B17: JOSPHAT KINZI | E17: 2500 | F17: =MAR!K17 -> 0 | G17: =D17+E17+F17 -> 2500 | H17: =2500 -> 2500 | I17: UD2DNB7VAE | J17: APR | K17: =G17-H17 -> 0 | M17: RCTD
A18: 7 | B18: JOSEPH NJENGA/ELIZABETH | C18: 0755390895 | E18: 2500 | F18: =MAR!K18 -> 1700 | G18: =D18+E18+F18 -> 4200 | H18: =1800+500+1500 -> 3800 | I18: UD7C407S62/UDEC411NHL/2369 | J18: APR | K18: =G18-H18 -> 400 | M18: RCTD | O18: PETER KINYANJUI
A19: 8 | B19: MICHAEL | E19: 2500 | F19: =MAR!K19 -> 0 | G19: =D19+E19+F19 -> 2500 | H19: =1250+500 -> 1750 | I19: UDHIH1627K/UDLHI1MQTR | J19: APR | K19: =G19-H19 -> 750
A20: 9 | B20: TENANT | E20: 2500 | F20: =MAR!K20 -> 500 | G20: =D20+E20+F20 -> 3000 | H20: =3000 -> 3000 | I20: UDRI426XI0 | J20: APR | K20: =G20-H20 -> 0
A21: 10 | B21: JAMES OTIENO | E21: 2500 | F21: =MAR!K21 -> 2000 | G21: =D21+E21+F21 -> 4500 | H21: =500+3200 -> 3700 | I21: UD389BC4OX/UDE830VT9B | J21: APR | K21: =G21-H21 -> 800 | M21: RCTD
A22: 11 | B22: ISAYA ONDUNGA | C22: 0721854507 | E22: 2200 | F22: =MAR!K22 -> 0 | G22: =D22+E22+F22 -> 2200 | H22: =2200 -> 2200 | I22: UDC6A0ZWB | J22: APR | K22: =G22-H22 -> 0 | M22: RCTD
A23: 12 | B23: TENANT | E23: 2500 | F23: =MAR!K23 -> 0 | G23: =D23+E23+F23 -> 2500 | H23: =2000 -> 2000 | I23: UDRI426UUB | J23: APR | K23: =G23-H23 -> 500
A24: 13 | B24: ELECTINA AKHURA | C24: 0711949488 | E24: 2500 | F24: =MAR!K24 -> 0 | G24: =D24+E24+F24 -> 2500 | J24: APR | K24: =G24-H24 -> 2500 | L24: LOCJED
A25: 14 | B25: STEPHEN ORIAH | E25: 2500 | F25: =MAR!K25 -> 0 | G25: =D25+E25+F25 -> 2500 | H25: =2000 -> 2000 | I25: UDI0B17LJH | J25: APR | K25: =G25-H25 -> 500
A26: 15 | B26: ERIC MUNYWOKI | C26: 0702306957 | E26: 2500 | F26: =MAR!K26 -> 600 | G26: =D26+E26+F26 -> 3100 | H26: =1350 -> 1350 | I26: UDEE50SRCW | J26: APR | K26: =G26-H26 -> 1750 | M26: RCTD
A27: 16/5 | B27: PHILIS MUTHONI | C27: 0707135975 | E27: 3000 | F27: =MAR!K27 -> 0 | G27: =D27+E27+F27 -> 3000 | H27: =3000 -> 3000 | I27: UD8EB09BG5 | J27: APR | K27: =G27-H27 -> 0 | M27: SIGNED
A28: 17 | B28: LLD | F28: =MAR!K28 -> 0 | G28: =D28+E28+F28 -> 0 | J28: APR | K28: =G28-H28 -> 0
A29: 18 | B29: TENANT | E29: 2500 | G29: =D29+E29+F29 -> 2500 | H29: =2500 -> 2500 | I29: DIRECT | K29: =G29-H29 -> 0
A30: 19 | B30: CHRIS MUTETHIA | C30: 0101270483 | E30: 2500 | F30: =MAR!K29 -> 0 | G30: =D30+E30+F30 -> 2500 | J30: APR | K30: =G30-H30 -> 2500 | L30: LOCJED
A31: 21 | B31: MOSES NDWIGA | C31: 0708870237 | E31: 2500 | F31: =MAR!K30 -> 0 | G31: =D31+E31+F31 -> 2500 | H31: =2500 -> 2500 | I31: UDFR50RK9C | J31: APR | K31: =G31-H31 -> 0
D32: =SUM(D13:D30) -> 0 | E32: =SUM(E10:E31) -> 47700 | F32: =SUM(F10:F31) -> 9100 | G32: =SUM(G10:G31) -> 56800 | H32: =SUM(H10:H31) -> 38600 | J32: =SUM(J13:J30) -> 0 | K32: =SUM(K10:K31) -> 18200
A33: Totals
A34: Deductions
A35: Less Management fees | H35: =H32*10% -> 3860
A36: DIRECT | H36: =H29 -> 2500
A37: TOTAL DEDUCTIONS | H37: =SUM(H35:H36) -> 6360
A38: BAL B/F | H38: =MAR!K40 -> 0 | I38: Cash deposited | J38: Paid | K38: Balance
A39: AMOUNT DUE | H39: =H32-H37+H38 -> 32240 | I39: 20000 | J39: 12240 | K39: =H39-I39-J39 -> 0
A40: AUTHORISED BY JOSEPH GITHINJI | K40: 46142
H44: =H32/G32*100 -> 67.957746
...

Sheet MAY
C1: LOBBY ENTERPRISES
A2: PROPERTY MANAGERS AND ESTATE AGENTS
A3: 46173
I4: P.O.BOX 11987
I5: TEL : 0722711933/4454322
A6: KABAIKU | H6: Care taker
H7: Phone no
A9: HSE NO | B9: NAME | C9: PHONE NO | D9: DEPOSIT PAID | E9: MONTHLY RENT | F9: BAL B/D | G9: RENT DUE | H9: RENT PAID | I9: RCT NO | J9: PERIOD | K9: BALANCE | L9: STATUS | M9: FORMS
B10: LLD | F10: =APR!K10 -> 0 | G10: =D10+E10+F10 -> 0 | J10: MAY | K10: =G10-H10 -> 0
B11: LLD | F11: =APR!K11 -> 0 | G11: =D11+E11+F11 -> 0 | J11: MAY | K11: =G11-H11 -> 0
A12: 1 | B12: ELIJAH ONDENGO | E12: 2500 | F12: =APR!K12 -> 900 | G12: =D12+E12+F12 -> 3400 | H12: =2300 -> 2300 | I12: UEB8542MIT | J12: MAY | K12: =G12-H12 -> 1100 | M12: RCTD
A13: 2 | B13: VACANT | G13: =D13+E13+F13 -> 0 | J13: MAY | K13: =G13-H13 -> 0
A14: 3 | B14: NELSON KHAVUSHIRWA | C14: 0111590680 | E14: 2500 | F14: =APR!K14 -> 3400 | G14: =D14+E14+F14 -> 5900 | H14: =2500 -> 2500 | I14: UEBP73ZFAZ | J14: MAY | K14: =G14-H14 -> 3400 | L14: EVICT | M14: RCTD
A15: 4 | B15: FREDRICK OTIENO | C15: 0704917113 | E15: 2500 | F15: =APR!K15 -> 1000 | G15: =D15+E15+F15 -> 3500 | H15: =1000 -> 1000 | I15: UEP7M5RSYA | J15: MAY | K15: =G15-H15 -> 2500
A16: 5 | B16: PETER( KINYANJUI POLLY) | E16: 2500 | F16: =APR!K16 -> 0 | G16: =D16+E16+F16 -> 2500 | H16: =2500 -> 2500 | I16: UE7I83LDY0 | J16: MAY | K16: =G16-H16 -> 0 | M16: RCTD
A17: 6 | B17: JOSPHAT KINZI | E17: 2500 | F17: =APR!K17 -> 0 | G17: =D17+E17+F17 -> 2500 | H17: =2500 -> 2500 | I17: UE1DN2L8G | J17: MAY | K17: =G17-H17 -> 0 | M17: RCTD
A18: 7 | B18: JOSEPH NJENGA/ELIZABETH | C18: 0755390895 | E18: 2500 | F18: =APR!K18 -> 400 | G18: =D18+E18+F18 -> 2900 | H18: =2000 -> 2000 | I18: UEFC44OWUW | J18: MAY | K18: =G18-H18 -> 900 | M18: RCTD | O18: PETER KINYANJUI
A19: 8 | B19: MICHAEL | E19: 2500 | F19: =APR!K19 -> 750 | G19: =D19+E19+F19 -> 3250 | H19: =750+2000 -> 2750 | I19: UEAIH3R2KA/UEPIH5GKKQ | J19: MAY | K19: =G19-H19 -> 500
A20: 9 | B20: ISAAC JUMA | E20: 2500 | F20: =APR!K20 -> 0 | G20: =D20+E20+F20 -> 2500 | J20: MAY | K20: =G20-H20 -> 2500 | L20: EVICT
A21: 10 | B21: JAMES OTIENO | E21: 2500 | F21: =APR!K21 -> 800 | G21: =D21+E21+F21 -> 3300 | J21: MAY | K21: =G21-H21 -> 3300 | L21: EVICT | M21: RCTD
A22: 11 | B22: ISAYA ONDUNGA | C22: 0721854507 | E22: 2200 | F22: =APR!K22 -> 0 | G22: =D22+E22+F22 -> 2200 | H22: =2200 -> 2200 | I22: UEA6A3OJ0P | J22: MAY | K22: =G22-H22 -> 0 | M22: RCTD
A23: 12 | B23: TENANT | E23: 2500 | F23: =APR!K23 -> 500 | G23: =D23+E23+F23 -> 3000 | H23: =3000 -> 3000 | I23: DIRECT | J23: MAY | K23: =G23-H23 -> 0
A24: 13 | B24: ELECTINA AKHURA | C24: 0711949488 | E24: 2500 | F24: =APR!K24 -> 2500 | G24: =D24+E24+F24 -> 5000 | H24: 4500 | I24: DIRECT | J24: MAY | K24: =G24-H24 -> 500 | L24: 18TH
A25: 14 | B25: VACANT | G25: =D25+E25+F25 -> 0 | J25: MAY | K25: =G25-H25 -> 0
A26: 15 | B26: ERIC MUNYWOKI | C26: 0702306957 | E26: 2500 | F26: =APR!K26 -> 1750 | G26: =D26+E26+F26 -> 4250 | H26: =2500+1000 -> 3500 | I26: UEBE53VWF6/UEOE55ELTJ | J26: MAY | K26: =G26-H26 -> 750 | L26: MOVED OUT | M26: RCTD
A27: 16/5 | B27: PHILIS MUTHONI | C27: 0707135975 | E27: 3000 | F27: =APR!K27 -> 0 | G27: =D27+E27+F27 -> 3000 | H27: =3000 -> 3000 | I27: UE7EB3KRZM | J27: MAY | K27: =G27-H27 -> 0 | M27: SIGNED
A28: 17 | B28: LLD | F28: =APR!K28 -> 0 | G28: =D28+E28+F28 -> 0 | J28: MAY | K28: =G28-H28 -> 0
A29: 18 | B29: TENANT | E29: 2500 | F29: =APR!K29 -> 0 | G29: =D29+E29+F29 -> 2500 | H29: =2500 -> 2500 | I29: DIRECT | J29: MAY | K29: =G29-H29 -> 0
A30: 19 | B30: TENANT | E30: 2500 | G30: =D30+E30+F30 -> 2500 | H30: =2500 -> 2500 | I30: DIRECT | J30: MAY | K30: =G30-H30 -> 0 | L30: 15TH
A31: 21 | B31: MOSES NDWIGA | C31: 0708870237 | E31: 2500 | F31: =APR!K31 -> 0 | G31: =D31+E31+F31 -> 2500 | H31: =2500 -> 2500 | I31: UEKR54PQ8K | J31: MAY | K31: =G31-H31 -> 0
D32: =SUM(D13:D30) -> 0 | E32: =SUM(E10:E31) -> 42700 | F32: =SUM(F10:F31) -> 12000 | G32: =SUM(G10:G31) -> 54700 | H32: =SUM(H10:H31) -> 39250 | J32: =SUM(J13:J30) -> 0 | K32: =SUM(K10:K31) -> 15450
A33: Totals
A34: Deductions
A35: Less Management fees | H35: =H32*10% -> 3925
A36: RENTAL TAX | H36: 2678
A37: DIRECT | H37: =H30+H23+H29+H24 -> 12500
A38: TOTAL DEDUCTIONS | H38: =SUM(H35:H37) -> 19103
A39: BAL B/F | H39: =APR!K39 -> 0 | I39: Cash deposited | J39: Paid | K39: Balance
A40: AMOUNT DUE | H40: =H32-H38+H39 -> 20147 | I40: 20000 | J40: 0 | K40: =H40-I40-J40 -> 147
A41: AUTHORISED BY JOSEPH GITHINJI | K41: 46173
...

Sheet JUNE
C1: LOBBY ENTERPRISES
A2: PROPERTY MANAGERS AND ESTATE AGENTS
A3: 46203
I4: P.O.BOX 11987
I5: TEL : 0722711933/4454322
A6: KABAIKU | H6: Care taker
H7: Phone no
A9: HSE NO | B9: NAME | C9: PHONE NO | D9: DEPOSIT PAID | E9: MONTHLY RENT | F9: BAL B/D | G9: RENT DUE | H9: RENT PAID | I9: RCT NO | J9: PERIOD | K9: BALANCE | L9: STATUS | M9: FORMS
A10: 1 | B10: TENANT | E10: 2500 | G10: =D10+E10+F10 -> 2500 | H10: =2500 -> 2500 | I10: DIRECT | J10: JUNE | K10: =G10-H10 -> 0 | M10: RCTD
A11: 2 | B11: VACANT | F11: =MAY!K13 -> 0 | G11: =D11+E11+F11 -> 0 | J11: JUNE | K11: =G11-H11 -> 0
A12: 3 | B12: ELIJAH ONDENGO | E12: 2500 | F12: =MAY!K12 -> 1100 | G12: =D12+E12+F12 -> 3600 | H12: =2500+900 -> 3400 | I12: UF78573J31/direct | J12: JUNE | K12: =G12-H12 -> 200 | M12: RCTD
A13: 4 | B13: FREDRICK OTIENO | C13: 0704917113 | E13: 2500 | F13: =MAY!K15 -> 2500 | G13: =D13+E13+F13 -> 5000 | H13: =1500+1000+4000 -> 6500 | I13: UF27M6P36A/UFPHS90C95/UG2HS9CZT9 | J13: JUNE | K13: =G13-H13 -> -1500
A14: 5 | B14: PETER( KINYANJUI POLLY) | E14: 2500 | F14: =MAY!K16 -> 0 | G14: =D14+E14+F14 -> 2500 | H14: =2500 -> 2500 | I14: UFJI88FVXF | J14: JUNE | K14: =G14-H14 -> 0 | M14: RCTD
A15: 6 | B15: JOSPHAT KINZI | E15: 2500 | F15: =MAY!K17 -> 0 | G15: =D15+E15+F15 -> 2500 | H15: =2500 -> 2500 | I15: UF5DN6JK1M | J15: JUNE | K15: =G15-H15 -> 0 | M15: RCTD
A16: 7 | B16: JOSEPH NJENGA/ELIZABETH | C16: 0755390895 | E16: 2500 | F16: =MAY!K18 -> 900 | G16: =D16+E16+F16 -> 3400 | H16: =3000 -> 3000 | I16: UF5C472PM6 | J16: JUNE | K16: =G16-H16 -> 400 | M16: RCTD | O16: PETER KINYANJUI
A17: 8 | B17: MICHAEL | E17: 2500 | F17: =MAY!K19 -> 500 | G17: =D17+E17+F17 -> 3000 | H17: =500+1000 -> 1500 | I17: UF6IH6V8H2/UFJ7Y86L1N | J17: JUNE | K17: =G17-H17 -> 1500
A18: 9 | B18: TENANT | E18: 2500 | F18: =MAY!K20 -> 2500 | G18: =D18+E18+F18 -> 5000 | H18: =1300+1200+1500+1000 -> 5000 | I18: UF3CI6H5D8/UF3CI6LA3J/UFLCI8OREC/UFTCI9JL0I | J18: JUNE | K18: =G18-H18 -> 0
A19: 10 | B19: JAMES OTIENO | E19: 2500 | F19: =MAY!K21 -> 3300 | G19: =D19+E19+F19 -> 5800 | H19: =2000+2000 -> 4000 | I19: UF989758EM/UFKSG283DJ | J19: JUNE | K19: =G19-H19 -> 1800 | M19: RCTD
A20: 11 | B20: ISAYA ONDUNGA | C20: 0721854507 | E20: 2200 | F20: =MAY!K22 -> 0 | G20: =D20+E20+F20 -> 2200 | H20: =2200 -> 2200 | I20: UFE6A70D2V | J20: JUNE | K20: =G20-H20 -> 0 | M20: RCTD
A21: 12 | B21: TENANT | E21: 2500 | F21: =MAY!K23 -> 0 | G21: =D21+E21+F21 -> 2500 | J21: JUNE | K21: =G21-H21 -> 2500
A22: 13 | B22: ELECTINA AKHURA | C22: 0711949488 | E22: 2500 | F22: =MAY!K24 -> 500 | G22: =D22+E22+F22 -> 3000 | J22: JUNE | K22: =G22-H22 -> 3000 | L22: 18TH
A23: 14 | B23: STEPHEN ORIAH | E23: 2500 | F23: =MAY!K25 -> 0 | G23: =D23+E23+F23 -> 2500 | H23: =2500 -> 2500 | I23: DIRECT | J23: JUNE | K23: =G23-H23 -> 0
A24: 15 | B24: TENANT | E24: 2500 | G24: =D24+E24+F24 -> 2500 | H24: 2500 | I24: DIRECT | J24: JUNE | K24: =G24-H24 -> 0 | M24: RCTD
A25: 16/5 | B25: PHILIS MUTHONI | C25: 0707135975 | E25: 3000 | F25: =MAY!K27 -> 0 | G25: =D25+E25+F25 -> 3000 | H25: =3000 -> 3000 | I25: UF9EB7FSXZ | J25: JUNE | K25: =G25-H25 -> 0 | M25: SIGNED
A26: 17 | B26: LLD | F26: =MAY!K28 -> 0 | G26: =D26+E26+F26 -> 0 | J26: JUNE | K26: =G26-H26 -> 0
A27: 18 | B27: TENANT | E27: 2500 | F27: =MAY!K29 -> 0 | G27: =D27+E27+F27 -> 2500 | H27: =2500 -> 2500 | I27: DIRECT | J27: JUNE | K27: =G27-H27 -> 0
A28: 19 | B28: STEPHEN OTIENO | C28: 0746470193 | E28: 2500 | F28: =MAY!K30 -> 0 | G28: =D28+E28+F28 -> 2500 | H28: =2000 -> 2000 | I28: DIRECT | J28: JUNE | K28: =G28-H28 -> 500 | L28: 15TH
A29: 21 | B29: MOSES NDWIGA | C29: 0708870237 | E29: 2500 | F29: =MAY!K31 -> 0 | G29: =D29+E29+F29 -> 2500 | H29: =2500 -> 2500 | I29: UFJR58686N | J29: JUNE | K29: =G29-H29 -> 0
D30: =SUM(D11:D28) -> 0 | E30: =SUM(E10:E29) -> 45200 | F30: =SUM(F10:F29) -> 11300 | G30: =SUM(G10:G29) -> 56500 | H30: =SUM(H10:H29) -> 48100 | J30: =SUM(J11:J28) -> 0 | K30: =SUM(K10:K29) -> 8400
A31: Totals
A32: Deductions
A33: Less Management fees | H33: =H30*10% -> 4810
A34: RENTAL TAX | H34: =2250 -> 2250
A35: DIRECT | H35: =H27+H24+H23+H10+900+H28 -> 12900
A36: TOTAL DEDUCTIONS | H36: =SUM(H33:H35) -> 19960
A37: BAL B/F | H37: =MAY!K40 -> 147 | I37: Cash deposited | J37: Paid | K37: Balance
A38: AMOUNT DUE | H38: =H30-H36+H37 -> 28287 | I38: 20000 | J38: =1742+6545 -> 8287 | K38: =H38-I38-J38 -> 0
A39: AUTHORISED BY JOSEPH GITHINJI | K39: 46203
H43: =H30/G30*100 -> 85.132743
I44: =6658-3980 -> 2678
...

Sheet JULY
C1: LOBBY ENTERPRISES
A2: PROPERTY MANAGERS AND ESTATE AGENTS
A3: 46234
I4: P.O.BOX 11987
I5: TEL : 0722711933/4454322
A6: KABAIKU | H6: Care taker
H7: Phone no
A9: HSE NO | B9: NAME | C9: PHONE NO | D9: DEPOSIT PAID | E9: MONTHLY RENT | F9: BAL B/D | G9: RENT DUE | H9: RENT PAID | I9: RCT NO | J9: PERIOD | K9: BALANCE | L9: STATUS | M9: FORMS
B10: LLD | F10: =JUNE!#REF! -> #REF! | G10: =D10+E10+F10 -> #REF! | J10: JULY | K10: =G10-H10 -> #REF!
B11: LLD | F11: =JUNE!#REF! -> #REF! | G11: =D11+E11+F11 -> #REF! | J11: JULY | K11: =G11-H11 -> #REF!
A12: 1 | B12: VACANT | F12: =JUNE!K10 -> 0 | G12: =D12+E12+F12 -> 0 | J12: JULY | K12: =G12-H12 -> 0 | M12: RCTD
A13: 2 | B13: NORMAN MAGWI | E13: 2500 | F13: =JUNE!K11 -> 0 | G13: =D13+E13+F13 -> 2500 | H13: =1500+1000 -> 2500 | I13: UG43MAWRWP/DIRECT | J13: JULY | K13: =G13-H13 -> 0
A14: 3 | B14: ELIJAH ONDENGO | C14: 0722245769 | E14: 2500 | F14: =JUNE!K12 -> 200 | G14: =D14+E14+F14 -> 2700 | H14: =2500 -> 2500 | I14: UGD85BAV85 | J14: JULY | K14: =G14-H14 -> 200 | M14: RCTD
A15: 4 | B15: FREDRICK OTIENO | C15: 0704917113 | E15: 2500 | F15: =JUNE!K13 -> -1500 | G15: =D15+E15+F15 -> 1000 | J15: JULY | K15: =G15-H15 -> 1000
A16: 5 | B16: PETER( KINYANJUI POLLY) | E16: 2500 | F16: =JUNE!K14 -> 0 | G16: =D16+E16+F16 -> 2500 | H16: =2500 -> 2500 | I16: UG7I8AJUHA | J16: JULY | K16: =G16-H16 -> 0 | M16: RCTD
A17: 6 | B17: JOSPHAT KINZI | E17: 2500 | F17: =JUNE!K15 -> 0 | G17: =D17+E17+F17 -> 2500 | H17: =2300+200 -> 2500 | I17: UG8DNABKAO/UGNDN030Y1 | J17: JULY | K17: =G17-H17 -> 0 | M17: RCTD
A18: 7 | B18: JOSEPH NJENGA/ELIZABETH | C18: 0755390895 | E18: 2500 | F18: =JUNE!K16 -> 400 | G18: =D18+E18+F18 -> 2900 | H18: =2500 -> 2500 | I18: UG6C4AQZ7T | J18: JULY | K18: =G18-H18 -> 400 | M18: RCTD | O18: PETER KINYANJUI
A19: 8 | B19: ALEX MBINDYO | E19: 2500 | F19: 0 | G19: =D19+E19+F19 -> 2500 | H19: =1500+1000 -> 2500 | I19: UGB7YAPBT1/UGI7YBGYUT | J19: JULY | K19: =G19-H19 -> 0
A20: 9 | B20: isaac uma | E20: 2500 | F20: =JUNE!K18 -> 0 | G20: =D20+E20+F20 -> 2500 | H20: =850+500+1150 -> 2500 | I20: UGKCI00NZZ/UGQCI0RAHI/UGOCI0JRR4 | J20: JULY | K20: =G20-H20 -> 0
A21: 10 | B21: JAMES OTIENO | E21: 2500 | F21: =JUNE!K19 -> 1800 | G21: =D21+E21+F21 -> 4300 | J21: JULY | K21: =G21-H21 -> 4300 | L21: TO EVICT | M21: RCTD
A22: 11 | B22: ISAYA ONDUNGA | C22: 0721854507 | E22: 2200 | F22: =JUNE!K20 -> 0 | G22: =D22+E22+F22 -> 2200 | H22: =2200 -> 2200 | I22: UGB6AAT266 | J22: JULY | K22: =G22-H22 -> 0 | M22: RCTD
A23: 12 | B23: JAEL MUTAKHE | E23: 2500 | F23: =JUNE!K21 -> 2500 | G23: =D23+E23+F23 -> 5000 | H23: =2000+500+2500 -> 5000 | I23: UG5I4A57UX/UG51GACYN6 | J23: JULY | K23: =G23-H23 -> 0 | L23: LOCKED
A24: 13 | B24: ELECTINA AKHURA | C24: 0711949488 | E24: 2500 | F24: =JUNE!K22 -> 3000 | G24: =D24+E24+F24 -> 5500 | H24: =4500 -> 4500 | I24: DIRECT | J24: JULY | K24: =G24-H24 -> 1000 | L24: 18TH
A25: 14 | B25: STEPHEN ORIAH | E25: 2500 | F25: =JUNE!K23 -> 0 | G25: =D25+E25+F25 -> 2500 | H25: =2500 -> 2500 | I25: UG65CADU2D | J25: JULY | K25: =G25-H25 -> 0
A26: 15 | B26: EUNICE NJOKI | C26: 0118271368 | E26: 2500 | F26: =JUNE!K24 -> 0 | G26: =D26+E26+F26 -> 2500 | H26: =2400+100 -> 2500 | I26: UGDDNAW2LR/UGEDNB38E9 | J26: JULY | K26: =G26-H26 -> 0 | M26: RCTD
A27: 16/5 | B27: PHILIS MUTHONI | C27: 0707135975 | E27: 3000 | F27: =JUNE!K25 -> 0 | G27: =D27+E27+F27 -> 3000 | H27: =3000 -> 3000 | I27: UG6EBAJQII | J27: JULY | K27: =G27-H27 -> 0 | M27: SIGNED
A28: 17 | B28: LLD | F28: =JUNE!K26 -> 0 | G28: =D28+E28+F28 -> 0 | J28: JULY | K28: =G28-H28 -> 0
A29: 18 | B29: TENANT | E29: 2500 | F29: =JUNE!K27 -> 0 | G29: =D29+E29+F29 -> 2500 | H29: 2500 | I29: DIRECT | J29: JULY | K29: =G29-H29 -> 0
A30: 19 | B30: VACANT | G30: =D30+E30+F30 -> 0 | J30: JULY | K30: =G30-H30 -> 0 | L30: 15TH
A31: 21 | B31: MOSES NDWIGA | C31: 0708870237 | E31: 2500 | F31: =JUNE!K29 -> 0 | G31: =D31+E31+F31 -> 2500 | H31: =2500 -> 2500 | I31: UGLR5BSGH6 | J31: JULY | K31: =G31-H31 -> 0
D32: =SUM(D13:D30) -> 0 | E32: =SUM(E10:E31) -> 42700 | F32: =SUM(F10:F31) -> #REF! | G32: =SUM(G10:G31) -> #REF! | H32: =SUM(H10:H31) -> 42200 | J32: =SUM(J13:J30) -> 0 | K32: =SUM(K10:K31) -> #REF!
A33: Totals
A34: Deductions
A35: Less Management fees | H35: =H32*10% -> 4220
A36: RENTAL TAX | H36: 2250
A37: DIRECT | H37: =H29+H24+1000+2500 -> 10500
A38: TOTAL DEDUCTIONS | H38: =SUM(H35:H37) -> 16970
A39: BAL B/F | H39: =JUNE!K38 -> 0 | I39: Cash deposited | J39: Paid | K39: Balance
A40: AMOUNT DUE | H40: =H32-H38+H39 -> 25230 | I40: 20000 | J40: 7480 | K40: =H40-I40-J40 -> -2250
A41: AUTHORISED BY JOSEPH GITHINJI | K41: 46234
...

Sheet AUG
C1: LOBBY ENTERPRISES
A2: PROPERTY MANAGERS AND ESTATE AGENTS
A3: 46265
I4: P.O.BOX 11987
I5: TEL : 0722711933/4454322
A6: KABAIKU | H6: Care taker
H7: Phone no
A9: HSE NO | B9: NAME | C9: PHONE NO | D9: DEPOSIT PAID | E9: MONTHLY RENT | F9: BAL B/D | G9: RENT DUE | H9: RENT PAID | I9: RCT NO | J9: PERIOD | K9: BALANCE | L9: STATUS | M9: FORMS
B10: LLD | F10: =JULY!K10 -> #REF! | G10: =D10+E10+F10 -> #REF! | J10: AUG | K10: =G10-H10 -> #REF!
B11: LLD | F11: =JULY!K11 -> #REF! | G11: =D11+E11+F11 -> #REF! | J11: AUG | K11: =G11-H11 -> #REF!
A12: 1 | B12: VACANT | F12: =JULY!K12 -> 0 | G12: =D12+E12+F12 -> 0 | J12: AUG | K12: =G12-H12 -> 0 | M12: RCTD
A13: 2 | B13: NORMAN MAGWI | E13: 2500 | F13: =JULY!K13 -> 0 | G13: =D13+E13+F13 -> 2500 | H13: =2000 -> 2000 | I13: UHI3M43V85 | J13: AUG | K13: =G13-H13 -> 500
A14: 3 | B14: ELIJAH ONDENGO | C14: 0722245769 | E14: 2500 | F14: =JULY!K14 -> 200 | G14: =D14+E14+F14 -> 2700 | J14: AUG | K14: =G14-H14 -> 2700 | L14: LOCKED | M14: RCTD
A15: 4 | B15: FREDRICK OTIENO | C15: 0704917113 | E15: 2500 | F15: =JULY!K15 -> 1000 | G15: =D15+E15+F15 -> 3500 | H15: =3000 -> 3000 | I15: UH67M2A9U7 | J15: AUG | K15: =G15-H15 -> 500
A16: 5 | B16: PETER( KINYANJUI POLLY) | E16: 2500 | F16: =JULY!K16 -> 0 | G16: =D16+E16+F16 -> 2500 | H16: =2500 -> 2500 | I16: UHBI82LEQK | J16: AUG | K16: =G16-H16 -> 0 | M16: RCTD
A17: 6 | B17: JOSPHAT KINZI | E17: 2500 | F17: =JULY!K17 -> 0 | G17: =D17+E17+F17 -> 2500 | H17: =2500 -> 2500 | I17: DIRECT | J17: AUG | K17: =G17-H17 -> 0 | M17: RCTD
A18: 7 | B18: JOSEPH NJENGA/ELIZABETH | C18: 0755390895 | E18: 2500 | F18: =JULY!K18 -> 400 | G18: =D18+E18+F18 -> 2900 | H18: =2500 -> 2500 | I18: UHE7E2Q3QJ | J18: AUG | K18: =G18-H18 -> 400 | M18: RCTD | O18: PETER KINYANJUI
A19: 8 | B19: ALEX MBINDYO | E19: 2500 | F19: =JULY!K19 -> 0 | G19: =D19+E19+F19 -> 2500 | H19: =2500 -> 2500 | I19: UHF7Y2QJKV | J19: AUG | K19: =G19-H19 -> 0
A20: 9 | B20: ISAAC JUMA | D20: 1000 | E20: 2500 | F20: =JULY!K20 -> 0 | G20: =D20+E20+F20 -> 3500 | H20: =1000 -> 1000 | I20: UHNCI40P1N | J20: AUG | K20: =G20-H20 -> 2500 | L20: LOCKED
A21: 10 | B21: VACANT | G21: =D21+E21+F21 -> 0 | J21: AUG | K21: =G21-H21 -> 0 | M21: RCTD
A22: 11 | B22: ISAYA ONDUNGA | C22: 0721854507 | E22: 2200 | F22: =JULY!K22 -> 0 | G22: =D22+E22+F22 -> 2200 | H22: =2200 -> 2200 | I22: UHE6A2O69T | J22: AUG | K22: =G22-H22 -> 0 | M22: RCTD
A23: 12 | B23: JAEL MUTAKHE | E23: 2500 | F23: =JULY!K23 -> 0 | G23: =D23+E23+F23 -> 2500 | H23: =2500 -> 2500 | I23: DIRECT | J23: AUG | K23: =G23-H23 -> 0
A24: 13 | B24: ELECTINA AKHURA | C24: 0711949488 | E24: 2500 | F24: =JULY!K24 -> 1000 | G24: =D24+E24+F24 -> 3500 | H24: =1000 -> 1000 | I24: UHCP121ELN | J24: AUG | K24: =G24-H24 -> 2500 | L24: LOCKED
A25: 14 | B25: STEPHEN ORIAH | E25: 2500 | F25: =JULY!K25 -> 0 | G25: =D25+E25+F25 -> 2500 | H25: =500+2000 -> 2500 | I25: UHHG5C33YNP/UHHE5C2VEOK | J25: AUG | K25: =G25-H25 -> 0
A26: 15 | B26: EUNICE NJOKI | C26: 0118271368 | E26: 2500 | F26: =JULY!K26 -> 0 | G26: =D26+E26+F26 -> 2500 | H26: =2500 -> 2500 | I26: UH8DN1WPCX | J26: AUG | K26: =G26-H26 -> 0 | M26: RCTD
A27: 16/5 | B27: PHILIS MUTHONI | C27: 0707135975 | E27: 3000 | F27: =JULY!K27 -> 0 | G27: =D27+E27+F27 -> 3000 | H27: =3000 -> 3000 | I27: UH8EB2H06M | J27: AUG | K27: =G27-H27 -> 0 | M27: SIGNED
A28: 17 | B28: LLD | F28: =JULY!K28 -> 0 | G28: =D28+E28+F28 -> 0 | J28: AUG | K28: =G28-H28 -> 0
A29: 18 | B29: TENANT | E29: 2500 | F29: =JULY!K29 -> 0 | G29: =D29+E29+F29 -> 2500 | H29: =2500 -> 2500 | I29: DIRECT | J29: AUG | K29: =G29-H29 -> 0
A30: 19 | B30: VACANT | F30: =JULY!K30 -> 0 | G30: =D30+E30+F30 -> 0 | J30: AUG | K30: =G30-H30 -> 0
A31: 21 | B31: MOSES NDWIGA | C31: 0708870237 | E31: 2500 | F31: =JULY!K31 -> 0 | G31: =D31+E31+F31 -> 2500 | J31: AUG | K31: =G31-H31 -> 2500 | L31: LOCKED
D32: =SUM(D13:D30) -> 1000 | E32: =SUM(E10:E31) -> 40200 | F32: =SUM(F10:F31) -> #REF! | G32: =SUM(G10:G31) -> #REF! | H32: =SUM(H10:H31) -> 32200 | J32: =SUM(J13:J30) -> 0 | K32: =SUM(K10:K31) -> #REF!
A33: Totals
A34: Deductions
A35: Less Management fees | H35: =H32*10% -> 3220
A36: RENTAL TAX | H36: =2250 -> 2250
A37: DIRECT | H37: =H17+H29+H23 -> 7500
A38: TOTAL DEDUCTIONS | H38: =SUM(H35:H37) -> 12970
A39: BAL B/F | H39: =JULY!K40 -> -2250 | I39: Cash deposited | J39: Paid | K39: Balance
A40: AMOUNT DUE | H40: =H32-H38+H39 -> 16980 | I40: 20000 | K40: =H40-I40-J40 -> -3020
A41: AUTHORISED BY JOSEPH GITHINJI | K41: 46265
...

Sheet SEP
C1: LOBBY ENTERPRISES
A2: PROPERTY MANAGERS AND ESTATE AGENTS
A3: 46295
I4: P.O.BOX 11987
I5: TEL : 0722711933/4454322
A6: KABAIKU | H6: Care taker
H7: Phone no
A9: HSE NO | B9: NAME | C9: PHONE NO | D9: DEPOSIT PAID | E9: MONTHLY RENT | F9: BAL B/D | G9: RENT DUE | H9: RENT PAID | I9: RCT NO | J9: PERIOD | K9: BALANCE | L9: STATUS | M9: FORMS
B10: LLD | F10: =AUG!K10 -> #REF! | G10: =D10+E10+F10 -> #REF! | J10: SEP | K10: =G10-H10 -> #REF!
B11: LLD | F11: =AUG!K11 -> #REF! | G11: =D11+E11+F11 -> #REF! | J11: SEP | K11: =G11-H11 -> #REF!
A12: 1 | B12: VACANT | F12: =AUG!K12 -> 0 | G12: =D12+E12+F12 -> 0 | J12: SEP | K12: =G12-H12 -> 0
A13: 2 | B13: NORMAN MAGWI | C13: 0715604050 | E13: 2500 | F13: =AUG!K13 -> 500 | G13: =D13+E13+F13 -> 3000 | H13: =2000 -> 2000 | I13: UID3M78VXR | J13: SEP | K13: =G13-H13 -> 1000
A14: 3 | B14: ELIJAH ONDENGO | C14: 0722245769 | E14: 2500 | F14: =AUG!K14 -> 2700 | G14: =D14+E14+F14 -> 5200 | H14: =1500+1000+1500 -> 4000 | I14: UHL853V9PT/UIB856H1W4/UIO8581H5H | J14: SEP | K14: =G14-H14 -> 1200
A15: 4 | B15: FREDRICK OTIENO | C15: 0704917113 | E15: 2500 | F15: =AUG!K15 -> 500 | G15: =D15+E15+F15 -> 3000 | H15: =2700 -> 2700 | I15: UIA7M6AKKD | J15: SEP | K15: =G15-H15 -> 300
A16: 5 | B16: PETER( KINYANJUI POLLY) | C16: 0741868972 | E16: 2500 | F16: =AUG!K16 -> 0 | G16: =D16+E16+F16 -> 2500 | H16: =2500 -> 2500 | I16: UIDI86H456 | J16: SEP | K16: =G16-H16 -> 0
A17: 6 | B17: JOSPHAT KINZI | E17: 2500 | F17: =AUG!K17 -> 0 | G17: =D17+E17+F17 -> 2500 | H17: =1000+1500 -> 2500 | I17: UI84H6QQRC2/UIC4H6VNSY | J17: SEP | K17: =G17-H17 -> 0
A18: 7 | B18: JOSEPH NJENGA/ELIZABETH | C18: 0755390895 | E18: 2500 | F18: =AUG!K18 -> 400 | G18: =D18+E18+F18 -> 2900 | H18: =2500 -> 2500 | I18: UI6C460KAN | J18: SEP | K18: =G18-H18 -> 400 | O18: PETER KINYANJUI
A19: 8 | B19: ALEX MBINDYO | C19: 0721300663 | E19: 2500 | F19: =AUG!K19 -> 0 | G19: =D19+E19+F19 -> 2500 | H19: =1000+1000+500 -> 2500 | I19: UIB7Y55NBQ/UIC7Y6O844/UI7Y657MR | J19: SEP | K19: =G19-H19 -> 0
A20: 9 | B20: ISAAC JUMA | C20: 0721112662 | E20: 2500 | F20: =AUG!K20 -> 2500 | G20: =D20+E20+F20 -> 5000 | H20: =2500+2500 -> 5000 | I20: DIRECT/UICCI6F3G0 | J20: SEP | K20: =G20-H20 -> 0
A21: 10 | B21: JAMES OCHIENG | D21: 1000 | F21: =AUG!K21 -> 0 | G21: =D21+E21+F21 -> 1000 | H21: =300+700 -> 1000 | I21: UIJBT717ZB/UIJBT711HK | J21: SEP | K21: =G21-H21 -> 0
A22: 11 | B22: ISAYA ONDUNGA | C22: 0721854507 | E22: 2200 | F22: =AUG!K22 -> 0 | G22: =D22+E22+F22 -> 2200 | H22: =2200 -> 2200 | I22: UIF6A6G2M8 | J22: SEP | K22: =G22-H22 -> 0
A23: 12 | B23: JAEL MUTAKHE | C23: 0119652370 | E23: 2500 | F23: =AUG!K23 -> 0 | G23: =D23+E23+F23 -> 2500 | H23: =2500 -> 2500 | I23: DIRECT | J23: SEP | K23: =G23-H23 -> 0
A24: 13 | B24: ELECTINA AKHURA | C24: 073903831 | E24: 2500 | F24: =AUG!K24 -> 2500 | G24: =D24+E24+F24 -> 5000 | H24: =2500 -> 2500 | I24: UI4P159BSP | J24: SEP | K24: =G24-H24 -> 2500
A25: 14 | B25: STEPHEN ORIAH | C25: 0736048010 | E25: 2500 | F25: =AUG!K25 -> 0 | G25: =D25+E25+F25 -> 2500 | H25: 7500 | I25: DIRECT | J25: SEP | K25: =G25-H25 -> -5000
A26: 15 | B26: EUNICE NJOKI | C26: 0118271368 | E26: 2500 | F26: =AUG!K26 -> 0 | G26: =D26+E26+F26 -> 2500 | H26: =3500 -> 3500 | I26: UILDN749TU | J26: SEP | K26: =G26-H26 -> -1000
A27: 16/5 | B27: PHILIS MUTHONI | C27: 0707135975 | E27: 3000 | F27: =AUG!K27 -> 0 | G27: =D27+E27+F27 -> 3000 | H27: =3000 -> 3000 | I27: UI8EB625ER | J27: SEP | K27: =G27-H27 -> 0
A28: 17 | B28: LLD | F28: =AUG!K28 -> 0 | G28: =D28+E28+F28 -> 0 | J28: SEP | K28: =G28-H28 -> 0
A29: 18 | B29: EVANS NDEGE | C29: 0715030807 | E29: 2500 | F29: =AUG!K29 -> 0 | G29: =D29+E29+F29 -> 2500 | H29: =2500 -> 2500 | I29: DIRECT | J29: SEP | K29: =G29-H29 -> 0
A30: 19 | B30: ZACHARY ODERO | C30: 0796494141 | F30: =AUG!K30 -> 0 | G30: =D30+E30+F30 -> 0 | H30: =2500 -> 2500 | I30: UIQI188E3R | J30: SEP | K30: =G30-H30 -> -2500 | L30: OCT BOOKING
A31: 21 | B31: MOSES NDWIGA | C31: 0708870237 | E31: 2500 | F31: =AUG!K31 -> 2500 | G31: =D31+E31+F31 -> 5000 | H31: =2500 -> 2500 | I31: UIER5674B5 | J31: SEP | K31: =G31-H31 -> 2500
D32: =SUM(D13:D30) -> 1000 | E32: =SUM(E10:E31) -> 40200 | F32: =SUM(F10:F31) -> #REF! | G32: =SUM(G10:G31) -> #REF! | H32: =SUM(H10:H31) -> 53400 | J32: =SUM(J13:J30) -> 0 | K32: =SUM(K10:K31) -> #REF!
A33: Totals
A34: Deductions
A35: Less Management fees | H35: =H32*10% -> 5340
A36: RENTAL TAX | H36: =2250 -> 2250
A37: DIRECT | H37: =H29+H23+2500+H25 -> 15000
A38: TOTAL DEDUCTIONS | H38: =SUM(H35:H37) -> 22590
A39: BAL B/F | H39: =AUG!K40 -> -3020 | I39: Cash deposited | J39: Paid | K39: Balance
A40: AMOUNT DUE | H40: =H32-H38+H39 -> 27790 | I40: 20000 | K40: =H40-I40-J40 -> 7790
A41: AUTHORISED BY JOSEPH GITHINJI | K41: 46295
...

Sheet OCT
C1: LOBBY ENTERPRISES
A2: PROPERTY MANAGERS AND ESTATE AGENTS
A3: 46326
I4: P.O.BOX 11987
I5: TEL : 0722711933/4454322
A6: KABAIKU | H6: Care taker
H7: Phone no
A9: HSE NO | B9: NAME | C9: PHONE NO | D9: DEPOSIT PAID | E9: MONTHLY RENT | F9: BAL B/D | G9: RENT DUE | H9: RENT PAID | I9: RCT NO | J9: PERIOD | K9: BALANCE | L9: STATUS | M9: FORMS
B10: LLD | F10: =SEP!K10 -> #REF! | G10: =D10+E10+F10 -> #REF! | J10: OCT | K10: =G10-H10 -> #REF!
B11: LLD | F11: =SEP!K11 -> #REF! | G11: =D11+E11+F11 -> #REF! | J11: OCT | K11: =G11-H11 -> #REF!
A12: 1 | B12: VACANT | F12: =SEP!K12 -> 0 | G12: =D12+E12+F12 -> 0 | J12: OCT | K12: =G12-H12 -> 0
A13: 2 | B13: NORMAN MAGWI | C13: 0715604050 | E13: 2500 | F13: =SEP!K13 -> 1000 | G13: =D13+E13+F13 -> 3500 | J13: OCT | K13: =G13-H13 -> 3500
A14: 3 | B14: ELIJAH ONDENGO | C14: 0722245769 | E14: 2500 | F14: =SEP!K14 -> 1200 | G14: =D14+E14+F14 -> 3700 | J14: OCT | K14: =G14-H14 -> 3700
A15: 4 | B15: FREDRICK OTIENO | C15: 0704917113 | E15: 2500 | F15: =SEP!K15 -> 300 | G15: =D15+E15+F15 -> 2800 | J15: OCT | K15: =G15-H15 -> 2800
A16: 5 | B16: PETER( KINYANJUI POLLY) | C16: 0741868972 | E16: 2500 | F16: =SEP!K16 -> 0 | G16: =D16+E16+F16 -> 2500 | J16: OCT | K16: =G16-H16 -> 2500
A17: 6 | B17: JOSPHAT KINZI | E17: 2500 | F17: =SEP!K17 -> 0 | G17: =D17+E17+F17 -> 2500 | J17: OCT | K17: =G17-H17 -> 2500
A18: 7 | B18: JOSEPH NJENGA/ELIZABETH | C18: 0755390895 | E18: 2500 | F18: =SEP!K18 -> 400 | G18: =D18+E18+F18 -> 2900 | J18: OCT | K18: =G18-H18 -> 2900 | O18: PETER KINYANJUI
A19: 8 | B19: ALEX MBINDYO | C19: 0721300663 | E19: 2500 | F19: =SEP!K19 -> 0 | G19: =D19+E19+F19 -> 2500 | J19: OCT | K19: =G19-H19 -> 2500
A20: 9 | B20: ISAAC JUMA | C20: 0721112662 | E20: 2500 | F20: =SEP!K20 -> 0 | G20: =D20+E20+F20 -> 2500 | J20: OCT | K20: =G20-H20 -> 2500
A21: 10 | B21: JAMES OCHIENG | E21: 2500 | F21: =SEP!K21 -> 0 | G21: =D21+E21+F21 -> 2500 | J21: OCT | K21: =G21-H21 -> 2500
A22: 11 | B22: ISAYA ONDUNGA | C22: 0721854507 | E22: 2200 | F22: =SEP!K22 -> 0 | G22: =D22+E22+F22 -> 2200 | J22: OCT | K22: =G22-H22 -> 2200
A23: 12 | B23: JAEL MUTAKHE | C23: 0119652370 | E23: 2500 | F23: =SEP!K23 -> 0 | G23: =D23+E23+F23 -> 2500 | J23: OCT | K23: =G23-H23 -> 2500
A24: 13 | B24: ELECTINA AKHURA | C24: 073903831 | E24: 2500 | F24: =SEP!K24 -> 2500 | G24: =D24+E24+F24 -> 5000 | J24: OCT | K24: =G24-H24 -> 5000
A25: 14 | B25: STEPHEN ORIAH | C25: 0736048010 | E25: 2500 | F25: =SEP!K25 -> -5000 | G25: =D25+E25+F25 -> -2500 | J25: OCT | K25: =G25-H25 -> -2500
A26: 15 | B26: EUNICE NJOKI | C26: 0118271368 | E26: 2500 | F26: =SEP!K26 -> -1000 | G26: =D26+E26+F26 -> 1500 | J26: OCT | K26: =G26-H26 -> 1500
A27: 16/5 | B27: PHILIS MUTHONI | C27: 0707135975 | E27: 3000 | F27: =SEP!K27 -> 0 | G27: =D27+E27+F27 -> 3000 | J27: OCT | K27: =G27-H27 -> 3000
A28: 17 | B28: LLD | F28: =SEP!K28 -> 0 | G28: =D28+E28+F28 -> 0 | J28: OCT | K28: =G28-H28 -> 0
A29: 18 | B29: EVANS NDEGE | C29: 0715030807 | E29: 2500 | F29: =SEP!K29 -> 0 | G29: =D29+E29+F29 -> 2500 | J29: OCT | K29: =G29-H29 -> 2500
A30: 19 | B30: ZACHARY ODERO | C30: 0796494141 | E30: 2500 | F30: =SEP!K30 -> -2500 | G30: =D30+E30+F30 -> 0 | J30: OCT | K30: =G30-H30 -> 0
A31: 21 | B31: MOSES NDWIGA | C31: 0708870237 | E31: 2500 | F31: =SEP!K31 -> 2500 | G31: =D31+E31+F31 -> 5000 | J31: OCT | K31: =G31-H31 -> 5000
D32: =SUM(D13:D30) -> 0 | E32: =SUM(E10:E31) -> 45200 | F32: =SUM(F10:F31) -> #REF! | G32: =SUM(G10:G31) -> #REF! | H32: =SUM(H10:H31) -> 0 | J32: =SUM(J13:J30) -> 0 | K32: =SUM(K10:K31) -> #REF!
A33: Totals
A34: Deductions
A35: Less Management fees | H35: =H32*10% -> 0
A36: RENTAL TAX
A37: DIRECT
A38: TOTAL DEDUCTIONS | H38: =SUM(H35:H37) -> 0
A39: BAL B/F | H39: =SEP!K40 -> 7790 | I39: Cash deposited | J39: Paid | K39: Balance
A40: AMOUNT DUE | H40: =H32-H38+H39 -> 7790 | K40: =H40-I40-J40 -> 7790
A41: AUTHORISED BY JOSEPH GITHINJI | K41: 46326
...
