Workbook

Sheet FEB
C1: LOBBY ENTERPRISES
A2: PROPERTY MANAGERS AND ESTATE AGENTS
A3: FEB 2026
B4: RIVUNIA | K4: P.O.BOX 11987
K5: TEL : 0722711933/0712949022
A6: PAYBILL | J6: Care taker
A7: AC NO | J7: Phone no
O8: BALANCE BREAKDOWN
A9: HSE NO | B9: NAME | C9: PHONE NO | D9: DEPOSIT PAID | E9: MONTHLY RENT | F9: WATER BILL | G9: GARBAGE | H9: BAL B/D | I9: RENT DUE | J9: RENT PAID | K9: RCT NO | L9: PAYMENT DATE | M9: PERIOD | N9: BALANCE | O9: WATER BILL | P9: RENT ARREAS | Q9: STATUS | R9: FORMS
A10: G1 | B10: CARETAKER | C10: 0721131902 | I10: =D10+E10+F10+G10+H10 -> 0 | M10: FEB | N10: =I10-J10 -> 0
A11: G2 | B11: KEVIN ESSAU | C11: 0705152448 | E11: 11000 | F11: 450 | G11: 300 | H11: 0 | I11: =D11+E11+F11+G11+H11 -> 11750 | J11: =11450 -> 11450 | K11: UBMI5JUJS | M11: FEB | N11: =I11-J11 -> 300
A12: G3 | B12: STANLEY MUTHOKA | C12: 0726696925 | E12: 21000 | F12: 750 | G12: 300 | H12: =44100+22050 -> 66150 | I12: =D12+E12+F12+G12+H12 -> 88200 | J12: =21900+22050 -> 43950 | K12: TD293D90SB/UBP8N7PDVY | M12: FEB | N12: =I12-J12 -> 44250 | Q12: 10TH
A13: A1 | B13: YUSUF GICHANA | C13: 0724604589 | E13: 22000 | F13: 150 | G13: 300 | H13: 0 | I13: =D13+E13+F13+G13+H13 -> 22450 | J13: =22150+300 -> 22450 | K13: UB46V5OWF6 /UB56V5Q0LN | M13: FEB | N13: =I13-J13 -> 0 | R13: SIGNED
A14: A2 | B14: ANNE MAHERO | C14: 0732891525 | E14: 20000 | F14: 450 | G14: 300 | H14: 0 | I14: =D14+E14+F14+G14+H14 -> 20750 | J14: =20750 -> 20750 | K14: UB5JA5U84X | M14: FEB | N14: =I14-J14 -> 0
A15: A3 | B15: VACANT | I15: =D15+E15+F15+G15+H15 -> 0 | M15: FEB | N15: =I15-J15 -> 0 | O15: WANTS DEPOSIT
A16: A4 | B16: NELSON MUIA | C16: 0722750497 | E16: 21000 | F16: 150 | G16: 300 | H16: 0 | I16: =D16+E16+F16+G16+H16 -> 21450 | J16: 22000 | K16: UB8NF63MI5 | M16: FEB | N16: =I16-J16 -> -550
A17: A5 | B17: CLARE NYAERA BOSIRE | C17: 0759158949 | D17: 21000 | E17: 21000 | G17: 300 | H17: 0 | I17: =D17+E17+F17+G17+H17 -> 42300 | J17: =21000+21000 -> 42000 | K17: UB3GQ5MIDS /UBCGQ6FMNE | M17: FEB | N17: =I17-J17 -> 300
A18: A6 | B18: SWEENEY WANGUI | C18: 0745529428 | E18: 12000 | F18: 450 | G18: 300 | H18: 12600 | I18: =D18+E18+F18+G18+H18 -> 25350 | J18: 24000 | K18: UB83L6I8P4 | M18: FEB | N18: =I18-J18 -> 1350
A19: A7 | B19: HILLARY YALLAH | C19: 0705682987 | E19: 20000 | F19: 450 | G19: 300 | H19: 0 | I19: =D19+E19+F19+G19+H19 -> 20750 | J19: =6000+15000 -> 21000 | K19: UBC1Q6SPQH/UBL1Q7NR4T | M19: FEB | N19: =I19-J19 -> -250 | Q19: SATO
A20: A8 | B20: EFFIE REINEE | C20: 0728224646 | E20: 20000 | F20: 450 | G20: 300 | H20: 20600 | I20: =D20+E20+F20+G20+H20 -> 41350 | J20: =20600+20300 -> 40900 | K20: DIRECT/UBBFX6IC5Y | M20: FEB | N20: =I20-J20 -> 450
A21: B1 | B21: IAN WANDA | C21: 0702837845 | E21: 20000 | F21: 300 | G21: 300 | H21: 0 | I21: =D21+E21+F21+G21+H21 -> 20600 | J21: 22300 | K21: UB9EP669B9 | M21: FEB | N21: =I21-J21 -> -1700 | Q21: 10TH
A22: B2 | B22: RAHIM YUSUF HAFIZ | C22: 0112321416 | E22: 20000 | F22: 150 | G22: 300 | H22: 10600 | I22: =D22+E22+F22+G22+H22 -> 31050 | J22: =6000+20450+500 -> 26950 | K22: DIRECT/UB56N5PPG6 /UB56N5OSIS | M22: FEB | N22: =I22-J22 -> 4100 | Q22: 24TH
A23: B3 | B23: SARAH KABIRU | C23: 0726491785 | E23: 21000 | F23: 600 | G23: 300 | H23: 0 | I23: =D23+E23+F23+G23+H23 -> 21900 | J23: =21600 -> 21600 | K23: UB7EP61QTL | M23: FEB | N23: =I23-J23 -> 300
A24: B4 | B24: DOMITILIA WANJIKU | C24: 0798059118 | E24: 21000 | F24: 450 | G24: 300 | H24: 0 | I24: =D24+E24+F24+G24+H24 -> 21750 | J24: =21750 -> 21750 | K24: UB42B5ULMV | M24: FEB | N24: =I24-J24 -> 0
A25: B5 | B25: KEVIN GITAU | C25: 0720548574 | E25: 21000 | F25: 0 | G25: 300 | H25: 81200 | I25: =D25+E25+F25+G25+H25 -> 102500 | J25: =69600+5000 -> 74600 | K25: DIRECT/UBLHM78AH3 | M25: FEB | N25: =I25-J25 -> 27900 | Q25: FRIDAY
A26: B6 | B26: OFFICE | H26: 0 | I26: =D26+E26+F26+G26+H26 -> 0 | M26: FEB | N26: =I26-J26 -> 0
A27: B7 | B27: NESH | C27: 0719728717 | E27: 21000 | F27: 150 | G27: 300 | H27: 114100 | I27: =D27+E27+F27+G27+H27 -> 135550 | K27: LEFT | M27: FEB | N27: =I27-J27 -> 135550 | Q27: LOCKED | R27: LEFT
A28: B8 | B28: DENNIS MBOYA | C28: 0726689860 | E28: 21000 | F28: 1500 | G28: 300 | H28: 0 | I28: =D28+E28+F28+G28+H28 -> 22800 | J28: =22500+300 -> 22800 | K28: UB5G35OPDV/UB5G35OUNN | M28: FEB | N28: =I28-J28 -> 0 | R28: SIGNED | T28: A7 D2 B7 E1 C1 C2
A29: C1 | B29: STACY WANGECHI | C29: 0728444472 | E29: 22000 | F29: 150 | G29: 300 | H29: 0 | I29: =D29+E29+F29+G29+H29 -> 22450 | J29: =22600 -> 22600 | K29: UBCOD6KI05 | L29: 12TH FEB | M29: FEB | N29: =I29-J29 -> -150
A30: C2 | B30: FRANCIS KAMAU | C30: 0724960681 | E30: 20000 | F30: 600 | G30: 300 | H30: 0 | I30: =D30+E30+F30+G30+H30 -> 20900 | J30: =21000 -> 21000 | K30: UB6QC5W8SC | M30: FEB | N30: =I30-J30 -> -100
A31: C3 | B31: JACINTA | C31: 0735765230 | E31: 20000 | F31: 1050 | G31: 300 | H31: 0 | I31: =D31+E31+F31+G31+H31 -> 21350 | J31: =21050+300 -> 21350 | K31: UB4I05NLU7/UB5I05T1L5 | M31: FEB | N31: =I31-J31 -> 0
A32: C4 | B32: CATHERINE MWENDE | C32: 0714216677 | E32: 21000 | F32: 300 | G32: 300 | H32: 43200 | I32: =D32+E32+F32+G32+H32 -> 64800 | J32: =43200+21600 -> 64800 | K32: DIRECT/UB52U5Y3GM | M32: FEB | N32: =I32-J32 -> 0
A33: C5 | B33: ALEX OMANGA | C33: 0713579337 | E33: 20000 | F33: 1800 | G33: 300 | H33: 0 | I33: =D33+E33+F33+G33+H33 -> 22100 | J33: 22100 | K33: UB5NL5YPVP | M33: FEB | N33: =I33-J33 -> 0
A34: C6 | B34: NATASHA KAMARI | C34: 0769308005 | E34: 12000 | F34: 600 | G34: 300 | H34: 0 | I34: =D34+E34+F34+G34+H34 -> 12900 | J34: =6000+6900 -> 12900 | K34: UBDEV6LJGZ/UBOEV7LV27 | M34: FEB | N34: =I34-J34 -> 0 | Q34: WED
A35: C7 | B35: CALVIN OUMA | C35: 0717038580 | E35: 20000 | F35: 300 | G35: 300 | H35: 0 | I35: =D35+E35+F35+G35+H35 -> 20600 | J35: =20600 -> 20600 | K35: UB4G65MNG3 | M35: FEB | N35: =I35-J35 -> 0
A36: C8 | B36: TITUS MUTHARIA | C36: 0721211242 | E36: 20000 | F36: 150 | G36: 300 | H36: 0 | I36: =D36+E36+F36+G36+H36 -> 20450 | J36: 20450 | K36: UB4GX5M2W2 | M36: FEB | N36: =I36-J36 -> 0 | R36: SIGNED
A37: D1 | B37: CONTANA ERICK | C37: 0724567912 | E37: 22000 | F37: 900 | G37: 300 | H37: 0 | I37: =D37+E37+F37+G37+H37 -> 23200 | J37: =23200 -> 23200 | K37: UB46V5OWF6 | M37: FEB | N37: =I37-J37 -> 0 | R37: SIGNED
A38: D2 | B38: REDEMPTA | C38: 0758251456 | E38: 21000 | F38: 450 | G38: 300 | H38: 42800 | I38: =D38+E38+F38+G38+H38 -> 64550 | J38: =30000+20300+450+18000 -> 68750 | K38: TJTAY80R37/UBDAY6JAJS/UBDAY6JH4K/UBOAY710GP | M38: FEB | N38: =I38-J38 -> -4200
A39: D3 | B39: GITURU SAMSON | C39: 0717152296 | E39: 21000 | F39: 300 | G39: 300 | H39: 0 | I39: =D39+E39+F39+G39+H39 -> 21600 | J39: 21300 | K39: UB6BO5ZRS9 | M39: FEB | N39: =I39-J39 -> 300
A40: D4 | B40: IRENE NASHIPEI | C40: 0719361901 | E40: 20000 | F40: 1050 | G40: 300 | H40: 0 | I40: =D40+E40+F40+G40+H40 -> 21350 | J40: 21050 | K40: UB5FS5VTXW | M40: FEB | N40: =I40-J40 -> 300
...

Sheet MARCH
C1: LOBBY ENTERPRISES
A2: PROPERTY MANAGERS AND ESTATE AGENTS
A3: FEB 2026
B4: RIVUNIA | K4: P.O.BOX 11987
K5: TEL : 0722711933/0712949022
A6: PAYBILL | J6: Care taker
A7: AC NO | J7: Phone no
O8: BALANCE BREAKDOWN
A9: HSE NO | B9: NAME | C9: PHONE NO | D9: DEPOSIT PAID | E9: MONTHLY RENT | F9: WATER BILL | G9: GARBAGE | H9: BAL B/D | I9: RENT DUE | J9: RENT PAID | K9: RCT NO | L9: DATES | M9: PERIOD | N9: BALANCE | O9: WATER BILL | P9: RENT ARREAS | Q9: STATUS | R9: FORMS
A10: G2 | B10: KEVIN ESSAU | C10: 0705152448 | E10: 11000 | F10: 450 | G10: 300 | H10: =FEB!N11 -> 300 | I10: =D10+E10+F10+G10+H10 -> 12050 | J10: 12050 | K10: UC2MI7Z4NW | L10: 2ND MARCH | N10: =I10-J10 -> 0 | R10: SIGNED
A11: G3 | B11: STANLEY MUTHOKA | C11: 0726696925 | E11: 21000 | F11: 750 | G11: 300 | H11: =FEB!N12 -> 44250 | I11: =D11+E11+F11+G11+H11 -> 66300 | J11: =22050 -> 22050 | K11: UCB8N90U9K | L11: 11TH MARCH | N11: =I11-J11 -> 44250 | Q11: 10TH
A12: A1 | B12: YUSUF GICHANA | C12: 0724604589 | E12: 22000 | F12: 150 | G12: 300 | H12: =FEB!N13 -> 0 | I12: =D12+E12+F12+G12+H12 -> 22450 | J12: =22450 -> 22450 | K12: UC46V890SU | L12: 4TH MARCH | N12: =I12-J12 -> 0 | R12: SIGNED
A13: A2 | B13: ANNE MAHERO | C13: 0732891525 | E13: 20000 | F13: 300 | G13: 300 | H13: =FEB!N14 -> 0 | I13: =D13+E13+F13+G13+H13 -> 20600 | J13: =20600 -> 20600 | K13: UC5JA8ITZ6 | L13: 5TH MARCH | N13: =I13-J13 -> 0 | R13: SIGNED
A14: A3 | B14: JANE ACHIENG | C14: 0787049221 | D14: 22700 | E14: 21000 | F14: 0 | G14: 300 | H14: =FEB!N15 -> 0 | I14: =D14+E14+F14+G14+H14 -> 44000 | J14: =30000+14000+21000 -> 65000 | K14: UBOF37R8UV /UC9F3900GV /UCPF3AMHDG | L14: 9TH /26TH MARCH | N14: =I14-J14 -> -21000
A15: A4 | B15: NELSON MUIA | C15: 0722750497 | E15: 21000 | F15: 450 | G15: 300 | H15: =FEB!N16 -> -550 | I15: =D15+E15+F15+G15+H15 -> 21200 | J15: =22500 -> 22500 | K15: UCANF8UMPL | L15: 10TH MARCH | N15: =I15-J15 -> -1300 | R15: SIGNED
A16: A5 | B16: CLARE NYAERA BOSIRE | C16: 0759158949 | E16: 21000 | F16: 450 | G16: 300 | H16: =FEB!N17 -> 300 | I16: =D16+E16+F16+G16+H16 -> 22050 | J16: =22050 -> 22050 | K16: UC4GQ8DEBN | L16: 5TH MARCH | N16: =I16-J16 -> 0
A17: A6 | B17: SWEENEY WANGUI | C17: 0745529428 | E17: 12000 | F17: 150 | G17: 300 | H17: =FEB!N18 -> 1350 | I17: =D17+E17+F17+G17+H17 -> 13800 | J17: =12500+1350 -> 13850 | K17: UC53L8YMJU /UCQ3LB4AY3 | L17: 8TH MARCH | N17: =I17-J17 -> -50
A18: A7 | B18: HILLARY YALLAH | C18: 0705682987 | E18: 20000 | F18: 300 | G18: 300 | H18: =FEB!N19 -> -250 | I18: =D18+E18+F18+G18+H18 -> 20350 | J18: =18000+3000+21000 -> 42000 | K18: UC91Q93EBN/UCO11QAO66E/UCO1QAOLXJ | N18: =I18-J18 -> -21650 | Q18: SATO | R18: SIGNED
A19: A8 | B19: EFFIE REINEE | C19: 0728224646 | E19: 20000 | F19: 150 | G19: 300 | H19: =FEB!N20 -> 450 | I19: =D19+E19+F19+G19+H19 -> 20900 | J19: =20000+450 -> 20450 | K19: UC1FX87ACL/UB4FX5UEG4 | L19: 4TH FEB/2ND MARCH | N19: =I19-J19 -> 450
A20: B1 | B20: IAN WANDA | C20: 0702837845 | E20: 20000 | F20: 210 | G20: 300 | H20: =FEB!N21 -> -1700 | I20: =D20+E20+F20+G20+H20 -> 18810 | J20: =22510 -> 22510 | K20: UC4EP8BT0N | L20: 4TH MARCH | N20: =I20-J20 -> -3700 | Q20: 10TH
A21: B2 | B21: RAHIM YUSUF HAFIZ | C21: 0112321416 | E21: 20000 | F21: 0 | G21: 300 | H21: =FEB!N22 -> 4100 | I21: =D21+E21+F21+G21+H21 -> 24400 | J21: =21300 -> 21300 | K21: UC1DI84LT5 | L21: 1ST MARCH | N21: =I21-J21 -> 3100 | O21: REDUCING | Q21: 24TH
A22: B3 | B22: SARAH KABIRU | C22: 0726491785 | E22: 21000 | F22: 600 | G22: 300 | H22: =FEB!N23 -> 300 | I22: =D22+E22+F22+G22+H22 -> 22200 | J22: =22200 -> 22200 | K22: UC7EP8LVXZ | N22: =I22-J22 -> 0
A23: B4 | B23: DOMITILIA WANJIKU | C23: 0798059118 | E23: 21000 | F23: 600 | G23: 300 | H23: =FEB!N24 -> 0 | I23: =D23+E23+F23+G23+H23 -> 21900 | J23: =21900+21750 -> 43650 | K23: UC32B8F8LF /UCU2BB7JTL | L23: 3RD/30TH MARCH | N23: =I23-J23 -> -21750
A24: B5 | B24: KEVIN GITAU | C24: 0720548574 | E24: 21000 | F24: 300 | G24: 300 | H24: =FEB!N25 -> 27900 | I24: =D24+E24+F24+G24+H24 -> 49500 | J24: =7000 -> 7000 | K24: UC9HM8R3NZ | L24: 9TH MARCH | N24: =I24-J24 -> 42500 | Q24: FRIDAY
A25: B6 | B25: OFFICE | H25: =FEB!N26 -> 0 | I25: =D25+E25+F25+G25+H25 -> 0 | N25: =I25-J25 -> 0
A26: B7 | B26: JONES MAGETO | C26: 0720834992 | D26: 23700 | E26: 22000 | F26: 0 | G26: 300 | I26: =D26+E26+F26+G26+H26 -> 46000 | J26: =46000 -> 46000 | K26: UBN637PBLZ | N26: =I26-J26 -> 0 | Q26: LOCKED
A27: B8 | B27: DENNIS MBOYA | C27: 0726689860 | E27: 21000 | F27: 600 | G27: 300 | H27: =FEB!N28 -> 0 | I27: =D27+E27+F27+G27+H27 -> 21900 | J27: =21900 -> 21900 | K27: UC2G37ZUKW | L27: 2ND MARCH | N27: =I27-J27 -> 0 | R27: SIGNED | T27: A7 D2 B7 E1 C1 C2
A28: C1 | B28: STACY WANGECHI | C28: 0728444472 | E28: 22000 | F28: 0 | G28: 300 | H28: =FEB!N29 -> -150 | I28: =D28+E28+F28+G28+H28 -> 22150 | J28: =22300 -> 22300 | K28: UC4OD8F7KG | L28: 4TH MARCH | N28: =I28-J28 -> -150
A29: C2 | B29: FRANCIS KAMAU | C29: 0724960681 | E29: 20000 | F29: 750 | G29: 300 | H29: =FEB!N30 -> -100 | I29: =D29+E29+F29+G29+H29 -> 20950 | J29: =21000 -> 21000 | K29: UC6QC8LUBP | L29: 8TH MARCH | N29: =I29-J29 -> -50 | R29: SIGNED
A30: C3 | B30: JACINTA | C30: 0735765230 | E30: 20000 | F30: 1050 | G30: 300 | H30: =FEB!N31 -> 0 | I30: =D30+E30+F30+G30+H30 -> 21350 | J30: =21350 -> 21350 | K30: UC3I088TY7 | L30: 3RD MARCH | N30: =I30-J30 -> 0 | R30: SIGNED
A31: C4 | B31: CATHERINE MWENDE | C31: 0714216677 | E31: 21000 | F31: 450 | G31: 300 | H31: =FEB!N32 -> 0 | I31: =D31+E31+F31+G31+H31 -> 21750 | J31: =21750 -> 21750 | K31: UC82U8WQ6K | L31: 9TH MARCH | N31: =I31-J31 -> 0 | R31: SIGNED
A32: C5 | B32: ALEX OMANGA | C32: 0713579337 | E32: 20000 | F32: 900 | G32: 300 | H32: =FEB!N33 -> 0 | I32: =D32+E32+F32+G32+H32 -> 21200 | J32: =21200 -> 21200 | K32: UC4NL8IMXU | L32: 4TH MARCH | N32: =I32-J32 -> 0
A33: C6 | B33: NATASHA KAMARI | C33: 0769308005 | E33: 12000 | F33: 300 | G33: 300 | H33: =FEB!N34 -> 0 | I33: =D33+E33+F33+G33+H33 -> 12600 | J33: =4500+8100 -> 12600 | K33: UCAEV8XK6W | L33: 10TH MARCH | N33: =I33-J33 -> 0 | Q33: WED
A34: C7 | B34: CALVIN OUMA | C34: 0717038580 | E34: 20000 | F34: 450 | G34: 300 | H34: =FEB!N35 -> 0 | I34: =D34+E34+F34+G34+H34 -> 20750 | J34: =20750 -> 20750 | K34: UC1G67YBW6 | L34: 1ST MARCH | N34: =I34-J34 -> 0
A35: C8 | B35: TITUS MUTHARIA | C35: 0721211242 | E35: 20000 | F35: 0 | G35: 300 | H35: =FEB!N36 -> 0 | I35: =D35+E35+F35+G35+H35 -> 20300 | J35: =20300 -> 20300 | K35: UC5GX88I71 | L35: 5TH MARCH | N35: =I35-J35 -> 0 | R35: SIGNED
A36: D1 | B36: CONTANA ERICK | C36: 0724567912 | E36: 22000 | F36: 750 | G36: 300 | H36: =FEB!N37 -> 0 | I36: =D36+E36+F36+G36+H36 -> 23050 | J36: =23050 -> 23050 | K36: UC59H8H7DG | L36: 6TH MARCH | N36: =I36-J36 -> 0 | R36: SIGNED
A37: D2 | B37: REDEMPTA | C37: 0758251456 | E37: 21000 | F37: 150 | G37: 300 | H37: =FEB!N38 -> -4200 | I37: =D37+E37+F37+G37+H37 -> 17250 | J37: =20450 -> 20450 | K37: UCIAY9L7ZN | L37: 18TH MARCH | N37: =I37-J37 -> -3200
A38: D3 | B38: GITURU SAMSON | C38: 0717152296 | E38: 21000 | F38: 0 | G38: 300 | H38: =FEB!N39 -> 300 | I38: =D38+E38+F38+G38+H38 -> 21600 | J38: =21600 -> 21600 | K38: UC5BO8IO8V | L38: 5TH MARCH | N38: =I38-J38 -> 0
A39: D4 | B39: IRENE NASHIPEI | C39: 0719361901 | E39: 20000 | F39: 900 | G39: 300 | H39: =FEB!N40 -> 300 | I39: =D39+E39+F39+G39+H39 -> 21500 | J39: =21500 -> 21500 | K39: UC3FS8B6TV | L39: 3RD MARCH | N39: =I39-J39 -> 0
A40: D5 | B40: DIANA KAMAU | C40: 0713040717 | E40: 20000 | F40: 900 | G40: 300 | H40: =FEB!N41 -> 0 | I40: =D40+E40+F40+G40+H40 -> 21200 | J40: =21200 -> 21200 | K40: UC3T77PQ33 | L40: 9TH MARCH | N40: =I40-J40 -> 0 | R40: SIGNED
...

Sheet APR
C1: LOBBY ENTERPRISES
A2: PROPERTY MANAGERS AND ESTATE AGENTS
A3: APR2026
B4: RIVUNIA | K4: P.O.BOX 11987
K5: TEL : 0722711933/0712949022
A6: PAYBILL | J6: Care taker
A7: AC NO | J7: Phone no
A9: HSE NO | B9: NAME | C9: PHONE NO | D9: DEPOSIT PAID | E9: MONTHLY RENT | F9: WATER BILL | G9: GARBAGE | H9: BAL B/D | I9: RENT DUE | J9: RENT PAID | K9: RCT NO | L9: DATES | M9: PERIOD | N9: BALANCE | O9: STATUS | P9: FORMS
A10: G2 | B10: KEVIN ESSAU | C10: 0705152448 | E10: 11000 | F10: 150 | G10: 300 | H10: =MARCH!N10 -> 0 | I10: =D10+E10+F10+G10+H10 -> 11450 | J10: 11750 | K10: UCSMIAMHRU | M10: APR | N10: =I10-J10 -> -300 | P10: SIGNED
A11: G3 | B11: STANLEY MUTHOKA | C11: 0726696925 | E11: 21000 | F11: 750 | G11: 300 | H11: =MARCH!N11 -> 44250 | I11: =D11+E11+F11+G11+H11 -> 66300 | M11: APR | N11: =I11-J11 -> 66300 | O11: TO BE AUCTIONED | Q11: N/R
A12: A1 | B12: YUSUF GICHANA | C12: 0724604589 | E12: 22000 | F12: 1050 | G12: 300 | H12: =MARCH!N12 -> 0 | I12: =D12+E12+F12+G12+H12 -> 23350 | J12: 22450 | M12: APR | N12: =I12-J12 -> 900 | P12: SIGNED
A13: A2 | B13: ANNE MAHERO | C13: 0732891525 | E13: 20000 | F13: 750 | G13: 300 | H13: =MARCH!N13 -> 0 | I13: =D13+E13+F13+G13+H13 -> 21050 | J13: 21750 | K13: UD4JABM | M13: APR | N13: =I13-J13 -> -700 | P13: SIGNED
A14: A3 | B14: JANE ACHIENG | C14: 0787049221 | E14: 21000 | F14: 750 | G14: 300 | H14: =MARCH!N14 -> -21000 | I14: =D14+E14+F14+G14+H14 -> 1050 | M14: APR | N14: =I14-J14 -> 1050 | Q14: LEAVING REQUESTING REFUND
A15: A4 | B15: NELSON MUIA | C15: 0722750497 | E15: 21000 | F15: 450 | G15: 300 | H15: =MARCH!N15 -> -1300 | I15: =D15+E15+F15+G15+H15 -> 20450 | J15: 22500 | K15: UDENR0R7Z6 | M15: APR | N15: =I15-J15 -> -2050 | P15: SIGNED | Q15: TODAY
A16: A5 | B16: CLARE NYAERA BOSIRE | C16: 0759158949 | E16: 21000 | F16: 300 | G16: 300 | H16: =MARCH!N16 -> 0 | I16: =D16+E16+F16+G16+H16 -> 21600 | J16: 21750 | K16: UD6GQBQTOW | L16: 46177 | M16: APR | N16: =I16-J16 -> -150
A17: A6 | B17: SWEENEY WANGUI | C17: 0745529428 | E17: 12000 | F17: 750 | G17: 300 | H17: =MARCH!N17 -> -50 | I17: =D17+E17+F17+G17+H17 -> 13000 | J17: 12450 | K17: UDE3L1D875 | M17: APR | N17: =I17-J17 -> 550 | P17: To send mess
A18: A7 | B18: HILLARY YALLAH | C18: 0705682987 | E18: 20000 | F18: 450 | G18: 300 | H18: =MARCH!N18 -> -21650 | I18: =D18+E18+F18+G18+H18 -> -900 | J18: 21000 | K18: UCO1QQQQAOLXJ | M18: APR | N18: =I18-J18 -> -21900 | P18: SIGNED
A19: A8 | B19: EFFIE REINEE | C19: 0728224646 | E19: 20000 | F19: 600 | G19: 300 | H19: =MARCH!N19 -> 450 | I19: =D19+E19+F19+G19+H19 -> 21350 | J19: 20700 | K19: UD5FXBUYV6 | M19: APR | N19: =I19-J19 -> 650
A20: B1 | B20: IAN WANDA | C20: 0702837845 | E20: 20000 | F20: 450 | G20: 300 | H20: =MARCH!N20 -> -3700 | I20: =D20+E20+F20+G20+H20 -> 17050 | J20: 22390 | K20: UDEEP0QJ1O | M20: APR | N20: =I20-J20 -> -5340 | O20: 10TH | Q20: N/R
A21: B2 | B21: RAHIM YUSUF HAFIZ | C21: 0112321416 | E21: 20000 | F21: 390 | G21: 300 | H21: =MARCH!N21 -> 3100 | I21: =D21+E21+F21+G21+H21 -> 23790 | J21: 15000 | K21: UD66NBPPHW | M21: APR | N21: =I21-J21 -> 8790 | O21: 24TH
A22: B3 | B22: SARAH KABIRU | C22: 0726491785 | E22: 21000 | F22: 450 | G22: 300 | H22: =MARCH!N22 -> 0 | I22: =D22+E22+F22+G22+H22 -> 21750 | J22: 21600 | K22: UD8EP03K95 | M22: APR | N22: =I22-J22 -> 150
A23: B4 | B23: DOMITILIA WANJIKU | C23: 0798059118 | E23: 21000 | F23: 1050 | G23: 300 | H23: =MARCH!N23 -> -21750 | I23: =D23+E23+F23+G23+H23 -> 600 | L23: 30/3/26 | M23: APR | N23: =I23-J23 -> 600
A24: B5 | B24: KEVIN GITAU | C24: 0720548574 | E24: 21000 | F24: 750 | G24: 300 | H24: =MARCH!N24 -> 42500 | I24: =D24+E24+F24+G24+H24 -> 64550 | J24: 20000 | K24: UD3HMBBWSO | M24: APR | N24: =I24-J24 -> 44550
A25: B6 | B25: OFFICE | F25: 900 | H25: =MARCH!N25 -> 0 | I25: =D25+E25+F25+G25+H25 -> 900 | M25: APR | N25: =I25-J25 -> 900
A26: B7 | B26: JONES MAGETO | C26: 0720834992 | E26: 22000 | F26: 300 | G26: 300 | H26: =MARCH!N26 -> 0 | I26: =D26+E26+F26+G26+H26 -> 22600 | J26: 22000 | K26: UD66304PUW | M26: APR | N26: =I26-J26 -> 600
A27: B8 | B27: DENNIS MBOYA | C27: 0726689860 | E27: 21000 | F27: 450 | G27: 300 | H27: =MARCH!N27 -> 0 | I27: =D27+E27+F27+G27+H27 -> 21750 | J27: 22500 | K27: UD3G3B91PZ | M27: APR | N27: =I27-J27 -> -750 | P27: SIGNED | R27: A7 D2 B7 E1 C1 C2
A28: C1 | B28: STACY WANGECHI | C28: 0728444472 | E28: 22000 | F28: 1500 | G28: 300 | H28: =MARCH!N28 -> -150 | I28: =D28+E28+F28+G28+H28 -> 23650 | J28: 22400 | K28: UD6OD014A9 | L28: 6TH APRIL | M28: APR | N28: =I28-J28 -> 1250 | Q28: N/R
A29: C2 | B29: FRANCIS KAMAU | C29: 0724960681 | E29: 20000 | F29: 300 | G29: 300 | H29: =MARCH!N29 -> -50 | I29: =D29+E29+F29+G29+H29 -> 20550 | J29: 21000 | K29: UD6FX01KDZ | M29: APR | N29: =I29-J29 -> -450 | P29: SIGNED
A30: C3 | B30: JACINTA | C30: 0735765230 | E30: 20000 | F30: 750 | G30: 300 | H30: =MARCH!N30 -> 0 | I30: =D30+E30+F30+G30+H30 -> 21050 | J30: 21350 | K30: UD410BLUTU | M30: APR | N30: =I30-J30 -> -300 | P30: SIGNED
A31: C4 | B31: CATHERINE MWENDE | C31: 0714216677 | E31: 21000 | F31: 1350 | G31: 300 | H31: =MARCH!N31 -> 0 | I31: =D31+E31+F31+G31+H31 -> 22650 | J31: 21750 | K31: UD72U056CU | M31: APR | N31: =I31-J31 -> 900 | P31: SIGNED
A32: C5 | B32: ALEX OMANGA | C32: 0713579337 | E32: 20000 | F32: 750 | G32: 300 | H32: =MARCH!N32 -> 0 | I32: =D32+E32+F32+G32+H32 -> 21050 | M32: APR | N32: =I32-J32 -> 21050
A33: C6 | B33: NATASHA KAMARI | C33: 0769308005 | E33: 12000 | F33: 900 | G33: 300 | H33: =MARCH!N33 -> 0 | I33: =D33+E33+F33+G33+H33 -> 13200 | J33: 5000 | K33: UD1EVBAPNR | M33: APR | N33: =I33-J33 -> 8200
A34: C7 | B34: CALVIN OUMA | C34: 0717038580 | E34: 20000 | F34: 600 | G34: 300 | H34: =MARCH!N34 -> 0 | I34: =D34+E34+F34+G34+H34 -> 20900 | J34: 20750 | K34: UCRG6AKH7T | M34: APR | N34: =I34-J34 -> 150
A35: C8 | B35: TITUS MUTHARIA | C35: 0721211242 | E35: 20000 | F35: 600 | G35: 300 | H35: =MARCH!N35 -> 0 | I35: =D35+E35+F35+G35+H35 -> 20900 | J35: 20300 | K35: UD4GXBFBA9 | M35: APR | N35: =I35-J35 -> 600 | P35: SIGNED
A36: D1 | B36: CONTANA ERICK | C36: 0724567912 | E36: 22000 | F36: 300 | G36: 300 | H36: =MARCH!N36 -> 0 | I36: =D36+E36+F36+G36+H36 -> 22600 | J36: 22900 | K36: UD79H01IPP | M36: APR | N36: =I36-J36 -> -300 | P36: SIGNED | Q36: N/R
A37: D2 | B37: REDEMPTA | C37: 0758251456 | E37: 21000 | F37: 900 | G37: 300 | H37: =MARCH!N37 -> -3200 | I37: =D37+E37+F37+G37+H37 -> 19000 | J37: 20750 | K37: UDLAY1G843 | M37: APR | N37: =I37-J37 -> -1750 | Q37: Salary delay
A38: D3 | B38: GITURU SAMSON | C38: 0717152296 | E38: 21000 | F38: 150 | G38: 300 | H38: =MARCH!N38 -> 0 | I38: =D38+E38+F38+G38+H38 -> 21450 | J38: 21450 | K38: UD6BOBUH3J | M38: APR | N38: =I38-J38 -> 0 | Q38: N/R
A39: D4 | B39: IRENE NASHIPEI | C39: 0719361901 | E39: 20000 | F39: 150 | G39: 300 | H39: =MARCH!N39 -> 0 | I39: =D39+E39+F39+G39+H39 -> 20450 | J39: 21350 | K39: UDIFSBAKXJ | M39: APR | N39: =I39-J39 -> -900
A40: D5 | B40: DIANA KAMAU | C40: 0713040717 | E40: 20000 | F40: 1350 | G40: 300 | H40: =MARCH!N40 -> 0 | I40: =D40+E40+F40+G40+H40 -> 21650 | J40: 21200 | K40: UD6AOBUQLR | M40: APR | N40: =I40-J40 -> 450 | P40: SIGNED
A41: D6 | B41: TRACY MUTHONI | C41: 0705708602 | E41: 12000 | F41: 150 | G41: 300 | H41: =MARCH!N41 -> 0 | I41: =D41+E41+F41+G41+H41 -> 12450 | J41: 12600 | K41: UDANYOCYHO | M41: APR | N41: =I41-J41 -> -150 | P41: SIGNED | Q41: 11/4/26
...

Sheet MAY
C1: LOBBY ENTERPRISES
A2: PROPERTY MANAGERS AND ESTATE AGENTS
A3: MAY 2026
B4: RIVUNIA | K4: P.O.BOX 11987
K5: TEL : 0722711933/0712949022
A6: PAYBILL | J6: Care taker
A7: AC NO | J7: Phone no
A9: HSE NO | B9: NAME | C9: PHONE NO | D9: DEPOSIT PAID | E9: MONTHLY RENT | F9: WATER BILL | G9: GARBAGE | H9: BAL B/D | I9: RENT DUE | J9: RENT PAID | K9: RCT NO | L9: DATES | M9: PERIOD | N9: BALANCE | O9: STATUS | P9: FORMS
A10: G2 | B10: KEVIN ESSAU | C10: 0705152448 | E10: 11000 | F10: 150 | G10: 300 | H10: =APR!N10 -> -300 | I10: =D10+E10+F10+G10+H10 -> 11150 | J10: 10750 | K10: UEMI3HMCK | M10: MAY | N10: =I10-J10 -> 400 | P10: SIGNED
A11: G3 | B11: STANLEY MUTHOKA | C11: 0726696925 | E11: 21000 | F11: 900 | G11: 300 | H11: =APR!N11 -> 66300 | I11: =D11+E11+F11+G11+H11 -> 88500 | J11: =22050+22050 -> 44100 | K11: UF38N6JIT/UF38N6JIZN | L11: 3RD JUNE | M11: MAY | N11: =I11-J11 -> 44400 | O11: TO AUCTION | P11: SIGNED
A12: A1 | B12: YUSUF GICHANA | C12: 0724604589 | E12: 22000 | F12: 450 | G12: 300 | H12: 0 | I12: =D12+E12+F12+G12+H12 -> 22750 | J12: 23650 | K12: UE76V3BII1 | M12: MAY | N12: =I12-J12 -> -900 | P12: SIGNED
A13: A2 | B13: ANNE MAHERO | C13: 0732891525 | E13: 20000 | F13: 600 | G13: 300 | H13: =APR!N13 -> -700 | I13: =D13+E13+F13+G13+H13 -> 20200 | J13: 20750 | K13: UE5JA39FZH | M13: MAY | N13: =I13-J13 -> -550 | P13: SIGNED
A14: A3 | B14: ELIZABETH WAYUA NZIOKI | C14: 0704827726 | E14: 20000 | F14: 600 | I14: =D14+E14+F14+G14+H14 -> 20600 | J14: =25000+20000 -> 45000 | K14: UEMA51IH16/UETAN6C1X1 | L14: 30/5/26 | M14: MAY | N14: =I14-J14 -> -24400 | P14: SIGNED
A15: A4 | B15: NELSON MUIA | C15: 0722750497 | E15: 21000 | F15: 600 | G15: 300 | H15: =APR!N15 -> -2050 | I15: =D15+E15+F15+G15+H15 -> 19850 | J15: 22500 | K15: UEFNF4BRLW | M15: MAY | N15: =I15-J15 -> -2650 | P15: SIGNED
A16: A5 | B16: CLARE NYAERA BOSIRE | C16: 0759158949 | E16: 21000 | F16: 600 | G16: 150 | H16: =APR!N16 -> -150 | I16: =D16+E16+F16+G16+H16 -> 21600 | J16: 21300 | K16: UE2GQ2TQDS | L16: 2/5/26 | M16: MAY | N16: =I16-J16 -> 300 | P16: SIGNED
A17: A6 | B17: SWEENEY WANGUI | C17: 0745529428 | E17: 12000 | F17: 450 | G17: 300 | H17: =APR!N17 -> 550 | I17: =D17+E17+F17+G17+H17 -> 13300 | J17: 9000 | K17: UEK3L5KWTN | M17: MAY | N17: =I17-J17 -> 4300 | O17: POWER OFF | P17: SIGNED
A18: A7 | B18: HILLARY YALLAH | C18: 0705682987 | E18: 20000 | F18: 900 | G18: 300 | H18: =APR!N18 -> -21900 | I18: =D18+E18+F18+G18+H18 -> -700 | J18: 21000 | K18: UCO1QAOLXJ | M18: MAY | N18: =I18-J18 -> -21700 | P18: SIGNED
A19: A8 | B19: EFFIE REINEE | C19: 0728224646 | E19: 20000 | F19: 1500 | G19: 300 | H19: =APR!N19 -> 650 | I19: =D19+E19+F19+G19+H19 -> 22450 | J19: 20600 | K19: UEFFXKLK8E | M19: MAY | N19: =I19-J19 -> 1850 | P19: SIGNED
A20: B1 | B20: IAN WANDA | C20: 0702837845 | E20: 20000 | F20: 450 | G20: 300 | H20: =APR!N20 -> -5340 | I20: =D20+E20+F20+G20+H20 -> 15410 | J20: 22450 | K20: UEAEP3QO1L | M20: MAY | N20: =I20-J20 -> -7040 | P20: SIGNED
A21: B2 | B21: RAHIM YUSUF HAFIZ | C21: 0112321416 | E21: 20000 | F21: 450 | G21: 300 | H21: =APR!N21 -> 8790 | I21: =D21+E21+F21+G21+H21 -> 29540 | J21: 20400 | K21: UE26N2TG86 | M21: MAY | N21: =I21-J21 -> 9140 | P21: SIGNED
A22: B3 | B22: SARAH KABIRU | C22: 0726491785 | E22: 21000 | F22: 450 | G22: 300 | H22: =APR!N22 -> 150 | I22: =D22+E22+F22+G22+H22 -> 21900 | J22: 22050 | K22: UE8EP3GXYQ | M22: MAY | N22: =I22-J22 -> -150 | P22: SIGNED
A23: B4 | B23: DOMITILIA WANJIKU | C23: 0798059118 | E23: 21000 | F23: 600 | G23: 300 | H23: =APR!N23 -> 600 | I23: =D23+E23+F23+G23+H23 -> 22500 | J23: 21600 | K23: UE62B3JIG3 | L23: 46178 | M23: MAY | N23: =I23-J23 -> 900 | P23: SIGNED
A24: B5 | B24: KEVIN GITAU | C24: 0720548574 | E24: 21000 | F24: 600 | G24: 300 | H24: =APR!N24 -> 44550 | I24: =D24+E24+F24+G24+H24 -> 66450 | J24: =22000+15000 -> 37000 | K24: UEBHM3QJVY/UDBHMOF3JW | M24: MAY | N24: =I24-J24 -> 29450 | O24: POWER OFF | P24: SIGNED
A25: B6 | B25: OFFICE | F25: 0 | I25: =D25+E25+F25+G25+H25 -> 0 | M25: MAY | N25: =I25-J25 -> 0 | P25: SIGNED
A26: B7 | B26: JONES MAGETO | C26: 0720834992 | E26: 22000 | F26: 450 | G26: 300 | H26: =APR!N26 -> 600 | I26: =D26+E26+F26+G26+H26 -> 23350 | J26: 22600 | K26: UE5633GOLX | M26: MAY | N26: =I26-J26 -> 750 | P26: SIGNED
A27: B8 | B27: DENNIS MBOYA | C27: 0726689860 | E27: 21000 | F27: 1350 | G27: 300 | H27: =APR!N27 -> -750 | I27: =D27+E27+F27+G27+H27 -> 21900 | J27: 22800 | K27: UE5G32ZK11 | L27: 5/5/26 | M27: MAY | N27: =I27-J27 -> -900 | P27: SIGNED | Q27: A7 D2 B7 E1 C1 C2
A28: C1 | B28: STACY WANGECHI | C28: 0728444472 | E28: 22000 | F28: 300 | G28: 300 | H28: =APR!N28 -> 1250 | I28: =D28+E28+F28+G28+H28 -> 23850 | J28: 44000 | K28: UEUOD68N32 | L28: 30TH MAY | M28: MAY | N28: =I28-J28 -> -20150 | P28: SIGNED
A29: C2 | B29: VACANT | F29: 300 | I29: =D29+E29+F29+G29+H29 -> 300 | M29: MAY | N29: =I29-J29 -> 300 | P29: SIGNED
A30: C3 | B30: JACINTA | C30: 0735765230 | E30: 20000 | F30: 600 | G30: 300 | H30: =APR!N30 -> -300 | I30: =D30+E30+F30+G30+H30 -> 20600 | J30: 21500 | K30: UE5I03500AJ | M30: MAY | N30: =I30-J30 -> -900 | P30: SIGNED
A31: C4 | B31: CATHERINE MWENDE | C31: 0714216677 | E31: 21000 | F31: 750 | G31: 300 | H31: =APR!N31 -> 900 | I31: =D31+E31+F31+G31+H31 -> 22950 | J31: 21900 | K31: UE52U3CSA6 | L31: 5/5/26 | M31: MAY | N31: =I31-J31 -> 1050 | P31: SIGNED
A32: C5 | B32: JOY MBITI | C32: 0702496071 | D32: 22000 | E32: 22000 | F32: 600 | I32: =D32+E32+F32+G32+H32 -> 44600 | J32: =22000+22000 -> 44000 | K32: UE7LG3CBSK/UDALGOAC50 | M32: MAY | P32: SIGNED
A33: C6 | B33: NATASHA KAMARI | C33: 0769308005 | E33: 12000 | F33: 750 | G33: 300 | H33: =APR!N33 -> 8200 | I33: =D33+E33+F33+G33+H33 -> 21250 | J33: 7000 | K33: UE8EV3LPXP | M33: MAY | N33: =I33-J33 -> 14250 | O33: POWER OFF | P33: SIGNED
A34: C7 | B34: CALVIN OUMA | C34: 0717038580 | E34: 20000 | F34: 900 | G34: 300 | H34: =APR!N34 -> 150 | I34: =D34+E34+F34+G34+H34 -> 21350 | J34: 20750 | K34: UE76V3BII1 | M34: MAY | N34: =I34-J34 -> 600 | P34: SIGNED
A35: C8 | B35: TITUS MUTHARIA | C35: 0721211242 | E35: 20000 | F35: 300 | G35: 300 | H35: =APR!N35 -> 600 | I35: =D35+E35+F35+G35+H35 -> 21200 | J35: 20450 | K35: UE5GX2YXO4 | L35: 5/5/26 | M35: MAY | N35: =I35-J35 -> 750 | P35: SIGNED
A36: D1 | B36: CONTANA ERICK | C36: 0724567912 | E36: 22000 | F36: 1350 | G36: 300 | H36: =APR!N36 -> -300 | I36: =D36+E36+F36+G36+H36 -> 23350 | J36: 23500 | K36: UE59H38OEA | M36: MAY | N36: =I36-J36 -> -150 | P36: SIGNED
A37: D2 | B37: REDEMPTA | C37: 0758251456 | E37: 21000 | F37: 1200 | G37: 300 | H37: =APR!N37 -> -1750 | I37: =D37+E37+F37+G37+H37 -> 20750 | J37: 21050 | K37: UEFAY46X38 | M37: MAY | N37: =I37-J37 -> -300 | P37: SIGNED
A38: D3 | B38: GITURU SAMSON | C38: 0717152296 | E38: 21000 | F38: 150 | G38: 300 | H38: =APR!N38 -> 0 | I38: =D38+E38+F38+G38+H38 -> 21450 | J38: 21450 | K38: UE6B03FFDJ | M38: MAY | N38: =I38-J38 -> 0 | P38: SIGNED
A39: D4 | B39: IRENE NASHIPEI | C39: 0719361901 | E39: 20000 | F39: 150 | G39: 300 | H39: =APR!N39 -> -900 | I39: =D39+E39+F39+G39+H39 -> 19550 | J39: 21650 | K39: UE5FS3AEQJ | M39: MAY | N39: =I39-J39 -> -2100 | P39: SIGNED
A40: D5 | B40: DIANA KAMAU | C40: 0713040717 | E40: 20000 | F40: 300 | G40: 300 | H40: =APR!N40 -> 450 | I40: =D40+E40+F40+G40+H40 -> 21050 | J40: 21500 | K40: UE8T7AAD56 | M40: MAY | N40: =I40-J40 -> -450 | P40: SIGNED
A41: D6 | B41: TRACY MUTHONI | C41: 0705708602 | E41: 12000 | F41: 150 | G41: 300 | H41: =APR!N41 -> -150 | I41: =D41+E41+F41+G41+H41 -> 12300 | J41: 12750 | K41: UE6NY39M56 | M41: MAY | N41: =I41-J41 -> -450 | P41: SIGNED
...

Sheet JUNE
C1: LOBBY ENTERPRISES
A2: PROPERTY MANAGERS AND ESTATE AGENTS
A3: JUNE 2026
B4: RIVUNIA | K4: P.O.BOX 11987
K5: TEL : 0722711933/0712949022
A6: PAYBILL | J6: Care taker
A7: AC NO | J7: Phone no
A9: HSE NO | B9: NAME | C9: PHONE NO | D9: DEPOSIT PAID | E9: MONTHLY RENT | F9: WATER BILL | G9: GARBAGE | H9: BAL B/D | I9: RENT DUE | J9: RENT PAID | K9: RCT NO | L9: DATES | M9: PERIOD | N9: BALANCE | O9: STATUS | P9: FORMS
A10: G2 | B10: KEVIN ESSAU | C10: 0705152448 | E10: 11000 | F10: 150 | G10: 300 | H10: =MAY!N10 -> 400 | I10: =D10+E10+F10+G10+H10 -> 11850 | J10: 12300 | K10: UF5MI6D9UT | L10: 46148 | M10: JUNE | N10: =I10-J10 -> -450 | P10: SIGNED
A11: G3 | B11: STANLEY MUTHOKA | C11: 0726696925 | E11: 21000 | F11: 900 | G11: 300 | H11: =MAY!N11 -> 44400 | I11: =D11+E11+F11+G11+H11 -> 66600 | M11: JUNE | N11: =I11-J11 -> 66600 | P11: SIGNED
A12: A1 | B12: YUSUF GICHANA | C12: 0724604589 | E12: 22000 | F12: 450 | G12: 300 | H12: =MAY!N12 -> -900 | I12: =D12+E12+F12+G12+H12 -> 21850 | J12: 22450 | K12: UF46V6HIHB | L12: 46118 | M12: JUNE | N12: =I12-J12 -> -600 | P12: SIGNED
A13: A2 | B13: ANNE MAHERO | C13: 0732891525 | E13: 20000 | F13: 600 | G13: 300 | H13: =MAY!N13 -> -550 | I13: =D13+E13+F13+G13+H13 -> 20350 | J13: 22600 | K13: UF4JA6RFAG | L13: 46118 | M13: JUNE | N13: =I13-J13 -> -2250 | P13: SIGNED
A14: A3 | B14: ELIZABETH WAYUA NZIOKI | C14: 0704827726 | E14: 20000 | F14: 600 | H14: =MAY!N14 -> -24400 | I14: =D14+E14+F14+G14+H14 -> -3800 | J14: 20000 | K14: UETAN6CIX1 | L14: 29/5/2026 | M14: JUNE | N14: =I14-J14 -> -23800 | P14: SIGNED
A15: A4 | B15: NELSON MUIA | C15: 0722750497 | E15: 21000 | F15: 600 | G15: 300 | H15: =MAY!N15 -> -2650 | I15: =D15+E15+F15+G15+H15 -> 19250 | M15: JUNE | N15: =I15-J15 -> 19250 | P15: SIGNED
A16: A5 | B16: CLARE NYAERA BOSIRE | C16: 0759158949 | E16: 21000 | F16: 450 | G16: 300 | H16: =MAY!N16 -> 300 | I16: =D16+E16+F16+G16+H16 -> 22050 | J16: 22350 | K16: UF4GQ6MA2T | L16: 46118 | M16: JUNE | N16: =I16-J16 -> -300 | P16: SIGNED
A17: A6 | B17: SWEENEY WANGUI | C17: 0745529428 | E17: 12000 | F17: 450 | G17: 300 | H17: =MAY!N17 -> 4300 | I17: =D17+E17+F17+G17+H17 -> 17050 | J17: 12000 | K17: UFOQW99CLD | L17: 24TH JUNE | M17: JUNE | N17: =I17-J17 -> 5050 | P17: SIGNED
A18: A7 | B18: HILLARY YALLAH | C18: 0705682987 | E18: 20000 | F18: 900 | G18: 300 | H18: =MAY!N18 -> -21700 | I18: =D18+E18+F18+G18+H18 -> -500 | J18: 21000 | K18: UF81Q7LCAI | L18: 46301 | M18: JUNE | N18: =I18-J18 -> -21500 | P18: SIGNED
A19: A8 | B19: EFFIE REINEE | C19: 0728224646 | E19: 20000 | F19: 1500 | G19: 300 | H19: =MAY!N19 -> 1850 | I19: =D19+E19+F19+G19+H19 -> 23650 | J19: 13000 | K19: UFFFX84AGB | L19: 15/6/26 | M19: JUNE | N19: =I19-J19 -> 10650 | P19: SIGNED
A20: B1 | B20: IAN WANDA | C20: 0702837845 | E20: 20000 | F20: 450 | G20: 300 | H20: =MAY!N20 -> -7040 | I20: =D20+E20+F20+G20+H20 -> 13710 | J20: 22450 | K20: UF9EP7557L | M20: JUNE | N20: =I20-J20 -> -8740 | P20: SIGNED
A21: B2 | B21: RAHIM YUSUF HAFIZ | C21: 0112321416 | E21: 20000 | F21: 450 | G21: 300 | H21: =MAY!N21 -> 9140 | I21: =D21+E21+F21+G21+H21 -> 29890 | J21: 15000 | K21: UF2DI6FAOX | L21: 46118 | M21: JUNE | N21: =I21-J21 -> 14890 | P21: SIGNED
A22: B3 | B22: SARAH KABIRU | C22: 0726491785 | E22: 21000 | F22: 300 | G22: 300 | H22: =MAY!N22 -> -150 | I22: =D22+E22+F22+G22+H22 -> 21450 | J22: 21450 | K22: UF7EP6VXVP | L22: 46209 | M22: JUNE | N22: =I22-J22 -> 0 | P22: SIGNED
A23: B4 | B23: DOMITILIA WANJIKU | C23: 0798059118 | E23: 21000 | F23: 600 | G23: 300 | H23: =MAY!N23 -> 900 | I23: =D23+E23+F23+G23+H23 -> 22800 | J23: 21600 | K23: UF32B6TT02 | L23: 46118 | M23: JUNE | N23: =I23-J23 -> 1200 | P23: SIGNED
A24: B5 | B24: KEVIN GITAU | C24: 0720548574 | E24: 21000 | F24: 600 | G24: 300 | H24: =MAY!N24 -> 29450 | I24: =D24+E24+F24+G24+H24 -> 51350 | J24: =15000+10000 -> 25000 | K24: UDBHM0F3JW/UFGM7V9VQ | L24: 15TH JULY | M24: JUNE | N24: =I24-J24 -> 26350 | P24: SIGNED
A25: B6 | B25: OFFICE | F25: 0 | H25: =MAY!N25 -> 0 | I25: =D25+E25+F25+G25+H25 -> 0 | M25: JUNE | N25: =I25-J25 -> 0 | P25: SIGNED
A26: B7 | B26: JONES MAGETO | C26: 0720834992 | E26: 22000 | F26: 450 | G26: 300 | H26: 0 | I26: =D26+E26+F26+G26+H26 -> 22750 | J26: 44600 | K26: UEJ6354H61 | L26: 46148 | M26: JUNE | N26: =I26-J26 -> -21850 | P26: SIGNED
A27: B8 | B27: DENNIS MBOYA | C27: 0726689860 | E27: 21000 | F27: 1350 | G27: 300 | H27: =MAY!N27 -> -900 | I27: =D27+E27+F27+G27+H27 -> 21750 | J27: 22350 | K27: UF5G36KZNP | L27: 14/6/26 | M27: JUNE | N27: =I27-J27 -> -600 | P27: SIGNED | Q27: A7 D2 B7 E1 C1 C2
A28: C1 | B28: STACY WANGECHI | C28: 0728444472 | E28: 22000 | F28: 450 | G28: 300 | H28: =MAY!N28 -> -20150 | I28: =D28+E28+F28+G28+H28 -> 2600 | M28: JUNE | P28: SIGNED
A29: C2 | B29: ESTHER MAINA | C29: 0794611917/0707290791 | D29: 21000 | H29: =MAY!N29 -> 300 | I29: =D29+E29+F29+G29+H29 -> 21300 | J29: =21000 -> 21000 | K29: UFCGC7K5Q7 | L29: 12TH JUNE 2026 | M29: JUNE | N29: =I29-J29 -> 300 | O29: BOOKING FOR JULY | P29: SIGNED
A30: C3 | B30: JACINTA | C30: 0735765230 | E30: 20000 | F30: 1350 | G30: 300 | H30: =MAY!N30 -> -900 | I30: =D30+E30+F30+G30+H30 -> 20750 | J30: 21350 | K30: UF3I06GFZU | L30: 3/6/026 | M30: JUNE | N30: =I30-J30 -> -600 | P30: SIGNED
A31: C4 | B31: CATHERINE MWENDE | C31: 0714216677 | E31: 21000 | F31: 750 | G31: 300 | H31: =MAY!N31 -> 1050 | I31: =D31+E31+F31+G31+H31 -> 23100 | J31: 21750 | K31: UFA2U7G8IF | L31: 45936 | M31: JUNE | N31: =I31-J31 -> 1350 | P31: SIGNED
A32: C5 | B32: JOY MBITI | C32: 0702496071 | E32: 22000 | F32: 600 | H32: =MAY!N32 -> 0 | I32: =D32+E32+F32+G32+H32 -> 22600 | J32: 22600 | K32: UF4LG6ICXJ | L32: 46209 | M32: JUNE | N32: =I32-J32 -> 0 | P32: SIGNED
A33: C6 | B33: NATASHA KAMARI | C33: 0769308005 | E33: 12000 | F33: 750 | G33: 300 | H33: =MAY!N33 -> 14250 | I33: =D33+E33+F33+G33+H33 -> 27300 | M33: JUNE | N33: =I33-J33 -> 27300 | P33: SIGNED
A34: C7 | B34: CALVIN OUMA | C34: 0717038580 | E34: 20000 | F34: 900 | G34: 300 | H34: =MAY!N34 -> 600 | I34: =D34+E34+F34+G34+H34 -> 21800 | J34: 20750 | K34: UERG65LI4O | L34: 27/5/026 | M34: JUNE | N34: =I34-J34 -> 1050 | P34: SIGNED
A35: C8 | B35: TITUS MUTHARIA | C35: 0721211242 | E35: 20000 | F35: 450 | G35: 300 | H35: =MAY!N35 -> 750 | I35: =D35+E35+F35+G35+H35 -> 21500 | J35: 20300 | K35: UF4CX6AJM9 | L35: 4/6/026 | M35: JUNE | N35: =I35-J35 -> 1200 | P35: SIGNED
A36: D1 | B36: CONTANA ERICK | C36: 0724567912 | E36: 22000 | F36: 1350 | G36: 300 | H36: =MAY!N36 -> -150 | I36: =D36+E36+F36+G36+H36 -> 23500 | J36: 23500 | K36: UE59H38OEA | L36: 5/6/026 | M36: JUNE | N36: =I36-J36 -> 0 | P36: SIGNED
A37: D2 | B37: REDEMPTA | C37: 0758251456 | E37: 21000 | F37: 1200 | G37: 300 | H37: =MAY!N37 -> -300 | I37: =D37+E37+F37+G37+H37 -> 22200 | M37: JUNE | N37: =I37-J37 -> 22200 | P37: SIGNED
A38: D3 | B38: GITURU SAMSON | C38: 0717152296 | E38: 21000 | F38: 150 | G38: 300 | H38: =MAY!N38 -> 0 | I38: =D38+E38+F38+G38+H38 -> 21450 | J38: 21450 | K38: UF5BO6U9NU | L38: 5/6/026 | M38: JUNE | N38: =I38-J38 -> 0 | P38: SIGNED
A39: D4 | B39: JIM MBIRATA | C39: 0723138207 | E39: 20000 | G39: 300 | I39: =D39+E39+F39+G39+H39 -> 20300 | J39: 40000 | K39: UERS80G94G | L39: 27/6/126 | M39: JUNE | N39: =I39-J39 -> -19700 | P39: SIGNED
A40: D5 | B40: DIANA KAMAU | C40: 0713040717 | E40: 20000 | F40: 300 | G40: 300 | H40: =MAY!N40 -> -450 | I40: =D40+E40+F40+G40+H40 -> 20150 | J40: 21350 | K40: UF6A06WC17 | L40: 46179 | M40: JUNE | N40: =I40-J40 -> -1200 | P40: SIGNED
A41: D6 | B41: TRACY MUTHONI | C41: 0705708602 | E41: 12000 | F41: 450 | G41: 300 | H41: =MAY!N41 -> -450 | I41: =D41+E41+F41+G41+H41 -> 12300 | J41: 12600 | K41: UF8GD6WSZ0 | L41: 46271 | M41: JUNE | N41: =I41-J41 -> -300 | P41: SIGNED
...

Sheet JULY
C1: LOBBY ENTERPRISES
A2: PROPERTY MANAGERS AND ESTATE AGENTS
A3: JULY 2026
B4: RIVUNIA | K4: P.O.BOX 11987
K5: TEL : 0722711933/0712949022
A6: PAYBILL | J6: Care taker
A7: AC NO | J7: Phone no
A9: HSE NO | B9: NAME | C9: PHONE NO | D9: DEPOSIT PAID | E9: MONTHLY RENT | F9: WATER BILL | G9: GARBAGE | H9: BAL B/D | I9: RENT DUE | J9: RENT PAID | K9: RCT NO | L9: DATES | M9: PERIOD | N9: BALANCE | O9: STATUS | P9: FORMS
A10: G2 | B10: KEVIN ESSAU | C10: 0705152448 | E10: 11000 | F10: 300 | G10: 300 | H10: =JUNE!N10 -> -450 | I10: =D10+E10+F10+G10+H10 -> 11150 | J10: =11300+300 -> 11600 | K10: UFUMI98K3V | L10: 46203 | N10: =I10-J10 -> -450 | P10: SIGNED
A11: G3 | B11: ERNSEST MUKIRI MUCHENE | D11: 21000 | I11: =D11+E11+F11+G11+H11 -> 21000 | J11: =32000 -> 32000 | K11: UGUGO0P8NH | N11: =I11-J11 -> -11000 | P11: SIGNED
A12: A1 | B12: YUSUF GICHANA | C12: 0724604589 | E12: 22000 | F12: 900 | G12: 300 | H12: =JUNE!N12 -> -600 | I12: =D12+E12+F12+G12+H12 -> 22600 | J12: 22750 | K12: UG36V9V0Q8 | L12: 46206 | N12: =I12-J12 -> -150 | P12: SIGNED
A13: A2 | B13: ANNE MAHERO | C13: 0732891525 | E13: 20000 | F13: 750 | G13: 300 | H13: =JUNE!N13 -> -2250 | I13: =D13+E13+F13+G13+H13 -> 18800 | J13: 20600 | K13: UG1JA9YESR | L13: 46207 | N13: =I13-J13 -> -1800 | P13: SIGNED
A14: A3 | B14: ELIZABETH WAYUA NZIOKI | C14: 0704827726 | E14: 20000 | F14: 600 | H14: =JUNE!N14 -> -23800 | I14: =D14+E14+F14+G14+H14 -> -3200 | J14: 20300 | K14: U1ANA7MR2 | L14: 46204 | N14: =I14-J14 -> -23500 | P14: SIGNED
A15: A4 | B15: VACANT | I15: =D15+E15+F15+G15+H15 -> 0 | N15: =I15-J15 -> 0 | P15: SIGNED
A16: A5 | B16: CLARE NYAERA BOSIRE | C16: 0759158949 | E16: 21000 | F16: 900 | G16: 300 | H16: =JUNE!N16 -> -300 | I16: =D16+E16+F16+G16+H16 -> 21900 | J16: 21600 | K16: UG4GQA1BGJ | L16: 46207 | N16: =I16-J16 -> 300 | P16: SIGNED
A17: A6 | B17: SWEENEY WANGUI | C17: 0745529428 | E17: 12000 | F17: 450 | G17: 300 | H17: =JUNE!N17 -> 5050 | I17: =D17+E17+F17+G17+H17 -> 17800 | J17: =25000 -> 25000 | K17: UGJQW08BHW | L17: 20/07/2026 | N17: =I17-J17 -> -7200 | P17: SIGNED
A18: A7 | B18: HILLARY YALLAH | C18: 0705682987 | E18: 20000 | F18: 450 | G18: 300 | H18: =JUNE!N18 -> -21500 | I18: =D18+E18+F18+G18+H18 -> -750 | N18: =I18-J18 -> -750 | P18: SIGNED
A19: A8 | B19: EFFIE REINEE | C19: 0728224646 | E19: 20000 | F19: 750 | G19: 300 | H19: =JUNE!N19 -> 10650 | I19: =D19+E19+F19+G19+H19 -> 31700 | J19: 20600 | K19: UGCFXB99II | L19: 46215 | N19: =I19-J19 -> 11100 | P19: SIGNED
A20: B1 | B20: IAN WANDA | C20: 0702837845 | E20: 20000 | F20: 600 | G20: 300 | H20: =JUNE!N20 -> -8740 | I20: =D20+E20+F20+G20+H20 -> 12160 | J20: =22450 -> 22450 | K20: UG4EPAO3K | L20: 46208 | N20: =I20-J20 -> -10290 | P20: SIGNED
A21: B2 | B21: RAHIM YUSUF HAFIZ | C21: 0112321416 | E21: 20000 | F21: 450 | G21: 300 | H21: =JUNE!N21 -> 14890 | I21: =D21+E21+F21+G21+H21 -> 35640 | J21: 20500 | K21: UG56NA7F2L | L21: 46216 | N21: =I21-J21 -> 15140 | P21: SIGNED
A22: B3 | B22: SARAH KABIRU | C22: 0726491785 | E22: 21000 | F22: 450 | G22: 300 | H22: =JUNE!N22 -> 0 | I22: =D22+E22+F22+G22+H22 -> 21750 | N22: =I22-J22 -> 21750 | O22: POWER AND WATER DISCONNECTED | P22: SIGNED
A23: B4 | B23: DOMITILLA WANJIKU | C23: 0798059118 | E23: 21000 | F23: 600 | G23: 300 | H23: =JUNE!N23 -> 1200 | I23: =D23+E23+F23+G23+H23 -> 23100 | J23: =21600+600 -> 22200 | K23: UG42BAD9QP/ UGV2B1IVRH | L23: 46207 | N23: =I23-J23 -> 900 | P23: SIGNED
A24: B5 | B24: KEVIN GITAU | C24: 0720548574 | E24: 21000 | F24: 600 | G24: 300 | H24: =JUNE!N24 -> 26350 | I24: =D24+E24+F24+G24+H24 -> 48250 | J24: =10000+10000+35000 -> 55000 | K24: UFGHM7V9VQ/UFIHN848PC/ UGFHM4V9VXQ | L24: 7/26/2026/31.07.2026 | N24: =I24-J24 -> -6750 | P24: SIGNED
A25: B6 | B25: OFFICE | F25: 600 | H25: =JUNE!N25 -> 0 | I25: =D25+E25+F25+G25+H25 -> 600 | N25: =I25-J25 -> 600 | P25: SIGNED
A26: B7 | B26: JONES MAGETO | C26: 0720834992 | E26: 22000 | F26: 300 | G26: 300 | H26: =JUNE!N26 -> -21850 | I26: =D26+E26+F26+G26+H26 -> 750 | J26: 600 | K26: UEJ6354H61 | L26: 46211 | N26: =I26-J26 -> 150 | P26: SIGNED
A27: B8 | B27: DENNIS MBOYA | C27: 0726689860 | E27: 21000 | F27: 300 | G27: 300 | H27: =JUNE!N27 -> -600 | I27: =D27+E27+F27+G27+H27 -> 21000 | J27: =22500 -> 22500 | K27: UG6G3A1V6B | L27: 46209 | N27: =I27-J27 -> -1500 | P27: SIGNED
A28: C1 | B28: CATHERINE MWENDE | C28: 0728444472 | E28: 22000 | F28: 450 | G28: 300 | H28: =JUNE!N28 -> 0 | I28: =D28+E28+F28+G28+H28 -> 22750 | J28: 22750 | K28: UG62UAIPMY | L28: 46209 | N28: =I28-J28 -> 0 | P28: SIGNED
A29: C2 | B29: ESTHER MAINA | C29: 0794611917/0707290791 | E29: 21000 | F29: 300 | G29: 300 | H29: =JUNE!N29 -> 300 | I29: =D29+E29+F29+G29+H29 -> 21900 | J29: 20000 | K29: UG4GCA5NAY | L29: 46207 | N29: =I29-J29 -> 1900 | P29: SIGNED
A30: C3 | B30: JACINTA | C30: 0735765230 | E30: 20000 | F30: 300 | G30: 300 | H30: =JUNE!N30 -> -600 | I30: =D30+E30+F30+G30+H30 -> 20000 | J30: =21350 -> 21350 | K30: UG4I0A3OMD | L30: 46208 | N30: =I30-J30 -> -1350 | P30: SIGNED
A31: C4 | B31: SIMON KABIRU | C31: 0714216677 | E31: 21000 | F31: 0 | G31: 300 | H31: 0 | I31: =D31+E31+F31+G31+H31 -> 21300 | J31: 42000 | K31: UG4GY9VP1Y | L31: 46207 | N31: =I31-J31 -> -20700 | P31: SIGNED
A32: C5 | B32: JOY MBITI | C32: 0702496071 | E32: 22000 | F32: 750 | H32: =JUNE!N32 -> 0 | I32: =D32+E32+F32+G32+H32 -> 22750 | J32: 22600 | K32: UG1LG9MYHK | L32: 46204 | N32: =I32-J32 -> 150 | P32: SIGNED
A33: C6 | B33: NATASHA KAMARI | C33: 0769308005 | E33: 12000 | F33: 600 | G33: 300 | H33: =JUNE!N33 -> 27300 | I33: =D33+E33+F33+G33+H33 -> 40200 | J33: 10000 | K33: UGBEVAVD2D | L33: 46214 | N33: =I33-J33 -> 30200 | O33: POWER AND WATER DISCONNECTED | P33: SIGNED
A34: C7 | B34: CALVIN OUMA | C34: 0717038580 | E34: 20000 | F34: 600 | G34: 300 | H34: =JUNE!N34 -> 1050 | I34: =D34+E34+F34+G34+H34 -> 21950 | J34: =21000+21000 -> 42000 | K34: UFQG693OSW/ UGRG60Q05K | L34: 7/26/2026 / 28/7/2026 | N34: =I34-J34 -> -20050 | P34: SIGNED
A35: C8 | B35: TITUS MUTHARIA | C35: 0721211242 | E35: 20000 | F35: 1050 | G35: 300 | H35: =JUNE!N35 -> 1200 | I35: =D35+E35+F35+G35+H35 -> 22550 | J35: 20300 | K35: UG2GX9L27A | L35: 46205 | N35: =I35-J35 -> 2250 | P35: SIGNED
A36: D1 | B36: CONTANA ERICK | C36: 0724567912 | E36: 22000 | F36: 300 | G36: 300 | H36: =JUNE!N36 -> 0 | I36: =D36+E36+F36+G36+H36 -> 22600 | J36: =23200 -> 23200 | K36: UG59HA7XPI | L36: 46204 | N36: =I36-J36 -> -600 | P36: SIGNED
A37: D2 | B37: REDEMPTA | C37: 0758251456 | E37: 21000 | F37: 1200 | G37: 300 | H37: =JUNE!N37 -> 22200 | I37: =D37+E37+F37+G37+H37 -> 44700 | J37: =18000+24550 -> 42550 | K37: UG1TN0GB42/UFRAYN3CYC | L37: 27/06/2026 / 01/07/2026 | N37: =I37-J37 -> 2150 | P37: SIGNED
A38: D3 | B38: GITURU SAMSON | C38: 0717152296 | E38: 21000 | F38: 1050 | G38: 300 | H38: =JUNE!N38 -> 0 | I38: =D38+E38+F38+G38+H38 -> 22350 | J38: 21450 | K38: UG5BOA8KWS | L38: 46208 | N38: =I38-J38 -> 900 | P38: SIGNED
A39: D4 | B39: JIM MBIRATA | C39: 0723138207 | E39: 20000 | F39: 450 | G39: 300 | H39: =JUNE!N39 -> -19700 | I39: =D39+E39+F39+G39+H39 -> 1050 | J39: 20600 | K39: UG4MUAGVDG | L39: 46205 | N39: =I39-J39 -> -19550 | P39: SIGNED
A40: D5 | B40: DIANA KAMAU | C40: 0713040717 | E40: 20000 | F40: 1800 | G40: 300 | H40: =JUNE!N40 -> -1200 | I40: =D40+E40+F40+G40+H40 -> 20900 | J40: =21050 -> 21050 | K40: UG5A0AA6HZ | L40: 46207 | N40: =I40-J40 -> -150 | P40: SIGNED
A41: D6 | B41: TRACY MUTHONI | C41: 0705708602 | E41: 12000 | F41: 1050 | G41: 300 | H41: =JUNE!N41 -> -300 | I41: =D41+E41+F41+G41+H41 -> 13050 | J41: 12300 | K41: UFQNY92CF7 | L41: 46199 | N41: =I41-J41 -> 750 | P41: SIGNED
...

Sheet AUGUST
C1: LOBBY ENTERPRISES
A2: PROPERTY MANAGERS AND ESTATE AGENTS
A3: JULY 2026
B4: RIVUNIA | K4: P.O.BOX 11987
K5: TEL : 0722711933/0712949022
A6: PAYBILL | J6: Care taker
A7: AC NO | J7: Phone no
A9: HSE NO | B9: NAME | C9: PHONE NO | D9: DEPOSIT PAID | E9: MONTHLY RENT | F9: WATER BILL | G9: GARBAGE | H9: BAL B/D | I9: RENT DUE | J9: RENT PAID | K9: RCT NO | L9: DATES | M9: PERIOD | N9: BALANCE | O9: STATUS | P9: FORMS
A10: G2 | B10: KEVIN ESSAU | C10: 0705152448 | E10: 11000 | F10: 300 | G10: 300 | H10: =JULY!N10 -> -450 | I10: =D10+E10+F10+G10+H10 -> 11150 | J10: =11600 -> 11600 | K10: UHQMI3Q3NM | M10: AUGUST | N10: =I10-J10 -> -450 | P10: SIGNED
A11: G3 | B11: ERNSEST MUKIRI MUTHOKA | C11: 0768782014 | E11: 21000 | F11: 600 | G11: 300 | H11: =JULY!N11 -> -11000 | I11: =D11+E11+F11+G11+H11 -> 10900 | J11: =10000+21750 -> 31750 | K11: UGOGOBWHLU/UHVGO4AOOD | L11: 24/07/2026/ 31.08.2026 | M11: AUGUST | N11: =I11-J11 -> -20850 | P11: SIGNED
A12: A1 | B12: YUSUF GICHANA | C12: 0724604589 | E12: 22000 | F12: 450 | G12: 300 | H12: =JULY!N12 -> -150 | I12: =D12+E12+F12+G12+H12 -> 22600 | J12: =22450 -> 22450 | K12: A4AE97B799627 | L12: 05.08.2026 | M12: AUGUST | N12: =I12-J12 -> 150 | P12: SIGNED
A13: A2 | B13: ANNE MAHERO | C13: 0732891525 | E13: 20000 | F13: 450 | G13: 300 | H13: =JULY!N13 -> -1800 | I13: =D13+E13+F13+G13+H13 -> 18950 | J13: =20750 -> 20750 | K13: UH1JA1ICWG | L13: 01.08.2026 | M13: AUGUST | N13: =I13-J13 -> -1800 | P13: SIGNED
A14: A3 | B14: ELIZABETH WAYUA NZIOKI | C14: 0704827726 | E14: 20000 | F14: 750 | H14: =JULY!N14 -> -23500 | I14: =D14+E14+F14+G14+H14 -> -2750 | M14: AUGUST | N14: =I14-J14 -> -2750 | P14: SIGNED
A15: A4 | B15: SAMUEL MUKOYA | C15: 0721636240 | D15: 21000 | E15: 21000 | F15: 450 | G15: 300 | H15: 0 | I15: =D15+E15+F15+G15+H15 -> 42750 | J15: =21000+21000 -> 42000 | K15: UGO8E0HNLQ/UH4KI25AEI | L15: 24/07/2026/ 04.08.2026 | M15: AUGUST | N15: =I15-J15 -> 750 | P15: SIGNED
A16: A5 | B16: CLARE NYAERA BOSIRE | C16: 0759158949 | E16: 21000 | F16: 300 | G16: 300 | H16: =JULY!N16 -> 300 | I16: =D16+E16+F16+G16+H16 -> 21900 | J16: =21750 -> 21750 | K16: UH3GQ1KF56 | L16: 03.08.2026 | M16: AUGUST | N16: =I16-J16 -> 150 | P16: SIGNED
A17: A6 | B17: SWEENEY WANGUI | C17: 0745529428 | E17: 12000 | F17: 1050 | G17: 300 | H17: =JULY!N17 -> -7200 | I17: =D17+E17+F17+G17+H17 -> 6150 | M17: AUGUST | N17: =I17-J17 -> 6150 | P17: SIGNED
A18: A7 | B18: HILLARY YALLAH | C18: 0705682987 | E18: 20000 | F18: 450 | G18: 300 | H18: =JULY!N18 -> -750 | I18: =D18+E18+F18+G18+H18 -> 20000 | J18: =21000 -> 21000 | K18: UH81Q2SMI8 | L18: 08.08.2026 | M18: AUGUST | N18: =I18-J18 -> -1000 | P18: SIGNED
A19: A8 | B19: EFFIE REINEE | C19: 0728224646 | E19: 20000 | F19: 600 | G19: 300 | H19: =JULY!N19 -> 11100 | I19: =D19+E19+F19+G19+H19 -> 32000 | J19: =20600 -> 20600 | K19: UHHFX3FIIR | M19: AUGUST | N19: =I19-J19 -> 11400 | P19: SIGNED
A20: B1 | B20: IAN WANDA | C20: 0702837845 | E20: 20000 | F20: 600 | G20: 300 | H20: =JULY!N20 -> -10290 | I20: =D20+E20+F20+G20+H20 -> 10610 | J20: =22450 -> 22450 | K20: UH3EP1FD9I | L20: 03.08.2026 | M20: AUGUST | N20: =I20-J20 -> -11840 | P20: SIGNED
A21: B2 | B21: RAHIM YUSUF HAFIZ | C21: 0112321416 | E21: 20000 | F21: 450 | G21: 300 | H21: =JULY!N21 -> 15140 | I21: =D21+E21+F21+G21+H21 -> 35890 | J21: =20500 -> 20500 | K21: UH46N1O9OX | L21: 04.08.2026 | M21: AUGUST | N21: =I21-J21 -> 15390 | P21: SIGNED
A22: B3 | B22: SARAH KABIRU | C22: 0726491785 | E22: 21000 | F22: 750 | G22: 300 | H22: =JULY!N22 -> 21750 | I22: =D22+E22+F22+G22+H22 -> 43800 | J22: =21000 -> 21000 | K22: UHHEP2ZSNT | L22: 17.08.2026 | M22: AUGUST | N22: =I22-J22 -> 22800 | O22: LOCKED | P22: SIGNED
A23: B4 | B23: PETER | C23: 0708870383 | D23: 20000 | E23: 20000 | F23: 750 | G23: 300 | H23: 0 | I23: =D23+E23+F23+G23+H23 -> 41050 | J23: =30000+5000+25600 -> 60600 | K23: UH3GC1J1M6/UHDGC2QXTA/UHRGC4AWNL | L23: 03.08.2026/13.08.2026/ 27.08.2026 | M23: AUGUST | N23: =I23-J23 -> -19550 | P23: SIGNED
A24: B5 | B24: KEVIN GITAU | C24: 0720548574 | E24: 21000 | F24: 600 | G24: 300 | H24: =JULY!N24 -> -6750 | I24: =D24+E24+F24+G24+H24 -> 15150 | M24: AUGUST | N24: =I24-J24 -> 15150 | O24: LOCKED | P24: SIGNED
A25: B6 | B25: OFFICE | F25: 750 | H25: =JULY!N25 -> 600 | I25: =D25+E25+F25+G25+H25 -> 1350 | M25: AUGUST | N25: =I25-J25 -> 1350 | P25: SIGNED
A26: B7 | B26: JONES MAGETO | C26: 0720834992 | E26: 22000 | F26: 300 | G26: 300 | H26: =JULY!N26 -> 150 | I26: =D26+E26+F26+G26+H26 -> 22750 | J26: =22000 -> 22000 | K26: UH9632JDDZ | L26: 09.08.2026 | M26: AUGUST | N26: =I26-J26 -> 750 | P26: SIGNED
A27: B8 | B27: DENNIS MBOYA | C27: 0726689860 | E27: 21000 | F27: 300 | G27: 300 | H27: =JULY!N27 -> -1500 | I27: =D27+E27+F27+G27+H27 -> 20100 | J27: =22650 -> 22650 | K27: UH1G314331 | L27: 01.08.2026 | M27: AUGUST | N27: =I27-J27 -> -2550 | P27: SIGNED
A28: C1 | B28: CATHERINE MWENDE | C28: 0728444472 | E28: 22000 | F28: 1650 | G28: 300 | H28: =JULY!N28 -> 0 | I28: =D28+E28+F28+G28+H28 -> 23950 | J28: =22750 -> 22750 | K28: UH3UH27OKA | L28: 03.08.2026 | M28: AUGUST | N28: =I28-J28 -> 1200 | P28: SIGNED
A29: C2 | B29: ESTHER MAINA | C29: 0794611917/0707290791 | E29: 21000 | F29: 750 | G29: 300 | H29: =JULY!N29 -> 1900 | I29: =D29+E29+F29+G29+H29 -> 23950 | J29: =20000 -> 20000 | K29: UH1GC1B9SF | L29: 01.08.2026 | M29: AUGUST | N29: =I29-J29 -> 3950 | P29: SIGNED
A30: C3 | B30: JACINTA | C30: 0735765230 | E30: 20000 | F30: 750 | G30: 300 | H30: =JULY!N30 -> -1350 | I30: =D30+E30+F30+G30+H30 -> 19700 | J30: =21200 -> 21200 | K30: UH5I01P26Q | L30: 05.08.2026 | M30: AUGUST | N30: =I30-J30 -> -1500 | P30: SIGNED
A31: C4 | B31: SIMON KABIRU | C31: 0714216677 | E31: 21000 | F31: 1200 | G31: 300 | H31: =JULY!N31 -> -20700 | I31: =D31+E31+F31+G31+H31 -> 1800 | J31: =21000 -> 21000 | K31: KE1BAAHA1Z4T | L31: 07.08.2026 | M31: AUGUST | N31: =I31-J31 -> -19200 | P31: SIGNED
A32: C5 | B32: JOY MBITI | C32: 0702496071 | E32: 22000 | F32: 450 | H32: =JULY!N32 -> 150 | I32: =D32+E32+F32+G32+H32 -> 22600 | J32: =22450 -> 22450 | K32: UH6LG1REQ7 | L32: 06.08.2026 | M32: AUGUST | N32: =I32-J32 -> 150 | P32: SIGNED
A33: C6 | B33: NATASHA KAMARI | C33: 0769308005 | E33: 12000 | F33: 450 | G33: 300 | H33: =JULY!N33 -> 30200 | I33: =D33+E33+F33+G33+H33 -> 42950 | M33: AUGUST | N33: =I33-J33 -> 42950 | O33: LOCKED | P33: SIGNED
A34: C7 | B34: CALVIN OUMA | C34: 0717038580 | E34: 20000 | F34: 600 | G34: 300 | H34: =JULY!N34 -> -20050 | I34: =D34+E34+F34+G34+H34 -> 850 | J34: =21000 -> 21000 | K34: UHSG64CDEN | L34: 46262 | M34: AUGUST | N34: =I34-J34 -> -20150 | P34: SIGNED
A35: C8 | B35: TITUS MUTHARIA | C35: 0721211242 | E35: 20000 | F35: 750 | G35: 300 | H35: =JULY!N35 -> 2250 | I35: =D35+E35+F35+G35+H35 -> 23300 | J35: =20300 -> 20300 | K35: UH6GX1L17E | L35: 06.08.2026 | M35: AUGUST | N35: =I35-J35 -> 3000 | P35: SIGNED
A36: D1 | B36: CONTANA ERICK | C36: 0724567912 | E36: 22000 | F36: 300 | G36: 300 | H36: =JULY!N36 -> -600 | I36: =D36+E36+F36+G36+H36 -> 22000 | J36: 23350 | K36: UH59H1SRQU | L36: 05.08.2026 | M36: AUGUST | N36: =I36-J36 -> -1350 | P36: SIGNED
A37: D2 | B37: REDEMPTA | C37: 0758251456 | E37: 21000 | F37: 1350 | G37: 300 | H37: =JULY!N37 -> 2150 | I37: =D37+E37+F37+G37+H37 -> 24800 | J37: =20000 -> 20000 | K37: UHHAY2YJ6I | L37: 17.08.2026 | M37: AUGUST | N37: =I37-J37 -> 4800 | P37: SIGNED
A38: D3 | B38: GITURU SAMSON | C38: 0717152296 | E38: 21000 | F38: 900 | G38: 300 | H38: =JULY!N38 -> 900 | I38: =D38+E38+F38+G38+H38 -> 23100 | J38: =21450 -> 21450 | K38: UH6BO1X6U3 | L38: 06.08.2026 | M38: AUGUST | N38: =I38-J38 -> 1650 | P38: SIGNED
A39: D4 | B39: JIM MBIRATA | C39: 0723138207 | E39: 20000 | F39: 450 | G39: 300 | H39: =JULY!N39 -> -19550 | I39: =D39+E39+F39+G39+H39 -> 1200 | J39: =21050 -> 21050 | K39: UH5MU2413U | L39: 05.08.2026 | M39: AUGUST | N39: =I39-J39 -> -19850 | P39: SIGNED
A40: D5 | B40: DIANA KAMAU | C40: 0713040717 | E40: 20000 | F40: 1800 | G40: 300 | H40: =JULY!N40 -> -150 | I40: =D40+E40+F40+G40+H40 -> 21950 | J40: =20900 -> 20900 | K40: UH5A01VOPD | L40: 05.08.2026 | M40: AUGUST | N40: =I40-J40 -> 1050 | P40: SIGNED
A41: D6 | B41: TRACY MUTHONI | C41: 0705708602 | E41: 12000 | F41: 900 | G41: 300 | H41: =JULY!N41 -> 750 | I41: =D41+E41+F41+G41+H41 -> 13950 | J41: =13050 -> 13050 | K41: UH1NY18ZI5 | L41: 01.08.2026 | M41: AUGUST | N41: =I41-J41 -> 900 | P41: SIGNED
...

Sheet SEPTEMBER
C1: LOBBY ENTERPRISES
A2: PROPERTY MANAGERS AND ESTATE AGENTS
A3: JULY 2026
B4: RIVUNIA | K4: P.O.BOX 11987
K5: TEL : 0722711933/0712949022
A6: PAYBILL | J6: Care taker
A7: AC NO | J7: Phone no
A9: HSE NO | B9: NAME | C9: PHONE NO | D9: DEPOSIT PAID | E9: MONTHLY RENT | F9: WATER BILL | G9: GARBAGE | H9: BAL B/D | I9: RENT DUE | J9: RENT PAID | K9: RCT NO | L9: DATES | M9: PERIOD | N9: BALANCE | O9: STATUS | P9: FORMS
A10: G2 | B10: KEVIN ESSAU | C10: 0705152448 | E10: 11000 | F10: 300 | G10: 300 | H10: =AUGUST!N10 -> -450 | I10: =D10+E10+F10+G10+H10 -> 11150 | J10: =11600 -> 11600 | K10: UI4MI4S539 | L10: 46269 | M10: SEPTEMBER | N10: =I10-J10 -> -450 | O10: 26TH | P10: SIGNED
A11: G3 | B11: ERNSEST MUKIRI MUTHOKA | C11: 0768782014 | E11: 21000 | F11: 600 | G11: 300 | H11: =AUGUST!N11 -> -20850 | I11: =D11+E11+F11+G11+H11 -> 1050 | J11: =150 -> 150 | K11: UI5GO4YS4U | L11: 46270 | M11: SEPTEMBER | N11: =I11-J11 -> 900 | P11: SIGNED
A12: A1 | B12: YUSUF GICHANA | C12: 0724604589 | E12: 22000 | F12: 600 | G12: 300 | H12: =AUGUST!N12 -> 150 | I12: =D12+E12+F12+G12+H12 -> 23050 | J12: =22450 -> 22450 | K12: 0068000320260903080657APEAC07C | L12: 46268 | M12: SEPTEMBER | N12: =I12-J12 -> 600 | P12: SIGNED
A13: A2 | B13: NANCY KAMAU | C13: 0799014762 | D13: 21000 | E13: 21000 | F13: 0 | G13: 300 | H13: 0 | I13: =D13+E13+F13+G13+H13 -> 42300 | J13: =21000 -> 21000 | K13: UI6SL3MF10 | L13: 9/6/2026 | M13: SEPTEMBER | N13: =I13-J13 -> 21300 | O13: NEW TENANT | P13: SIGNED
A14: A3 | B14: ELIZABETH WAYUA NZIOKI | C14: 0704827726 | E14: 20000 | F14: 0 | H14: =AUGUST!N14 -> -2750 | I14: =D14+E14+F14+G14+H14 -> 17250 | M14: SEPTEMBER | N14: =I14-J14 -> 17250 | P14: SIGNED
A15: A4 | B15: SAMUEL MUKOYA | C15: 0721636240 | E15: 21000 | F15: 1050 | G15: 300 | H15: =AUGUST!N15 -> 750 | I15: =D15+E15+F15+G15+H15 -> 23100 | M15: SEPTEMBER | N15: =I15-J15 -> 23100 | P15: SIGNED
A16: A5 | B16: CLARE NYAERA BOSIRE | C16: 0759158949 | E16: 21000 | F16: 450 | G16: 300 | H16: =AUGUST!N16 -> 150 | I16: =D16+E16+F16+G16+H16 -> 21900 | J16: =21750 -> 21750 | K16: UI5GQ5F4G4 | L16: 46270 | M16: SEPTEMBER | N16: =I16-J16 -> 150 | P16: SIGNED
A17: A6 | B17: SWEENEY WANGUI | C17: 0745529428 | E17: 12000 | F17: 600 | G17: 300 | H17: =AUGUST!N17 -> 6150 | I17: =D17+E17+F17+G17+H17 -> 19050 | M17: SEPTEMBER | N17: =I17-J17 -> 19050 | O17: 18TH | P17: SIGNED
A18: A7 | B18: HILLARY YALLAH | C18: 0705682987 | E18: 20000 | F18: 750 | G18: 300 | H18: =AUGUST!N18 -> -1000 | I18: =D18+E18+F18+G18+H18 -> 20050 | J18: =21000 -> 21000 | K18: UI41Q5Z6RZ | L18: 46269 | M18: SEPTEMBER | N18: =I18-J18 -> -950 | P18: SIGNED
A19: A8 | B19: EFFIE REINEE | C19: 0728224646 | E19: 20000 | F19: 300 | G19: 300 | H19: =AUGUST!N19 -> 11400 | I19: =D19+E19+F19+G19+H19 -> 32000 | M19: SEPTEMBER | N19: =I19-J19 -> 32000 | P19: SIGNED
A20: B1 | B20: IAN WANDA | C20: 0702837845 | E20: 20000 | F20: 150 | G20: 300 | H20: =AUGUST!N20 -> -11840 | I20: =D20+E20+F20+G20+H20 -> 8610 | J20: =22450 -> 22450 | K20: UIAEP5STDX | L20: 9/10/2026 | M20: SEPTEMBER | N20: =I20-J20 -> -13840 | P20: SIGNED
A21: B2 | B21: RAHIM YUSUF HAFIZ | C21: 0112321416 | E21: 20000 | F21: 1200 | G21: 300 | H21: =AUGUST!N21 -> 15390 | I21: =D21+E21+F21+G21+H21 -> 36890 | J21: =20500 -> 20500 | K21: UHT6N4L360 | L21: 46269 | M21: SEPTEMBER | N21: =I21-J21 -> 16390 | P21: SIGNED
A22: B3 | B22: SARAH KABIRU | C22: 0726491785 | E22: 21000 | F22: 150 | G22: 300 | H22: =AUGUST!N22 -> 22800 | I22: =D22+E22+F22+G22+H22 -> 44250 | J22: =10000 -> 10000 | K22: Q3R3MIEJOVF | L22: 9/11/2026 | M22: SEPTEMBER | N22: =I22-J22 -> 34250 | O22: 15TH | P22: SIGNED
A23: B4 | B23: PETER | C23: 0708870383 | E23: 20000 | F23: 300 | G23: 300 | H23: =AUGUST!N23 -> -19550 | I23: =D23+E23+F23+G23+H23 -> 1050 | M23: SEPTEMBER | N23: =I23-J23 -> 1050 | P23: SIGNED
A24: B5 | B24: KEVIN GITAU | C24: 0720548574 | E24: 21000 | F24: 300 | G24: 300 | H24: =AUGUST!N24 -> 15150 | I24: =D24+E24+F24+G24+H24 -> 36750 | M24: SEPTEMBER | N24: =I24-J24 -> 36750 | P24: SIGNED
A25: B6 | B25: OFFICE | F25: 0 | H25: =AUGUST!N25 -> 1350 | I25: =D25+E25+F25+G25+H25 -> 1350 | M25: SEPTEMBER | N25: =I25-J25 -> 1350 | P25: SIGNED
A26: B7 | B26: JONES MAGETO | C26: 0720834992 | E26: 22000 | F26: 600 | G26: 300 | H26: =AUGUST!N26 -> 750 | I26: =D26+E26+F26+G26+H26 -> 23650 | J26: =21400 -> 21400 | K26: UI6KB587OF | L26: 46271 | M26: SEPTEMBER | N26: =I26-J26 -> 2250 | P26: SIGNED
A27: B8 | B27: DENNIS MBOYA | C27: 0726689860 | E27: 21000 | F27: 1950 | G27: 300 | H27: =AUGUST!N27 -> -2550 | I27: =D27+E27+F27+G27+H27 -> 20700 | J27: =23250 -> 23250 | K27: UI5G352HAK | L27: 46270 | M27: SEPTEMBER | N27: =I27-J27 -> -2550 | P27: SIGNED
A28: C1 | B28: CATHERINE MWENDE | C28: 0728444472 | E28: 22000 | F28: 600 | G28: 300 | H28: =AUGUST!N28 -> 1200 | I28: =D28+E28+F28+G28+H28 -> 24100 | M28: SEPTEMBER | N28: =I28-J28 -> 24100 | P28: SIGNED
A29: C2 | B29: ESTHER MAINA | C29: 0794611917/0707290791 | E29: 21000 | F29: 600 | G29: 300 | H29: =AUGUST!N29 -> 3950 | I29: =D29+E29+F29+G29+H29 -> 25850 | J29: =20900 -> 20900 | K29: UI4GC5BLPK | L29: 46269 | M29: SEPTEMBER | N29: =I29-J29 -> 4950 | P29: SIGNED
A30: C3 | B30: JACINTA | C30: 0735765230 | E30: 20000 | F30: 1200 | G30: 300 | H30: =AUGUST!N30 -> -1500 | I30: =D30+E30+F30+G30+H30 -> 20000 | J30: =21500 -> 21500 | K30: UI5I05C48L | L30: 46270 | M30: SEPTEMBER | N30: =I30-J30 -> -1500 | P30: SIGNED
A31: C4 | B31: SIMON KABIRU | C31: 0714216677 | E31: 21000 | F31: 300 | G31: 300 | H31: =AUGUST!N31 -> -19200 | I31: =D31+E31+F31+G31+H31 -> 2400 | J31: =21000 -> 21000 | K31: KE2BABWZG20H-ABSA BANK | L31: 46266 | M31: SEPTEMBER | N31: =I31-J31 -> -18600 | P31: SIGNED
A32: C5 | B32: JOY MBITI | C32: 0702496071 | E32: 22000 | F32: 300 | H32: =AUGUST!N32 -> 150 | I32: =D32+E32+F32+G32+H32 -> 22450 | J32: =22500 -> 22500 | K32: UI3LG5OE3J | L32: 46268 | M32: SEPTEMBER | N32: =I32-J32 -> -50 | P32: SIGNED
A33: C6 | B33: NATASHA KAMARI | C33: 0769308005 | E33: 12000 | F33: 450 | G33: 300 | H33: =AUGUST!N33 -> 42950 | I33: =D33+E33+F33+G33+H33 -> 55700 | M33: SEPTEMBER | N33: =I33-J33 -> 55700 | P33: SIGNED
A34: C7 | B34: CALVIN OUMA | C34: 0717038580 | E34: 20000 | F34: 600 | G34: 300 | H34: =AUGUST!N34 -> -20150 | I34: =D34+E34+F34+G34+H34 -> 750 | M34: SEPTEMBER | N34: =I34-J34 -> 750 | P34: SIGNED
A35: C8 | B35: TITUS MUTHARIA | C35: 0721211242 | E35: 20000 | F35: 150 | G35: 300 | H35: =AUGUST!N35 -> 3000 | I35: =D35+E35+F35+G35+H35 -> 23450 | J35: =20300 -> 20300 | K35: UI4GX4XN6T | L35: 46269 | M35: SEPTEMBER | N35: =I35-J35 -> 3150 | P35: SIGNED
A36: D1 | B36: CONTANA ERICK | C36: 0724567912 | E36: 22000 | F36: 1350 | G36: 300 | H36: =AUGUST!N36 -> -1350 | I36: =D36+E36+F36+G36+H36 -> 22300 | M36: SEPTEMBER | N36: =I36-J36 -> 22300 | P36: SIGNED
